Workbook

Sheet DATA ENTRY
B1: Editable
C3: 1 Yr | D3: 2 Yrs | E3: 3 Yrs | F3: 4 Yrs | G3: 5 Yrs
B4: GROSS AMOUNT | C4: ='Computation Table'!C108 -> 112058.4 | D4: ='Computation Table'!C82 -> 118481.58 | E4: ='Computation Table'!C56 -> 53999.85 | F4: ='Computation Table'!C29 -> 133026.28 | G4: ='Computation Table'!C3 -> 900014.89
B5: NET PROCEEDS | C5: 93500 | D5: 93500 | E5: 37354.7 | F5: 93500 | G5: 600010.5
B6: Add:
B7: Service Fee | C7: ='Computation Table'!C110 -> 6545 | D7: ='Computation Table'!C84 -> 7012.5 | E7: ='Computation Table'!E58 -> 2988.376 | F7: ='Computation Table'!C31 -> 7480 | G7: ='Computation Table'!C5 -> 72601.27
B8: Insurance | C8: ='Computation Table'!C111 -> 1122 | D8: ='Computation Table'!C85 -> 2244 | E8: ='Computation Table'!C59 -> 1344.7692 | F8: ='Computation Table'!C32 -> 4488 | G8: ='Computation Table'!C6 -> 36000.63
B9: CapCon | C9: 5000 | D9: 5000 | E9: 5000 | F9: 5000 | G9: 5000
B10: membership fee | C10: 300 | E10: 300 | F10: 0 | G10: 0
B11: Advance Interest | C11: ='Computation Table'!C114 -> 1168.75 | D11: ='Computation Table'!C88 -> 1265.3667 | E11: ='Computation Table'!C62 -> 529.19158 | F11: ='Computation Table'!C35 -> 1368.2167 | G11: ='Computation Table'!C9 -> 9000.1575
B12: LOAN AMOUNT | C12: =SUM(C5:C11) -> 107635.75 | D12: =SUM(D5:D11) -> 109021.87 | E12: =SUM(E5:E11) -> 47517.037 | F12: =SUM(F5:F11) -> 111836.22 | G12: =SUM(G5:G11) -> 722612.56
B13: Annual Interest Rate | C13: ='Computation Table'!C116 -> 0.075 | D13: ='Computation Table'!C90 -> 0.0812 | E13: ='Computation Table'!C64 -> 0.085 | F13: ='Computation Table'!C37 -> 0.0878 | G13: ='Computation Table'!C11 -> 0.09
B14: Effective Interest Rate | C14: ='Computation Table'!C117 -> 0.077632599 | D14: ='Computation Table'!F91 -> 0.084439155 | E14: ='Computation Table'!F65 -> 0.088607994 | F14: ='Computation Table'!C38 -> 0.091682187 | G14: ='Computation Table'!C12 -> 0.094100503
B15: Monthly Amortization | C15: ='Computation Table'!C126 -> 9338.1996 | D15: ='Computation Table'!C100 -> 4936.7326 | E15: ='Computation Table'!C74 -> 1499.9958 | F15: ='Computation Table'!C47 -> 2771.3809 | G15: ='Computation Table'!C21 -> 15000.248

Sheet Sheet2
A1: HIGHEST LOAN OFFER FOR 18-65 YO | B1: HIGHEST LOAN OFFERED FOR 71-75 | C1: HIGHEST LOAN OFFERED FOR 66-70
A2: 1224665.6 | B2: 141889.63 | C2: 325836.12
A3: 31137.533 | B3: 3632.7121 | C3: 8303.3421

Sheet Amortization  Table
B2: PEOPLE'S MULTI-PURPOSE COOPERATIVE EFFECTIVE ON JANUARY 16, 2025 | G2: PEOPLE'S MULTI-PURPOSE COOPERATIVE EFFECTIVE ON JANUARY 16, 2025 | N2: PEOPLE'S MULTI-PURPOSE COOPERATIVE EFFECTIVE ON JANUARY 16, 2025
B5: CDEA LOAN TABLE | G5: AFP LOAN TABLE W/O CAPCON | N5: AFP LOAN TABLE W/ CAPCON
B6: Net Proceeds | C6: 1 Yr 12 Months | D6: 2 Yrs 24 Months | E6: 3 Yrs 36 Months | G6: Net Proceeds | H6: 12 Months | I6: 24 Months | J6: 36 Months | K6: 48 Months | L6: 60 Months | N6: Net Proceeds | O6: 12 Months | P6: 24 Months | Q6: 36 Months | R6: 48 Months | S6: 60 Months
B7: 25000 | C7: ='Computation Table'!E126 -> 2373.8998 | D7: ='Computation Table'!C100 -> 4936.7326 | E7: ='Computation Table'!E74 -> 923.11506 | G7: 25000 | H7: 2373.8998 | I7: 1259.4445 | J7: 891.91446 | K7: 721.48005 | L7: 620.67482 | N7: 25000 | O7: 2833.7141 | P7: 1499.4393 | Q7: 1059.2224 | R7: 852.81781 | S7: 730.6941 | T7: 5000
B8: 50000 | C8: ='Computation Table'!F126 -> 5207.6139 | D8: ='Computation Table'!F100 -> 2745.2992 | E8: ='Computation Table'!F74 -> 1943.245 | G8: 50000 | H8: 4747.7996 | I8: 2518.889 | J8: 1783.8289 | K8: 1442.9601 | L8: 1241.3496 | N8: 50000 | O8: 5207.6139 | P8: 2758.8838 | Q8: 1951.1369 | R8: 1574.2979 | S8: 1351.3689
B9: 75000 | C9: ='Computation Table'!G126 -> 7121.6995 | D9: ='Computation Table'!G100 -> 3778.3335 | E9: ='Computation Table'!G74 -> 2663.9056 | G9: 75000 | H9: 7121.6995 | I9: 3778.3335 | J9: 2675.7434 | K9: 2164.4401 | L9: 1862.0245 | N9: 75000 | O9: 7581.5138 | P9: 4018.3283 | Q9: 2843.0513 | R9: 2295.7779 | S9: 1972.0437
B10: 100000 | C10: ='Computation Table'!H126 -> 9955.4136 | D10: ='Computation Table'!H100 -> 5264.1882 | E10: ='Computation Table'!H74 -> 3719.182 | G10: 100000 | H10: 9495.5993 | I10: 5037.778 | J10: 3567.6579 | K10: 2885.9202 | L10: 2482.6993 | N10: 100000 | O10: 9955.4136 | P10: 5277.7728 | Q10: 3734.9658 | R10: 3017.258 | S10: 2592.7186
B11: 150000 | C11: ='Computation Table'!J126 -> 14703.213 | D11: ='Computation Table'!J100 -> 7783.0772 | E11: ='Computation Table'!J74 -> 5495.1191 | G11: 150000 | H11: 14243.399 | I11: 7556.667 | J11: 5351.4868 | K11: 4328.8803 | L11: 3724.0489 | N11: 150000 | O11: 14703.213 | P11: 7796.6618 | Q11: 5518.7947 | R11: 4460.2181 | S11: 3834.0682
B12: 200000 | C12: ='Computation Table'!L126 -> 19451.013 | D12: ='Computation Table'!L100 -> 10301.966 | E12: ='Computation Table'!L74 -> 7271.0561 | G12: 200000 | H12: 18991.199 | I12: 10075.556 | J12: 7135.3157 | K12: 5771.8404 | L12: 4965.3986 | N12: 200000 | O12: 19451.013 | P12: 10315.551 | Q12: 7302.6237 | R12: 5903.1782 | S12: 5075.4179
B13: 250000 | C13: ='Computation Table'!N126 -> 24198.813 | D13: ='Computation Table'!N100 -> 12820.855 | E13: ='Computation Table'!N74 -> 9046.9932 | G13: 250000 | H13: 23738.998 | I13: 12594.445 | J13: 8919.1446 | K13: 7214.8005 | L13: 6206.7482 | N13: 250000 | O13: 24198.813 | P13: 12834.44 | Q13: 9086.4526 | R13: 7346.1382 | S13: 6316.7675
B14: 300000 | C14: ='Computation Table'!P126 -> 28946.612 | D14: ='Computation Table'!P100 -> 15339.744 | E14: ='Computation Table'!P74 -> 10822.93 | G14: 300000 | H14: 28486.798 | I14: 15113.334 | J14: 10702.974 | K14: 8657.7606 | L14: 7448.0979 | N14: 300000 | O14: 29380.399 | P14: 15579.739 | Q14: 11028.119 | R14: 8913.0019 | S14: 7661.9089 | T14: 10000
B15: 350000 | C15: ='Computation Table'!R126 -> 33694.412 | D15: ='Computation Table'!R100 -> 17858.633 | E15: ='Computation Table'!R74 -> 12598.867 | G15: 350000 | H15: 33234.597 | I15: 17632.223 | J15: 12486.802 | K15: 10100.721 | L15: 8689.4475 | N15: 350000 | O15: 34128.199 | P15: 18098.628 | Q15: 12811.948 | R15: 10355.962 | S15: 8903.2586
B16: 400000 | C16: ='Computation Table'!T126 -> 38442.211 | D16: ='Computation Table'!T100 -> 20377.522 | E16: ='Computation Table'!T74 -> 14374.804 | G16: 400000 | H16: 37982.397 | I16: 20151.112 | J16: 14270.631 | K16: 11543.681 | L16: 9930.7971 | N16: 400000 | O16: 38875.999 | P16: 20617.517 | Q16: 14595.777 | R16: 11798.922 | S16: 10144.608
B17: 450000 | C17: ='Computation Table'!V126 -> 43190.011 | D17: ='Computation Table'!V100 -> 22896.411 | E17: ='Computation Table'!V74 -> 16150.741 | G17: 450000 | H17: 42730.197 | I17: 22670.001 | J17: 16054.46 | K17: 12986.641 | L17: 11172.147 | N17: 450000 | O17: 43623.798 | P17: 23136.406 | Q17: 16379.606 | R17: 13241.882 | S17: 11385.958
B18: 500000 | C18: ='Computation Table'!X126 -> 47937.811 | D18: ='Computation Table'!X100 -> 25415.3 | E18: ='Computation Table'!X74 -> 17926.678 | G18: 500000 | H18: 47477.996 | I18: 25188.89 | J18: 17838.289 | K18: 14429.601 | L18: 12413.496 | N18: 500000 | O18: 48371.598 | P18: 25655.295 | Q18: 18163.435 | R18: 14684.842 | S18: 12627.307
B19: 550000 | C19: ='Computation Table'!Z126 -> 52685.61 | D19: ='Computation Table'!Z100 -> 27934.189 | E19: ='Computation Table'!Z74 -> 19702.615 | G19: 550000 | H19: 52225.796 | I19: 27707.779 | J19: 19622.118 | K19: 15872.561 | L19: 13654.846 | N19: 550000 | O19: 53119.397 | P19: 28174.184 | Q19: 19947.264 | R19: 16127.802 | S19: 13868.657
B20: 600000 | C20: ='Computation Table'!AB126 -> 57433.41 | D20: ='Computation Table'!AB100 -> 30453.078 | E20: ='Computation Table'!AB74 -> 21478.552 | G20: 600000 | H20: 56973.596 | I20: 30226.668 | J20: 21405.947 | K20: 17315.521 | L20: 14896.196 | N20: 600000 | O20: 57867.197 | P20: 30693.073 | Q20: 21731.093 | R20: 17570.762 | S20: 15110.007
B21: 650000 | C21: ='Computation Table'!AD126 -> 62181.21 | D21: ='Computation Table'!AD100 -> 32971.967 | E21: ='Computation Table'!AD74 -> 23254.49 | G21: 650000 | H21: 61721.395 | I21: 32745.557 | J21: 23189.776 | K21: 18758.481 | L21: 16137.545 | N21: 650000 | O21: 62614.997 | P21: 33211.962 | Q21: 23514.922 | R21: 19013.723 | S21: 16351.356
B22: 700000 | C22: ='Computation Table'!AF126 -> 66929.009 | D22: ='Computation Table'!AF100 -> 35490.856 | E22: ='Computation Table'!AF74 -> 25030.427 | G22: 700000 | H22: 66469.195 | I22: 35264.446 | J22: 24973.605 | K22: 20201.441 | L22: 17378.895 | N22: 700000 | O22: 67362.796 | P22: 35730.851 | Q22: 25298.751 | R22: 20456.683 | S22: 17592.706
B23: 750000 | C23: ='Computation Table'!AH126 -> 71676.809 | D23: ='Computation Table'!AH100 -> 38009.745 | E23: ='Computation Table'!AH74 -> 26806.364 | G23: 750000 | H23: 71216.995 | I23: 37783.335 | J23: 26757.434 | K23: 21644.401 | L23: 18620.245 | N23: 750000 | O23: 72110.596 | P23: 38249.74 | Q23: 27082.58 | R23: 21899.643 | S23: 18834.056
B24: 800000 | C24: ='Computation Table'!AJ126 -> 76424.609 | D24: ='Computation Table'!AJ100 -> 40528.634 | E24: ='Computation Table'!AJ74 -> 28582.301 | G24: 800000 | H24: 75964.794 | I24: 40302.224 | J24: 28541.263 | K24: 23087.362 | L24: 19861.594 | N24: 800000 | O24: 76858.396 | P24: 40768.629 | Q24: 28866.408 | R24: 23342.603 | S24: 20075.405
B25: 850000 | C25: ='Computation Table'!AL126 -> 81172.408 | D25: ='Computation Table'!AL100 -> 43047.523 | E25: ='Computation Table'!AL74 -> 30358.238 | G25: 850000 | H25: 80712.594 | I25: 42821.113 | J25: 30325.092 | K25: 24530.322 | L25: 21102.944 | N25: 850000 | O25: 81606.195 | P25: 43287.518 | Q25: 30650.237 | R25: 24785.563 | S25: 21316.755
B26: 900000 | C26: ='Computation Table'!AN126 -> 85920.208 | D26: ='Computation Table'!AN100 -> 45566.412 | E26: ='Computation Table'!AN74 -> 32134.175 | G26: 900000 | H26: 85460.394 | I26: 45340.002 | J26: 32108.921 | K26: 25973.282 | L26: 22344.294 | N26: 900000 | O26: 86353.995 | P26: 45806.407 | Q26: 32434.066 | R26: 26228.523 | S26: 22558.105
B27: 950000 | C27: ='Computation Table'!AP126 -> 90668.007 | D27: ='Computation Table'!AP100 -> 48085.301 | E27: ='Computation Table'!AP74 -> 33910.112 | G27: 950000 | H27: 90208.193 | I27: 47858.891 | J27: 33892.75 | K27: 27416.242 | L27: 23585.643 | N27: 950000 | O27: 91101.795 | P27: 48325.296 | Q27: 34217.895 | R27: 27671.483 | S27: 23799.454
B28: 1000000 | C28: ='Computation Table'!AR126 -> 95415.807 | D28: ='Computation Table'!AR100 -> 50604.19 | E28: ='Computation Table'!AR74 -> 35686.049 | G28: 1000000 | H28: 94955.993 | I28: 50377.78 | J28: 35676.579 | K28: 28859.202 | L28: 24826.993 | N28: 1000000 | O28: 98018.53 | P28: 51976.236 | Q28: 36790.913 | R28: 29733.961 | S28: 25559.763 | T28: 35000
G29: 9% HIGHEST INTEREST RATE | N29: 9% HIGHEST INTEREST RATE
N33: Monthly Amortization | O33: 12 Months | P33: 24 Months | Q33: 36 Months | R33: 48 Months | S33: 60 Months
G34: AGE INSURANCE | H34: MAXIMUM NET PROCEEDS | J34: REQUIREMENTS | N34: 1000 | O34: 5688.8 | P34: 15086.1 | Q34: 23340 | R34: 30100 | S34: 35847.5
G35: 18 TO 65 | H35: 1200000 | J35: NON-MEDICAL LIMIT (HEALTH QUESTIONNAIRE) | N35: 1500 | O35: 10954.39 | P35: 25011.1 | Q35: 37354.8 | R35: 47425.5 | S35: 55986.8
G36: 66 TO 70 | H36: 325000 | J36: NON-MEDICAL LIMIT (HEALTH QUESTIONNAIRE) | N36: 2000 | O36: 16219.98 | P36: 34936.1 | Q36: 51369.6 | R36: 64751 | S36: 76126.1
G37: 71 TO 75 | H37: 120000 | J37: NON-MEDICAL LIMIT (HEALTH QUESTIONNAIRE) | N37: 2500 | O37: 21485.57 | P37: 44861.1 | Q37: 65384.4 | R37: 82076.5 | S37: 96265.4
N38: 3000 | O38: 26751.16 | P38: 54786.1 | Q38: 79399.2 | R38: 99402 | S38: 116404.7
N39: 3500 | O39: 32016.75 | P39: 64711.1 | Q39: 93414 | R39: 116727.5 | S39: 136544
N40: 4000 | O40: 37282.34 | P40: 74636.1 | Q40: 107428.8 | R40: 134053 | S40: 156683.3
N41: 4500 | O41: 42547.93 | P41: 84561.1 | Q41: 121443.6 | R41: 151378.5 | S41: 176822.6
N42: 5000 | O42: 47813.62 | P42: 94486.1 | Q42: 135458.4 | R42: 168704 | S42: 196961.9
N43: 5500 | O43: 53079.2 | P43: 104411.1 | Q43: 149473.2 | R43: 186029.5 | S43: 217101.2
N44: 6000 | O44: 58344.8 | P44: 114336.1 | Q44: 163488 | R44: 203355 | S44: 237240.5
N45: 6500 | O45: 63610.4 | P45: 124261.1 | Q45: 177502.8 | R45: 220680.5 | S45: 257379.8
N46: 7000 | O46: 68875.88 | P46: 134186.1 | Q46: 191517.6 | R46: 238006 | S46: 277519.1
...

Sheet Computation Table
B2: 5 Yrs
B3: GROSS | C3: =C21*C15 -> 900014.89 | E3: =E21*E15 -> 36586.601 | F3: =F21*F15 -> 79400.709 | G3: =G21*G15 -> 109759.8 | H3: =H21*H15 -> 152573.91 | I3: =I21*I15 -> 182933.01 | J3: =J21*J15 -> 225747.11 | K3: =K21*K15 -> 256106.21 | L3: =L21*L15 -> 298920.32 | ... AR3: =AR21*AR15 -> 1469691.6
B4: NET | C4: ='DATA ENTRY'!G5 -> 600010.5 | E4: 25000 | F4: 50000 | G4: 75000 | H4: 100000 | I4: 125000 | J4: 150000 | K4: 175000 | L4: 200000 | M4: 225000 | N4: 250000 | O4: 275000 | P4: 300000 | Q4: 325000 | R4: 350000 | S4: 375000 | T4: 400000 | U4: 425000 | V4: 450000 | W4: 475000 | X4: 500000 | Y4: 525000 | Z4: 550000 | AA4: 575000 | AB4: 600000 | AC4: 625000 | AD4: 650000 | AE4: 675000 | AF4: 700000 | AG4: 725000 | AH4: 750000 | AI4: 775000 | AJ4: 800000 | AK4: 825000 | AL4: 850000 | AM4: 875000 | AN4: 900000 | AO4: 925000 | AP4: 950000 | AQ4: 975000 | AR4: 1000000
B5: SF | C5: =C4*0.121 -> 72601.27 | D5: =D4*0.1 -> 0 | E5: =E4*0.1 -> 2500 | F5: =F4*0.1 -> 5000 | G5: =G4*0.1 -> 7500 | H5: =H4*0.1 -> 10000 | I5: =I4*0.1 -> 12500 | J5: =J4*0.1 -> 15000 | K5: =K4*0.1 -> 17500 | ... AR5: =AR4*0.1 -> 100000
B6: Insurance | C6: =(C4/1000)*C15 -> 36000.63 | E6: =(E4/1000)*E15 -> 1500 | F6: =(F4/1000)*F15 -> 3000 | G6: =(G4/1000)*G15 -> 4500 | H6: =(H4/1000)*H15 -> 6000 | I6: =(I4/1000)*I15 -> 7500 | J6: =(J4/1000)*J15 -> 9000 | K6: =(K4/1000)*K15 -> 10500 | L6: =(L4/1000)*L15 -> 12000 | ... AR6: =(AR4/1000)*AR15 -> 60000
B7: CapCon | C7: ='DATA ENTRY'!G9 -> 5000 | F7: =C7 -> 5000 | G7: =E7 -> 0 | H7: =F7 -> 5000 | I7: =G7 -> 0 | J7: =H7 -> 5000 | K7: =I7 -> 0 | L7: =J7 -> 5000 | M7: =K7 -> 0 | N7: =L7 -> 5000 | ... AR7: =AP7 -> 5000
B8: membership fee | C8: ='DATA ENTRY'!G10 -> 0 | F8: =C8 -> 0 | G8: =E8 -> 0 | H8: =F8 -> 0 | I8: =G8 -> 0 | J8: =H8 -> 0 | K8: =I8 -> 0 | L8: =J8 -> 0 | M8: =K8 -> 0 | N8: =L8 -> 0 | ... AR8: =AP8 -> 0
B9: Advance Interest | C9: =C14*C4*2 -> 9000.1575 | E9: =E14*E4*2 -> 375 | F9: =F14*F4*2 -> 750 | G9: =G14*G4*2 -> 1125 | H9: =H14*H4*2 -> 1500 | I9: =I14*I4*2 -> 1875 | J9: =J14*J4*2 -> 2250 | K9: =K14*K4*2 -> 2625 | L9: =L14*L4*2 -> 3000 | ... AR9: =AR14*AR4*2 -> 15000
B10: LOAN AMOUNT | C10: =SUM(C4:C9) -> 722612.56 | E10: =SUM(E4:E9) -> 29375 | F10: =SUM(F4:F9) -> 63750 | G10: =SUM(G4:G9) -> 88125 | H10: =SUM(H4:H9) -> 122500 | I10: =SUM(I4:I9) -> 146875 | J10: =SUM(J4:J9) -> 181250 | K10: =SUM(K4:K9) -> 205625 | L10: =SUM(L4:L9) -> 240000 | ... AR10: =SUM(AR4:AR9) -> 1180000
B11: Annual Interest | C11: 0.09 | E11: =C11 -> 0.09 | F11: =C11 -> 0.09 | G11: =F11 -> 0.09 | H11: =G11 -> 0.09 | I11: =H11 -> 0.09 | J11: =I11 -> 0.09 | K11: =J11 -> 0.09 | L11: =K11 -> 0.09 | M11: =L11 -> 0.09 | N11: =M11 -> 0.09 | ... W11: =V11 -> 0.09 | X11: 0.087 | Y11: =W11 -> 0.09 | Z11: =Y11 -> 0.09 | AA11: =Z11 -> 0.09 | AB11: =AA11 -> 0.09 | AC11: =AB11 -> 0.09 | AD11: =AC11 -> 0.09 | AE11: =AD11 -> 0.09 | AF11: =AE11 -> 0.09 | AG11: =AF11 -> 0.09 | ... AQ11: =AP11 -> 0.09 | AR11: 0.09
B12: Effective Interest rate | C12: =(1+C11/C15)^C15-1 -> 0.094100503 | E12: =(1+E11/E15)^E15-1 -> 0.094100503 | F12: =(1+F11/F15)^F15-1 -> 0.094100503 | G12: =(1+G11/G15)^G15-1 -> 0.094100503 | H12: =(1+H11/H15)^H15-1 -> 0.094100503 | I12: =(1+I11/I15)^I15-1 -> 0.094100503 | J12: =(1+J11/J15)^J15-1 -> 0.094100503 | K12: =(1+K11/K15)^K15-1 -> 0.094100503 | L12: =(1+L11/L15)^L15-1 -> 0.094100503 | ... AR12: =(1+AR11/AR15)^AR15-1 -> 0.094100503
B13: Loan Term | C13: 5 | E13: 5 | F13: 5 | G13: 5 | H13: 5 | I13: 5 | J13: 5 | K13: 5 | L13: 5 | M13: 5 | N13: 5 | O13: 5 | P13: 5 | Q13: 5 | R13: 5 | S13: 5 | T13: =P13 -> 5 | U13: =Q13 -> 5 | V13: =R13 -> 5 | W13: =S13 -> 5 | X13: =T13 -> 5 | Y13: =U13 -> 5 | Z13: =V13 -> 5 | AA13: =W13 -> 5 | ... AR13: =AN13 -> 5
B14: Monthly Interest Rate | C14: =C11/12 -> 0.0075 | E14: =E11/12 -> 0.0075 | F14: =F11/12 -> 0.0075 | G14: =G11/12 -> 0.0075 | H14: =H11/12 -> 0.0075 | I14: =I11/12 -> 0.0075 | J14: =J11/12 -> 0.0075 | K14: =K11/12 -> 0.0075 | L14: =L11/12 -> 0.0075 | ... AR14: =AR11/12 -> 0.0075
B15: Nr of Payments | C15: =C13*12 -> 60 | E15: =E13*12 -> 60 | F15: =F13*12 -> 60 | G15: =G13*12 -> 60 | H15: =H13*12 -> 60 | I15: =I13*12 -> 60 | J15: =J13*12 -> 60 | K15: =K13*12 -> 60 | L15: =L13*12 -> 60 | ... AR15: =AR13*12 -> 60
B17: Monthly Amortization | C17: =(1+C14)^C15 -> 1.565681 | E17: =(1+E14)^E15 -> 1.565681 | F17: =(1+F14)^F15 -> 1.565681 | G17: =(1+G14)^G15 -> 1.565681 | H17: =(1+H14)^H15 -> 1.565681 | I17: =(1+I14)^I15 -> 1.565681 | J17: =(1+J14)^J15 -> 1.565681 | K17: =(1+K14)^K15 -> 1.565681 | L17: =(1+L14)^L15 -> 1.565681 | ... AR17: =(1+AR14)^AR15 -> 1.565681
C18: =C17*C14 -> 0.011742608 | E18: =E17*E14 -> 0.011742608 | F18: =F17*F14 -> 0.011742608 | G18: =G17*G14 -> 0.011742608 | H18: =H17*H14 -> 0.011742608 | I18: =I17*I14 -> 0.011742608 | J18: =J17*J14 -> 0.011742608 | K18: =K17*K14 -> 0.011742608 | L18: =L17*L14 -> 0.011742608 | ... AR18: =AR17*AR14 -> 0.011742608
C19: =C17-1 -> 0.56568103 | E19: =E17-1 -> 0.56568103 | F19: =F17-1 -> 0.56568103 | G19: =G17-1 -> 0.56568103 | H19: =H17-1 -> 0.56568103 | I19: =I17-1 -> 0.56568103 | J19: =J17-1 -> 0.56568103 | K19: =K17-1 -> 0.56568103 | L19: =L17-1 -> 0.56568103 | ... AR19: =AR17-1 -> 0.56568103
C20: =C18/C19 -> 0.020758355 | E20: =E18/E19 -> 0.020758355 | F20: =F18/F19 -> 0.020758355 | G20: =G18/G19 -> 0.020758355 | H20: =H18/H19 -> 0.020758355 | I20: =I18/I19 -> 0.020758355 | J20: =J18/J19 -> 0.020758355 | K20: =K18/K19 -> 0.020758355 | L20: =L18/L19 -> 0.020758355 | ... AR20: =AR18/AR19 -> 0.020758355
B21: Monthly Amortization | C21: =C20*C10 -> 15000.248 | E21: =E20*E10 -> 609.77668 | F21: =F20*F10 -> 1323.3451 | G21: =G20*G10 -> 1829.3301 | H21: =H20*H10 -> 2542.8985 | I21: =I20*I10 -> 3048.8834 | J21: =J20*J10 -> 3762.4519 | K21: =K20*K10 -> 4268.4368 | L21: =L20*L10 -> 4982.0053 | ... AR21: =AR20*AR10 -> 24494.859
B23: Income | C23: =C3-C4 -> 300004.39 | E23: =E3-E4 -> 11586.601 | F23: =F3-F4 -> 29400.709 | G23: =G3-G4 -> 34759.803 | H23: =H3-H4 -> 52573.911 | I23: =I3-I4 -> 57933.005 | J23: =J3-J4 -> 75747.113 | K23: =K3-K4 -> 81106.208 | L23: =L3-L4 -> 98920.315 | ... AR23: =AR3-AR4 -> 469691.55
B24: % Income | C24: =C23/C3 -> 0.3333327 | E24: =E23/E3 -> 0.31668974 | F24: =F23/F3 -> 0.3702827 | G24: =G23/G3 -> 0.31668974 | H24: =H23/H3 -> 0.34457995 | I24: =I23/I3 -> 0.31668974 | J24: =J23/J3 -> 0.33553968 | K24: =K23/K3 -> 0.31668974 | L24: =L23/L3 -> 0.33092537 | ... AR24: =AR23/AR3 -> 0.31958512
B28: 4 yrs
B29: GROSS | C29: =C47*C41 -> 133026.28 | E29: =E47*E41 -> 33543.169 | F29: =F47*F41 -> 73033.709 | G29: =G47*G41 -> 100629.51 | H29: =H47*H41 -> 140120.05 | I29: =I47*I41 -> 167715.85 | J29: =J47*J41 -> 207206.39 | K29: =K47*K41 -> 234802.18 | L29: =L47*L41 -> 274292.72 | ... AR29: =AR47*AR41 -> 1347674.1
B30: NET | C30: ='DATA ENTRY'!F5 -> 93500 | E30: 25000 | F30: 50000 | G30: 75000 | H30: 100000 | I30: 125000 | J30: 150000 | K30: 175000 | L30: 200000 | M30: 225000 | N30: 250000 | O30: 275000 | P30: 300000 | Q30: 325000 | R30: 350000 | S30: 375000 | T30: 400000 | U30: 425000 | V30: 450000 | W30: 475000 | X30: 500000 | Y30: 525000 | Z30: 550000 | AA30: 575000 | AB30: 600000 | AC30: 625000 | AD30: 650000 | AE30: 675000 | AF30: 700000 | AG30: 725000 | AH30: 750000 | AI30: 775000 | AJ30: 800000 | AK30: 825000 | AL30: 850000 | AM30: 875000 | AN30: 900000 | AO30: 925000 | AP30: 950000 | AQ30: 975000 | AR30: 1000000
B31: SF | C31: =C30*0.08 -> 7480 | E31: =E30*0.08 -> 2000 | F31: =F30*0.08 -> 4000 | G31: =G30*0.08 -> 6000 | H31: =H30*0.08 -> 8000 | I31: =I30*0.08 -> 10000 | J31: =J30*0.08 -> 12000 | K31: =K30*0.08 -> 14000 | L31: =L30*0.08 -> 16000 | ... AR31: =AR30*0.08 -> 80000
B32: Insurance | C32: =(C30/1000)*C41 -> 4488 | E32: =(E30/1000)*E41 -> 1200 | F32: =(F30/1000)*F41 -> 2400 | G32: =(G30/1000)*G41 -> 3600 | H32: =(H30/1000)*H41 -> 4800 | I32: =(I30/1000)*I41 -> 6000 | J32: =(J30/1000)*J41 -> 7200 | K32: =(K30/1000)*K41 -> 8400 | L32: =(L30/1000)*L41 -> 9600 | ... AR32: =(AR30/1000)*AR41 -> 48000
B33: CapCon | C33: ='DATA ENTRY'!F9 -> 5000 | F33: =C33 -> 5000 | G33: =E33 -> 0 | H33: =F33 -> 5000 | I33: =G33 -> 0 | J33: =H33 -> 5000 | K33: =I33 -> 0 | L33: =J33 -> 5000 | M33: =K33 -> 0 | N33: =L33 -> 5000 | ... AR33: =AP33 -> 5000
B34: membership fee | C34: ='DATA ENTRY'!F10 -> 0 | F34: =C34 -> 0 | G34: =E34 -> 0 | H34: =F34 -> 0 | I34: =G34 -> 0 | J34: =H34 -> 0 | K34: =I34 -> 0 | L34: =J34 -> 0 | M34: =K34 -> 0 | N34: =L34 -> 0 | ... AR34: =AP34 -> 0
B35: Advance Interest | C35: =C40*C30*2 -> 1368.2167 | E35: =E40*E30*2 -> 365.83333 | F35: =F40*F30*2 -> 731.66667 | G35: =G40*G30*2 -> 1097.5 | H35: =H40*H30*2 -> 1463.3333 | I35: =I40*I30*2 -> 1829.1667 | J35: =J40*J30*2 -> 2195 | K35: =K40*K30*2 -> 2560.8333 | L35: =L40*L30*2 -> 2926.6667 | ... AR35: =AR40*AR30*2 -> 14633.333
B36: LOAN AMOUNT | C36: =SUM(C30:C35) -> 111836.22 | E36: =SUM(E30:E34) -> 28200 | F36: =SUM(F30:F34) -> 61400 | G36: =SUM(G30:G34) -> 84600 | H36: =SUM(H30:H34) -> 117800 | I36: =SUM(I30:I34) -> 141000 | J36: =SUM(J30:J34) -> 174200 | K36: =SUM(K30:K34) -> 197400 | L36: =SUM(L30:L34) -> 230600 | ... AR36: =SUM(AR30:AR34) -> 1133000
B37: Annual Interest | C37: 0.0878 | E37: 0.0878 | F37: =C37 -> 0.0878 | G37: =F37 -> 0.0878 | H37: =F37 -> 0.0878 | I37: =G37 -> 0.0878 | J37: =H37 -> 0.0878 | K37: =I37 -> 0.0878 | L37: =J37 -> 0.0878 | M37: =K37 -> 0.0878 | N37: =L37 -> 0.0878 | O37: =M37 -> 0.0878 | ... AR37: =AP37 -> 0.0878
B38: Effective Interest rate | C38: =(1+C37/C41)^C41-1 -> 0.091682187 | E38: =(1+E37/E41)^E41-1 -> 0.091682187 | F38: =(1+F37/F41)^F41-1 -> 0.091682187 | G38: =(1+G37/G41)^G41-1 -> 0.091682187 | H38: =(1+H37/H41)^H41-1 -> 0.091682187 | I38: =(1+I37/I41)^I41-1 -> 0.091682187 | J38: =(1+J37/J41)^J41-1 -> 0.091682187 | K38: =(1+K37/K41)^K41-1 -> 0.091682187 | L38: =(1+L37/L41)^L41-1 -> 0.091682187 | ... AR38: =(1+AR37/AR41)^AR41-1 -> 0.091682187
B39: Loan Term | C39: 4 | E39: 4 | F39: 4 | G39: 4 | H39: 4 | I39: 4 | J39: 4 | K39: 4 | L39: =H39 -> 4 | M39: =I39 -> 4 | N39: =K39 -> 4 | O39: =K39 -> 4 | P39: =L39 -> 4 | Q39: =M39 -> 4 | R39: =N39 -> 4 | S39: =O39 -> 4 | T39: =P39 -> 4 | U39: =Q39 -> 4 | V39: =R39 -> 4 | ... AR39: =AN39 -> 4
B40: Monthly Interest Rate | C40: =C37/12 -> 0.0073166667 | E40: =E37/12 -> 0.0073166667 | F40: =F37/12 -> 0.0073166667 | G40: =G37/12 -> 0.0073166667 | H40: =H37/12 -> 0.0073166667 | I40: =I37/12 -> 0.0073166667 | J40: =J37/12 -> 0.0073166667 | K40: =K37/12 -> 0.0073166667 | L40: =L37/12 -> 0.0073166667 | ... AR40: =AR37/12 -> 0.0073166667
B41: Nr of Payments | C41: =C39*12 -> 48 | E41: =E39*12 -> 48 | F41: =F39*12 -> 48 | G41: =G39*12 -> 48 | H41: =H39*12 -> 48 | I41: =I39*12 -> 48 | J41: =J39*12 -> 48 | K41: =K39*12 -> 48 | L41: =L39*12 -> 48 | ... AR41: =AR39*12 -> 48
B43: Monthly Amortization | C43: =(1+C40)^C41 -> 1.4189561 | E43: =(1+E40)^E41 -> 1.4189561 | F43: =(1+F40)^F41 -> 1.4189561 | G43: =(1+G40)^G41 -> 1.4189561 | H43: =(1+H40)^H41 -> 1.4189561 | I43: =(1+I40)^I41 -> 1.4189561 | J43: =(1+J40)^J41 -> 1.4189561 | K43: =(1+K40)^K41 -> 1.4189561 | L43: =(1+L40)^L41 -> 1.4189561 | ... AR43: =(1+AR40)^AR41 -> 1.4189561
C44: =C43*C40 -> 0.010382028 | E44: =E43*E40 -> 0.010382028 | F44: =F43*F40 -> 0.010382028 | G44: =G43*G40 -> 0.010382028 | H44: =H43*H40 -> 0.010382028 | I44: =I43*I40 -> 0.010382028 | J44: =J43*J40 -> 0.010382028 | K44: =K43*K40 -> 0.010382028 | L44: =L43*L40 -> 0.010382028 | ... AR44: =AR43*AR40 -> 0.010382028
C45: =C43-1 -> 0.41895605 | E45: =E43-1 -> 0.41895605 | F45: =F43-1 -> 0.41895605 | G45: =G43-1 -> 0.41895605 | H45: =H43-1 -> 0.41895605 | I45: =I43-1 -> 0.41895605 | J45: =J43-1 -> 0.41895605 | K45: =K43-1 -> 0.41895605 | L45: =L43-1 -> 0.41895605 | ... AR45: =AR43-1 -> 0.41895605
C46: =C44/C45 -> 0.02478071 | E46: =E44/E45 -> 0.02478071 | F46: =F44/F45 -> 0.02478071 | G46: =G44/G45 -> 0.02478071 | H46: =H44/H45 -> 0.02478071 | I46: =I44/I45 -> 0.02478071 | J46: =J44/J45 -> 0.02478071 | K46: =K44/K45 -> 0.02478071 | L46: =L44/L45 -> 0.02478071 | ... AR46: =AR44/AR45 -> 0.02478071
B47: Monthly Amortization | C47: =C46*C36 -> 2771.3809 | E47: =E46*E36 -> 698.81602 | F47: =F46*F36 -> 1521.5356 | G47: =G46*G36 -> 2096.4481 | H47: =H46*H36 -> 2919.1676 | I47: =I46*I36 -> 3494.0801 | J47: =J46*J36 -> 4316.7997 | K47: =K46*K36 -> 4891.7122 | L47: =L46*L36 -> 5714.4317 | ... AR47: =AR46*AR36 -> 28076.545
...

Sheet 3 YEARS
B1: Amortization | C1: ='DATA ENTRY'!E15 -> 1499.9958
B2: Timeline | C2: 0 | D2: 1 | E2: 2 | F2: 3 | G2: 4 | H2: 5 | I2: 6 | J2: 7 | K2: 8 | L2: 9 | M2: 10 | N2: 11 | O2: 12 | P2: 13 | Q2: 14 | R2: 15 | S2: 16 | T2: 17 | U2: 18 | V2: 19 | W2: 20 | X2: 21 | Y2: 22 | Z2: 23 | AA2: 24 | AB2: 25 | AC2: 26 | AD2: 27 | AE2: 28 | AF2: 29 | AG2: 30 | AH2: 31 | AI2: 32 | AJ2: 33 | AK2: 34 | AL2: 35 | AM2: 36 | AN2: 37 | AO2: 38 | AP2: 39 | AQ2: 40 | AR2: 41 | AS2: 42 | AT2: 43 | AU2: 44 | AV2: 45 | AW2: 46 | AX2: 47 | AY2: 48 | AZ2: 49 | BA2: 50 | BB2: 51 | BC2: 52 | BD2: 53 | BE2: 54 | BF2: 55 | BG2: 56 | BH2: 57 | BI2: 58 | BJ2: 59 | BK2: 60
B3: GROSS AMOUNT | C3: ='DATA ENTRY'!E4 -> 53999.85
B4: LOAN AMOUNT | C4: ='DATA ENTRY'!D12 -> 109021.87 | D4: =D10 -> -1499.9958 | E4: =E10 -> -1499.9958 | F4: =F10 -> -1499.9958 | G4: =G10 -> -1499.9958 | H4: =H10 -> -1499.9958 | I4: =I10 -> -1499.9958 | J4: =J10 -> -1499.9958 | K4: =K10 -> -1499.9958 | ... AY4: =AY10 -> -1499.9958
B5: Service Fee | C5: ='DATA ENTRY'!E7 -> 2988.376
B6: Insurance | C6: ='DATA ENTRY'!E8 -> 1344.7692
B7: CapCon | C7: ='DATA ENTRY'!E9 -> 5000
B8: membership fee | C8: ='DATA ENTRY'!E10 -> 300
B9: Advance Interest | C9: ='DATA ENTRY'!E11 -> 529.19158
B10: NET PROCEEDS/CASH FLOW | C10: =C4-C5-C6-C7-C8-C9-C13 -> 57135.55 | D10: =-$C1 -> -1499.9958 | E10: =-$C1 -> -1499.9958 | F10: =-$C1 -> -1499.9958 | G10: =-$C1 -> -1499.9958 | H10: =-$C1 -> -1499.9958 | I10: =-$C1 -> -1499.9958 | J10: =-$C1 -> -1499.9958 | K10: =-$C1 -> -1499.9958 | ... BK10: =-$C1 -> -1499.9958
B12: Interest Rate of Return | C12: =IRR(C4:AY4) -> -0.015816905 | D12: =C12/5 -> -0.003163381
B13: Outstanding Balance | C13: ='[1]ACTIVE CIV.'!$D$41 -> 41723.98
B14: Annual Interest Rate | C14: ='[2]AMORTIZATION '!$D$26 -> 0.016
B15: Effective Interest Rate | C15: ='DATA ENTRY'!F14 -> 0.091682187
C20: LOAN LEDGER CARD
C22: Name: | D22: CARLITO VASQUEZ GARCIA | G22: Loan Voucher No. | H22: LV- 047
C23: Serial: | D23: 637617 | E23: Address: | F23: PEMBO, MAKATI CITY , METRO MANILA | G23: Amount: | H23: =C10 -> 57135.55
C24: Posting date | D24: Date of Loan: | E24: 45846 | F24: Maturity Date | G24: =B75 -> 47430
D25: Term: | E25: 48 | F25: MOS
D26: Loan | E26: Installment | F26: Principal | G26: EIR | H26: Balance
H27: =C4 -> 109021.87
B28: =DATE(YEAR($E$24),MONTH($E$24)+D28+4,DAY($E$24)) -> 45999 | C28: =TEXT(B28,"mmm-yyyy") -> Dec-2025 | D28: 1 | E28: =C$1 -> 1499.9958 | F28: =E28-G28 -> 3224.3843 | G28: =H27*C$12 -> -1724.3885 | H28: =H27-F28 -> 105797.48
B29: =DATE(YEAR($E$24),MONTH($E$24)+D29+4,DAY($E$24)) -> 46030 | C29: =TEXT(B29,"mmm-yyyy") -> Jan-2026 | D29: 2 | E29: =C$1 -> 1499.9958 | F29: =E29-G29 -> 3173.3846 | G29: =H28*C$12 -> -1673.3887 | H29: =H28-F29 -> 102624.1
B30: =DATE(YEAR($E$24),MONTH($E$24)+D30+4,DAY($E$24)) -> 46061 | C30: =TEXT(B30,"mmm-yyyy") -> Feb-2026 | D30: 3 | E30: =C$1 -> 1499.9958 | F30: =E30-G30 -> 3123.1914 | G30: =H29*C$12 -> -1623.1956 | H30: =H29-F30 -> 99500.906
B31: =DATE(YEAR($E$24),MONTH($E$24)+D31+4,DAY($E$24)) -> 46089 | C31: =TEXT(B31,"mmm-yyyy") -> Mar-2026 | D31: 4 | E31: =C$1 -> 1499.9958 | F31: =E31-G31 -> 3073.7922 | G31: =H30*C$12 -> -1573.7964 | H31: =H30-F31 -> 96427.114
B32: =DATE(YEAR($E$24),MONTH($E$24)+D32+4,DAY($E$24)) -> 46120 | C32: =TEXT(B32,"mmm-yyyy") -> Apr-2026 | D32: 5 | E32: =C$1 -> 1499.9958 | F32: =E32-G32 -> 3025.1743 | G32: =H31*C$12 -> -1525.1785 | H32: =H31-F32 -> 93401.94
B33: =DATE(YEAR($E$24),MONTH($E$24)+D33+4,DAY($E$24)) -> 46150 | C33: =TEXT(B33,"mmm-yyyy") -> May-2026 | D33: 6 | E33: =C$1 -> 1499.9958 | F33: =E33-G33 -> 2977.3254 | G33: =H32*C$12 -> -1477.3296 | H33: =H32-F33 -> 90424.614
B34: =DATE(YEAR($E$24),MONTH($E$24)+D34+4,DAY($E$24)) -> 46181 | C34: =TEXT(B34,"mmm-yyyy") -> Jun-2026 | D34: 7 | E34: =C$1 -> 1499.9958 | F34: =E34-G34 -> 2930.2334 | G34: =H33*C$12 -> -1430.2375 | H34: =H33-F34 -> 87494.381
B35: =DATE(YEAR($E$24),MONTH($E$24)+D35+4,DAY($E$24)) -> 46211 | C35: =TEXT(B35,"mmm-yyyy") -> Jul-2026 | D35: 8 | E35: =C$1 -> 1499.9958 | F35: =E35-G35 -> 2883.8861 | G35: =H34*C$12 -> -1383.8903 | H35: =H34-F35 -> 84610.495
B36: =DATE(YEAR($E$24),MONTH($E$24)+D36+4,DAY($E$24)) -> 46242 | C36: =TEXT(B36,"mmm-yyyy") -> Aug-2026 | D36: 9 | E36: =C$1 -> 1499.9958 | F36: =E36-G36 -> 2838.272 | G36: =H35*C$12 -> -1338.2762 | H36: =H35-F36 -> 81772.223
B37: =DATE(YEAR($E$24),MONTH($E$24)+D37+4,DAY($E$24)) -> 46273 | C37: =TEXT(B37,"mmm-yyyy") -> Sep-2026 | D37: 10 | E37: =C$1 -> 1499.9958 | F37: =E37-G37 -> 2793.3793 | G37: =H36*C$12 -> -1293.3835 | H37: =H36-F37 -> 78978.844
B38: =DATE(YEAR($E$24),MONTH($E$24)+D38+4,DAY($E$24)) -> 46303 | C38: =TEXT(B38,"mmm-yyyy") -> Oct-2026 | D38: 11 | E38: =C$1 -> 1499.9958 | F38: =E38-G38 -> 2749.1967 | G38: =H37*C$12 -> -1249.2009 | H38: =H37-F38 -> 76229.647
B39: =DATE(YEAR($E$24),MONTH($E$24)+D39+4,DAY($E$24)) -> 46334 | C39: =TEXT(B39,"mmm-yyyy") -> Nov-2026 | D39: 12 | E39: =C$1 -> 1499.9958 | F39: =E39-G39 -> 2705.7129 | G39: =H38*C$12 -> -1205.7171 | H39: =H38-F39 -> 73523.934
... B64: =DATE(YEAR($E$24),MONTH($E$24)+D64+4,DAY($E$24)) -> 47095 | C64: =TEXT(B64,"mmm-yyyy") -> Dec-2028 | D64: 37 | E64: =C$1 -> 1499.9958 | F64: =E64-G64 -> 1816.2651 | G64: =H63*C$12 -> -316.26928 | H64: =H63-F64 -> 18179.384
A65: i | B65: =DATE(YEAR($E$24),MONTH($E$24)+D65+4,DAY($E$24)) -> 47126 | C65: =TEXT(B65,"mmm-yyyy") -> Jan-2029 | D65: 38 | E65: =C$1 -> 1499.9958 | F65: =E65-G65 -> 1787.5374 | G65: =H64*C$12 -> -287.54158 | H65: =H64-F65 -> 16391.846
B66: =DATE(YEAR($E$24),MONTH($E$24)+D66+4,DAY($E$24)) -> 47157 | C66: =TEXT(B66,"mmm-yyyy") -> Feb-2029 | D66: 39 | E66: =C$1 -> 1499.9958 | F66: =E66-G66 -> 1759.2641 | G66: =H65*C$12 -> -259.26827 | H66: =H65-F66 -> 14632.582
B67: =DATE(YEAR($E$24),MONTH($E$24)+D67+4,DAY($E$24)) -> 47185 | C67: =TEXT(B67,"mmm-yyyy") -> Mar-2029 | D67: 40 | E67: =C$1 -> 1499.9958 | F67: =E67-G67 -> 1731.438 | G67: =H66*C$12 -> -231.44216 | H67: =H66-F67 -> 12901.144
B68: =DATE(YEAR($E$24),MONTH($E$24)+D68+4,DAY($E$24)) -> 47216 | C68: =TEXT(B68,"mmm-yyyy") -> Apr-2029 | D68: 41 | E68: =C$1 -> 1499.9958 | F68: =E68-G68 -> 1704.052 | G68: =H67*C$12 -> -204.05617 | H68: =H67-F68 -> 11197.092
B69: =DATE(YEAR($E$24),MONTH($E$24)+D69+4,DAY($E$24)) -> 47246 | C69: =TEXT(B69,"mmm-yyyy") -> May-2029 | D69: 42 | E69: =C$1 -> 1499.9958 | F69: =E69-G69 -> 1677.0992 | G69: =H68*C$12 -> -177.10334 | H69: =H68-F69 -> 9519.993
B70: =DATE(YEAR($E$24),MONTH($E$24)+D70+4,DAY($E$24)) -> 47277 | C70: =TEXT(B70,"mmm-yyyy") -> Jun-2029 | D70: 43 | E70: =C$1 -> 1499.9958 | F70: =E70-G70 -> 1650.5727 | G70: =H69*C$12 -> -150.57682 | H70: =H69-F70 -> 7869.4203
...

Sheet 5 YEARS
B1: Amortization | C1: ='DATA ENTRY'!G15 -> 15000.248
B2: Timeline | C2: 0 | D2: 1 | E2: 2 | F2: 3 | G2: 4 | H2: 5 | I2: 6 | J2: 7 | K2: 8 | L2: 9 | M2: 10 | N2: 11 | O2: 12 | P2: 13 | Q2: 14 | R2: 15 | S2: 16 | T2: 17 | U2: 18 | V2: 19 | W2: 20 | X2: 21 | Y2: 22 | Z2: 23 | AA2: 24 | AB2: 25 | AC2: 26 | AD2: 27 | AE2: 28 | AF2: 29 | AG2: 30 | AH2: 31 | AI2: 32 | AJ2: 33 | AK2: 34 | AL2: 35 | AM2: 36 | AN2: 37 | AO2: 38 | AP2: 39 | AQ2: 40 | AR2: 41 | AS2: 42 | AT2: 43 | AU2: 44 | AV2: 45 | AW2: 46 | AX2: 47 | AY2: 48 | AZ2: 49 | BA2: 50 | BB2: 51 | BC2: 52 | BD2: 53 | BE2: 54 | BF2: 55 | BG2: 56 | BH2: 57 | BI2: 58 | BJ2: 59 | BK2: 60
B3: GROSS AMOUNT | C3: ='DATA ENTRY'!G4 -> 900014.89
B4: LOAN AMOUNT | C4: ='DATA ENTRY'!G12 -> 722612.56 | D4: =D10 -> -15000.248 | E4: =E10 -> -15000.248 | F4: =F10 -> -15000.248 | G4: =G10 -> -15000.248 | H4: =H10 -> -15000.248 | I4: =I10 -> -15000.248 | J4: =J10 -> -15000.248 | K4: =K10 -> -15000.248 | ... BK4: =BK10 -> -15000.248
B5: Service Fee | C5: ='DATA ENTRY'!G7 -> 72601.27
B6: Insurance | C6: ='DATA ENTRY'!G8 -> 36000.63
B7: CapCon | C7: ='DATA ENTRY'!G9 -> 5000
B8: membership fee | C8: ='DATA ENTRY'!G10 -> 0
B9: Advance Interest | C9: ='DATA ENTRY'!G11 -> 9000.1575
B10: NET PROCEEDS/CASH FLOW | C10: =C4-C5-C6-C7-C8-C9 -> 600010.5 | D10: =-$C1 -> -15000.248 | E10: =-$C1 -> -15000.248 | F10: =-$C1 -> -15000.248 | G10: =-$C1 -> -15000.248 | H10: =-$C1 -> -15000.248 | I10: =-$C1 -> -15000.248 | J10: =-$C1 -> -15000.248 | K10: =-$C1 -> -15000.248 | ... BK10: =-$C1 -> -15000.248
B12: Interest Rate of Return | C12: =IRR(C4:BK4) -> 0.0075 | D12: =C12/5 -> 0.0015
B14: ='DATA ENTRY'!B13 -> Annual Interest Rate | C14: ='DATA ENTRY'!G13 -> 0.09
B15: ='DATA ENTRY'!B14 -> Effective Interest Rate | C15: ='DATA ENTRY'!G14 -> 0.094100503
C20: LOAN LEDGER CARD
C22: Name: | D22: MARTIN BARROGA RICARDO | G22: Loan Voucher No. | H22: LV - 047
C23: Serial: | D23: O- 127212 | E23: Address: | F23: B4 L14 DEROSA ST. MS2, LNC, BRGY NAVARRO, CITY OF GENERAL TRIAS, CAVITE | G23: Amount: | H23: =C10 -> 600010.5
C24: Posting date | D24: Date of Loan: | E24: 45722 | F24: Maturity Date | G24: =B87 -> 47579
D25: Term: | E25: 60 | F25: MOS
D26: Loan | E26: Installment | F26: Principal | G26: EIR | H26: Balance
D27: Month 0 | H27: =C4 -> 722612.56
B28: =DATE(YEAR($E$24),MONTH($E$24)+D28+1,DAY($E$24)) -> 45783 | C28: =TEXT(B28,"mmm-yyyy") -> May-2025 | D28: 1 | E28: =C$1 -> 15000.248 | F28: =E28-G28 -> 9580.654 | G28: =H27*C$12 -> 5419.5942 | H28: =H27-F28 -> 713031.9
B29: =DATE(YEAR($E$24),MONTH($E$24)+D29+1,DAY($E$24)) -> 45814 | C29: =TEXT(B29,"mmm-yyyy") -> Jun-2025 | D29: 2 | E29: =C$1 -> 15000.248 | F29: =E29-G29 -> 9652.5089 | G29: =H28*C$12 -> 5347.7393 | H29: =H28-F29 -> 703379.4
B30: =DATE(YEAR($E$24),MONTH($E$24)+D30+1,DAY($E$24)) -> 45844 | C30: =TEXT(B30,"mmm-yyyy") -> Jul-2025 | D30: 3 | E30: =C$1 -> 15000.248 | F30: =E30-G30 -> 9724.9027 | G30: =H29*C$12 -> 5275.3455 | H30: =H29-F30 -> 693654.49
B31: =DATE(YEAR($E$24),MONTH($E$24)+D31+1,DAY($E$24)) -> 45875 | C31: =TEXT(B31,"mmm-yyyy") -> Aug-2025 | D31: 4 | E31: =C$1 -> 15000.248 | F31: =E31-G31 -> 9797.8395 | G31: =H30*C$12 -> 5202.4087 | H31: =H30-F31 -> 683856.65
B32: =DATE(YEAR($E$24),MONTH($E$24)+D32+1,DAY($E$24)) -> 45906 | C32: =TEXT(B32,"mmm-yyyy") -> Sep-2025 | D32: 5 | E32: =C$1 -> 15000.248 | F32: =E32-G32 -> 9871.3233 | G32: =H31*C$12 -> 5128.9249 | H32: =H31-F32 -> 673985.33
B33: =DATE(YEAR($E$24),MONTH($E$24)+D33+1,DAY($E$24)) -> 45936 | C33: =TEXT(B33,"mmm-yyyy") -> Oct-2025 | D33: 6 | E33: =C$1 -> 15000.248 | F33: =E33-G33 -> 9945.3582 | G33: =H32*C$12 -> 5054.89 | H33: =H32-F33 -> 664039.97
B34: =DATE(YEAR($E$24),MONTH($E$24)+D34+1,DAY($E$24)) -> 45967 | C34: =TEXT(B34,"mmm-yyyy") -> Nov-2025 | D34: 7 | E34: =C$1 -> 15000.248 | F34: =E34-G34 -> 10019.948 | G34: =H33*C$12 -> 4980.2998 | H34: =H33-F34 -> 654020.02
B35: =DATE(YEAR($E$24),MONTH($E$24)+D35+1,DAY($E$24)) -> 45997 | C35: =TEXT(B35,"mmm-yyyy") -> Dec-2025 | D35: 8 | E35: =C$1 -> 15000.248 | F35: =E35-G35 -> 10095.098 | G35: =H34*C$12 -> 4905.1502 | H35: =H34-F35 -> 643924.93
B36: =DATE(YEAR($E$24),MONTH($E$24)+D36+1,DAY($E$24)) -> 46028 | C36: =TEXT(B36,"mmm-yyyy") -> Jan-2026 | D36: 9 | E36: =C$1 -> 15000.248 | F36: =E36-G36 -> 10170.811 | G36: =H35*C$12 -> 4829.4369 | H36: =H35-F36 -> 633754.11
B37: =DATE(YEAR($E$24),MONTH($E$24)+D37+1,DAY($E$24)) -> 46059 | C37: =TEXT(B37,"mmm-yyyy") -> Feb-2026 | D37: 10 | E37: =C$1 -> 15000.248 | F37: =E37-G37 -> 10247.092 | G37: =H36*C$12 -> 4753.1559 | H37: =H36-F37 -> 623507.02
B38: =DATE(YEAR($E$24),MONTH($E$24)+D38+1,DAY($E$24)) -> 46087 | C38: =TEXT(B38,"mmm-yyyy") -> Mar-2026 | D38: 11 | E38: =C$1 -> 15000.248 | F38: =E38-G38 -> 10323.946 | G38: =H37*C$12 -> 4676.3027 | H38: =H37-F38 -> 613183.08
B39: =DATE(YEAR($E$24),MONTH($E$24)+D39+1,DAY($E$24)) -> 46118 | C39: =TEXT(B39,"mmm-yyyy") -> Apr-2026 | D39: 12 | E39: =C$1 -> 15000.248 | F39: =E39-G39 -> 10401.375 | G39: =H38*C$12 -> 4598.8731 | H39: =H38-F39 -> 602781.7
... B87: =DATE(YEAR($E$24),MONTH($E$24)+D87+1,DAY($E$24)) -> 47579 | C87: =TEXT(B87,"mmm-yyyy") -> Apr-2030 | D87: 60 | E87: =C$1 -> 15000.248 | F87: =E87-G87 -> 14888.584 | G87: =H86*C$12 -> 111.66438 | H87: =H86-F87 -> -1.8299033e-09
E88: =SUM(E28:E87) -> 900014.89 | F88: =SUM(F28:F87) -> 722612.56
K95: PEOPLE'S MULTI-PURPOSE COOPERATIVE
K96: 20-E 2nd Camarilla St. corner 15th Ave., Brgy. San Roque, Murphy Cubao, Quezon City
K98: LOAN RELEASE VOUCHER
R100: Date: | S100: =E24 -> 45722
R101: LV No: | S101: =H22 -> LV - 047
K104: Name of Borrower: | N104: =D22 -> MARTIN BARROGA RICARDO
...

Sheet LRV1YEAR
B1: Amortization | C1: ='DATA ENTRY'!C15 -> 9338.1996
B2: Timeline | C2: 0 | D2: 1 | E2: 2 | F2: 3 | G2: 4 | H2: 5 | I2: 6 | J2: 7 | K2: 8 | L2: 9 | M2: 10 | N2: 11 | O2: 12
B3: GROSS AMOUNT | C3: ='DATA ENTRY'!C4 -> 112058.4
A4: 41 | B4: LOAN AMOUNT | C4: ='DATA ENTRY'!C12 -> 107635.75 | D4: =-$C1 -> -9338.1996 | E4: =-$C1 -> -9338.1996 | F4: =-$C1 -> -9338.1996 | G4: =-$C1 -> -9338.1996 | H4: =-$C1 -> -9338.1996 | I4: =-$C1 -> -9338.1996 | J4: =-$C1 -> -9338.1996 | K4: =-$C1 -> -9338.1996 | ... O4: =-$C1 -> -9338.1996
B5: Service Fee | C5: ='DATA ENTRY'!C7 -> 6545
B6: Insurance | C6: ='DATA ENTRY'!C8 -> 1122
B7: CapCon | C7: 22000
B8: membership fee | C8: ='DATA ENTRY'!C10 -> 300
B9: Advance Interest | C9: ='DATA ENTRY'!C11 -> 1168.75
B10: NET PROCEEDS/CASH FLOW | C10: =C4-C5-C6-C7-C8-C9 -> 76500
B12: Interest Rate of Return | C12: =IRR(C4:O4) -> 0.00625 | D12: =C12/5 -> 0.00125
B14: Loan Balance
B15: Monthly Interest Rate | C15: ='[3]Data Entry'!D12/12 -> 0.0070833333
B16: Effective Interest Rate | C16: ='[3]Data Entry'!D13 -> 0.08855359
B17: Term | C17: 12 MON THS
C20: LOAN LEDGER CARD
C22: Name: | D22: SURAIDA S. ANOG | G22: Loan Voucher No. | H22: LV-054
C23: Serial Nr: | D23: 648091 | E23: Address: | F23: PUROK 4 GUIANG, GAMU, ISABELA
C24: Posting date | D24: Date of Loan: | E24: 45908 | F24: Maturity Date | G24: =B39 -> 46273 | K24: PEOPLE'S MULTI-PURPOSE COOPERATIVE
D25: Term: | E25: 12 | F25: MOS | K25: 20-E 2nd Camarilla St. corner 15th Ave., Brgy. San Roque, Murphy Cubao, Quezon City | X25: 20-E 2nd Camarilla St corner 15th Avenue,
D26: Loan | E26: Installment | F26: Principal | G26: EIR | H26: Balance | X26: Brgy San Roque, Murphy Cubao, Quezon City
D27: Month 0 | H27: =C4 -> 107635.75 | K27: LOAN RELEASE VOUCHER | X27: Mobile No. (+63)953-033-1580 (GLOBE)
B28: =DATE(YEAR(E$24),MONTH(E$24)+D28+0,DAY(E$24)) -> 45938 | C28: =TEXT(B28,"mmm-yyyy") -> Oct-2025 | D28: 1 | E28: =C$1 -> 9338.1996 | F28: =E28-G28 -> 8665.4762 | G28: =H27*C$12 -> 672.72344 | H28: =H27-F28 -> 98970.274
B29: =DATE(YEAR(E$24),MONTH(E$24)+D29+0,DAY(E$24)) -> 45969 | C29: =TEXT(B29,"mmm-yyyy") -> Nov-2025 | D29: 2 | E29: =C$1 -> 9338.1996 | F29: =E29-G29 -> 8719.6354 | G29: =H28*C$12 -> 618.56421 | H29: =H28-F29 -> 90250.638 | R29: Date: | S29: =E24 -> 45908 | X29: LOAN APPLICATION FORM
B30: =DATE(YEAR(E$24),MONTH(E$24)+D30+0,DAY(E$24)) -> 45999 | C30: =TEXT(B30,"mmm-yyyy") -> Dec-2025 | D30: 3 | E30: =C$1 -> 9338.1996 | F30: =E30-G30 -> 8774.1331 | G30: =H29*C$12 -> 564.06649 | H30: =H29-F30 -> 81476.505 | R30: LV No: | S30: =H22 -> LV-054 | AU30: Date: | AW30: 0 | AX30: 9 | AY30: 0 | AZ30: 8 | BA30: 2 | BB30: 0 | BC30: 2 | BD30: 5
B31: =DATE(YEAR(E$24),MONTH(E$24)+D31+0,DAY(E$24)) -> 46030 | C31: =TEXT(B31,"mmm-yyyy") -> Jan-2026 | D31: 4 | E31: =C$1 -> 9338.1996 | F31: =E31-G31 -> 8828.9715 | G31: =H30*C$12 -> 509.22816 | H31: =H30-F31 -> 72647.534 | AW31: m | AX31: m | AY31: d | AZ31: d | BA31: y | BB31: y | BC31: y | BD31: y
B32: =DATE(YEAR(E$24),MONTH(E$24)+D32+0,DAY(E$24)) -> 46061 | C32: =TEXT(B32,"mmm-yyyy") -> Feb-2026 | D32: 5 | E32: =C$1 -> 9338.1996 | F32: =E32-G32 -> 8884.1525 | G32: =H31*C$12 -> 454.04709 | H32: =H31-F32 -> 63763.381 | K32: Name of Borrower: | N32: =D22 -> SURAIDA S. ANOG | X32: APPLICATION TYPE | AE32: LOAN CLASSIFICATION | AM32: TERM | AT32: RELEASE OF LOAN PROCEEDS
B33: =DATE(YEAR(E$24),MONTH(E$24)+D33+0,DAY(E$24)) -> 46089 | C33: =TEXT(B33,"mmm-yyyy") -> Mar-2026 | D33: 6 | E33: =C$1 -> 9338.1996 | F33: =E33-G33 -> 8939.6785 | G33: =H32*C$12 -> 398.52113 | H33: =H32-F33 -> 54823.703 | K33: Serial No.: | N33: =D23 -> 648091 | Y33: New | AF33: Salary Loan | AN33: 12 Months | AU33: CHEQUE
B34: =DATE(YEAR(E$24),MONTH(E$24)+D34+0,DAY(E$24)) -> 46120 | C34: =TEXT(B34,"mmm-yyyy") -> Apr-2026 | D34: 7 | E34: =C$1 -> 9338.1996 | F34: =E34-G34 -> 8995.5515 | G34: =H33*C$12 -> 342.64814 | H34: =H33-F34 -> 45828.151 | K34: Address: | N34: =F23 -> PUROK 4 GUIANG, GAMU, ISABELA | Y34: Renewal | AF34: Pension Loan | AN34: 24 Months | AU34: Bank Electronic Transfer to Borrowers Account
B35: =DATE(YEAR(E$24),MONTH(E$24)+D35+0,DAY(E$24)) -> 46150 | C35: =TEXT(B35,"mmm-yyyy") -> May-2026 | D35: 8 | E35: =C$1 -> 9338.1996 | F35: =E35-G35 -> 9051.7737 | G35: =H34*C$12 -> 286.42595 | H35: =H34-F35 -> 36776.378 | Y35: Additional | AF35: Emergency | AN35: 36 Months | AU35: Others:
B36: =DATE(YEAR(E$24),MONTH(E$24)+D36+0,DAY(E$24)) -> 46181 | C36: =TEXT(B36,"mmm-yyyy") -> Jun-2026 | D36: 9 | E36: =C$1 -> 9338.1996 | F36: =E36-G36 -> 9108.3473 | G36: =H35*C$12 -> 229.85236 | H36: =H35-F36 -> 27668.03 | L36: Principal Amount | R36: =C4 -> 107635.75 | Y36: Reloan | AF36: Health Assistance Loan | AN36: 48 Months
B37: =DATE(YEAR(E$24),MONTH(E$24)+D37+0,DAY(E$24)) -> 46211 | C37: =TEXT(B37,"mmm-yyyy") -> Jul-2026 | D37: 10 | E37: =C$1 -> 9338.1996 | F37: =E37-G37 -> 9165.2744 | G37: =H36*C$12 -> 172.92519 | H37: =H36-F37 -> 18502.756 | Y37: Restructure | AF37: Educational Loan | AN37: 60 Months
B38: =DATE(YEAR(E$24),MONTH(E$24)+D38+0,DAY(E$24)) -> 46242 | C38: =TEXT(B38,"mmm-yyyy") -> Aug-2026 | D38: 11 | E38: =C$1 -> 9338.1996 | F38: =E38-G38 -> 9222.5574 | G38: =H37*C$12 -> 115.64222 | H38: =H37-F38 -> 9280.1984 | L38: (-) | M38: Balance Old Loan(s) | R38: =-C14 -> 0 | AF38: Others: | AH38: SMALL BUSINESS LOAN | AN38: Others:
B39: =DATE(YEAR(E$24),MONTH(E$24)+D39+0,DAY(E$24)) -> 46273 | C39: =TEXT(B39,"mmm-yyyy") -> Sep-2026 | D39: 12 | E39: =C$1 -> 9338.1996 | F39: =E39-G39 -> 9280.1984 | G39: =H38*C$12 -> 58.00124 | H39: =H38-F39 -> -5.0931703e-11 | L39: (-) | M39: Membership Fee: | R39: =-C8 -> -300 | X39: AMOUNT APPLIED: | AB39: =R44 -> 76500 | AN39: MONTHLY AMORTIZATION: | AT39: =C1 -> 9338.1996
E40: =SUM(E28:E39) -> 112058.4 | F40: =SUM(F28:F39) -> 107635.75 | G40: =SUM(G28:G39) -> 4422.6456 | L40: (-) | M40: Paid up Capital: | R40: =-C7 -> -22000
L41: (-) | M41: Service Fee | R41: =-C5 -> -6545 | X41: LOAN ID: | AF41: DEDUCTION CODE: | AR41: LOAN PURPOSE:
L42: (-) | M42: Insurance Premium - Paramount | R42: =-C6 -> -1122 | X42: MEM ID: | AG42: Regular Member | AS42: Old Member
L43: (-) | M43: Advance Interest | R43: =-C9 -> -1168.75 | AG43: Associate Member | AS43: New Member
L44: NET PROCEEDS (Php): | R44: =SUM(R36:T43) -> 76500 | X44: BORROWER'S INFORMATION
X45: ANOG | AD45: SURAIDA | AN45: SASAPAN
...

Sheet LRV2YEAR
B1: Amortization | C1: ='DATA ENTRY'!D15 -> 4936.7326 | T1: pvap
B2: Timeline | C2: 0 | D2: 1 | E2: 2 | F2: 3 | G2: 4 | H2: 5 | I2: 6 | J2: 7 | K2: 8 | L2: 9 | M2: 10 | N2: 11 | O2: 12 | P2: 13 | Q2: 14 | R2: 15 | S2: 16 | T2: 17 | U2: 18 | V2: 19 | W2: 20 | X2: 21 | Y2: 22 | Z2: 23 | AA2: 24 | AB2: 25 | AC2: 26 | AD2: 27 | AE2: 28 | AF2: 29 | AG2: 30 | AH2: 31 | AI2: 32 | AJ2: 33 | AK2: 34 | AL2: 35 | AM2: 36
B3: GROSS AMOUNT | C3: ='DATA ENTRY'!D4 -> 118481.58
A4: 41 | B4: LOAN AMOUNT | C4: ='DATA ENTRY'!D12 -> 109021.87
B5: Service Fee | C5: ='DATA ENTRY'!D7 -> 7012.5
B6: Insurance | C6: ='DATA ENTRY'!D8 -> 2244
B7: CapCon | C7: ='DATA ENTRY'!D9 -> 5000
B8: membership fee | C8: ='DATA ENTRY'!D10 -> 0
B9: Advance Interest | C9: ='DATA ENTRY'!D11 -> 1265.3667
B10: NET PROCEEDS/CASH FLOW | C10: =C4-C5-C6-C7-C8-C9 -> 93500 | D10: =-$C1 -> -4936.7326 | E10: =-$C1 -> -4936.7326 | F10: =-$C1 -> -4936.7326 | G10: =-$C1 -> -4936.7326 | H10: =-$C1 -> -4936.7326 | I10: =-$C1 -> -4936.7326 | J10: =-$C1 -> -4936.7326 | K10: =-$C1 -> -4936.7326 | ... AM10: =-$C1 -> -4936.7326
B12: Interest Rate of Return | C12: =IRR(C10:AM10) -> 0.039880345 | D12: =C12/5 -> 0.0079760691
B14: Loan Balance
B15: Monthly Interest Rate | C15: ='[3]Data Entry'!D12/12 -> 0.0070833333
B16: Effective Interest Rate | C16: ='[3]Data Entry'!D13 -> 0.08855359
B17: Term | C17: 24
C20: LOAN LEDGER CARD
C22: Name: | D22: MADONNA LYN ORTEGA MARQUEZ | G22: Loan Voucher No. | H22: CDEA-001
C23: Serial Nr: | D23: 2004-023 | E23: Address: | F23: BLK 1 LOT 8 JOSHUA ST., BEYOND HOMES BRGY SAN FRANCISCO, GENERAL TRIAS, CAVITE
C24: Posting date | D24: Date of Loan: | E24: 45701 | F24: Maturity Date | G24: =B51 -> 46431 | K24: PEOPLE'S MULTI-PURPOSE COOPERATIVE
D25: Term: | E25: 36 | F25: MOS | K25: 20-E 2nd Camarilla St. corner 15th Ave., Brgy. San Roque, Murphy Cubao, Quezon City | X25: 20-E 2nd Camarilla St corner 15th Avenue,
D26: Loan | E26: Installment | F26: Principal | G26: EIR | H26: Balance | X26: Brgy San Roque, Murphy Cubao, Quezon City
D27: Month 0 | H27: =C10 -> 93500 | K27: LOAN RELEASE VOUCHER | X27: Mobile No. (+63)953-033-1580 (GLOBE)
B28: =DATE(YEAR(E$24),MONTH(E$24)+D28+0,DAY(E$24)) -> 45729 | C28: =TEXT(B28,"mmm-yyyy") -> Mar-2025 | D28: 1 | E28: =C$1 -> 4936.7326 | F28: =E28-G28 -> 1207.9203 | G28: =H27*C$12 -> 3728.8123 | H28: =H27-F28 -> 92292.08
B29: =DATE(YEAR(E$24),MONTH(E$24)+D29+0,DAY(E$24)) -> 45760 | C29: =TEXT(B29,"mmm-yyyy") -> Apr-2025 | D29: 2 | E29: =C$1 -> 4936.7326 | F29: =E29-G29 -> 1256.0926 | G29: =H28*C$12 -> 3680.64 | H29: =H28-F29 -> 91035.987 | R29: Date: | S29: =E24 -> 45701 | X29: LOAN APPLICATION FORM
B30: =DATE(YEAR(E$24),MONTH(E$24)+D30+0,DAY(E$24)) -> 45790 | C30: =TEXT(B30,"mmm-yyyy") -> May-2025 | D30: 3 | E30: =C$1 -> 4936.7326 | F30: =E30-G30 -> 1306.186 | G30: =H29*C$12 -> 3630.5466 | H30: =H29-F30 -> 89729.801 | R30: LV No: | S30: =D23 -> 2004-023 | AU30: Date: | AW30: 0 | AX30: 2 | AY30: 1 | AZ30: 3 | BA30: 2 | BB30: 0 | BC30: 2 | BD30: 5
B31: =DATE(YEAR(E$24),MONTH(E$24)+D31+0,DAY(E$24)) -> 45821 | C31: =TEXT(B31,"mmm-yyyy") -> Jun-2025 | D31: 4 | E31: =C$1 -> 4936.7326 | F31: =E31-G31 -> 1358.2772 | G31: =H30*C$12 -> 3578.4555 | H31: =H30-F31 -> 88371.524 | AW31: m | AX31: m | AY31: d | AZ31: d | BA31: y | BB31: y | BC31: y | BD31: y
B32: =DATE(YEAR(E$24),MONTH(E$24)+D32+0,DAY(E$24)) -> 45851 | C32: =TEXT(B32,"mmm-yyyy") -> Jul-2025 | D32: 5 | E32: =C$1 -> 4936.7326 | F32: =E32-G32 -> 1412.4457 | G32: =H31*C$12 -> 3524.2869 | H32: =H31-F32 -> 86959.078 | K32: Name of Borrower: | N32: =D22 -> MADONNA LYN ORTEGA MARQUEZ | X32: APPLICATION TYPE | AE32: LOAN CLASSIFICATION | AM32: TERM | AT32: RELEASE OF LOAN PROCEEDS
B33: =DATE(YEAR(E$24),MONTH(E$24)+D33+0,DAY(E$24)) -> 45882 | C33: =TEXT(B33,"mmm-yyyy") -> Aug-2025 | D33: 6 | E33: =C$1 -> 4936.7326 | F33: =E33-G33 -> 1468.7746 | G33: =H32*C$12 -> 3467.9581 | H33: =H32-F33 -> 85490.303 | K33: Serial No.: | N33: =D23 -> 2004-023 | Y33: New | AF33: Salary Loan | AN33: 12 Months | AU33: Check
B34: =DATE(YEAR(E$24),MONTH(E$24)+D34+0,DAY(E$24)) -> 45913 | C34: =TEXT(B34,"mmm-yyyy") -> Sep-2025 | D34: 7 | E34: =C$1 -> 4936.7326 | F34: =E34-G34 -> 1527.3498 | G34: =H33*C$12 -> 3409.3828 | H34: =H33-F34 -> 83962.954 | K34: Address: | N34: =F23 -> BLK 1 LOT 8 JOSHUA ST., BEYOND HOMES BRGY SAN FRANCISCO, GENERAL TRIAS, CAVITE | Y34: Renewal | AF34: Pension Loan | AN34: 24 Months | AU34: Bank Electronic Transfer to Borrowers Account
B35: =DATE(YEAR(E$24),MONTH(E$24)+D35+0,DAY(E$24)) -> 45943 | C35: =TEXT(B35,"mmm-yyyy") -> Oct-2025 | D35: 8 | E35: =C$1 -> 4936.7326 | F35: =E35-G35 -> 1588.261 | G35: =H34*C$12 -> 3348.4716 | H35: =H34-F35 -> 82374.693 | Y35: Additional | AF35: Emergency | AN35: 36 Months | AU35: Others:
B36: =DATE(YEAR(E$24),MONTH(E$24)+D36+0,DAY(E$24)) -> 45974 | C36: =TEXT(B36,"mmm-yyyy") -> Nov-2025 | D36: 9 | E36: =C$1 -> 4936.7326 | F36: =E36-G36 -> 1651.6014 | G36: =H35*C$12 -> 3285.1312 | H36: =H35-F36 -> 80723.091 | L36: Principal Amount | R36: =C4 -> 109021.87 | Y36: Reloan | AF36: Health Assistance Loan | AN36: 48 Months
B37: =DATE(YEAR(E$24),MONTH(E$24)+D37+0,DAY(E$24)) -> 46004 | C37: =TEXT(B37,"mmm-yyyy") -> Dec-2025 | D37: 10 | E37: =C$1 -> 4936.7326 | F37: =E37-G37 -> 1717.4679 | G37: =H36*C$12 -> 3219.2648 | H37: =H36-F37 -> 79005.623 | Y37: Restructure | AF37: Educational Loan | AN37: 60 Months
B38: =DATE(YEAR(E$24),MONTH(E$24)+D38+0,DAY(E$24)) -> 46035 | C38: =TEXT(B38,"mmm-yyyy") -> Jan-2026 | D38: 11 | E38: =C$1 -> 4936.7326 | F38: =E38-G38 -> 1785.9611 | G38: =H37*C$12 -> 3150.7715 | H38: =H37-F38 -> 77219.662 | L38: (-) | M38: Balance Old Loan(s) | R38: =-C14 -> 0 | AF38: Others: | AN38: Others:
B39: =DATE(YEAR(E$24),MONTH(E$24)+D39+0,DAY(E$24)) -> 46066 | C39: =TEXT(B39,"mmm-yyyy") -> Feb-2026 | D39: 12 | E39: =C$1 -> 4936.7326 | F39: =E39-G39 -> 1857.1858 | G39: =H38*C$12 -> 3079.5468 | H39: =H38-F39 -> 75362.476 | L39: (-) | M39: Membership Fee: | R39: =-C8 -> 0 | X39: AMOUNT APPLIED: | AB39: ='[3]Data Entry'!E4 -> 150000 | AN39: MONTHLY AMORTIZATION: | AT39: =R49 -> 4936.7326
B40: =DATE(YEAR(E$24),MONTH(E$24)+D40+0,DAY(E$24)) -> 46094 | C40: =TEXT(B40,"mmm-yyyy") -> Mar-2026 | D40: 13 | E40: =C$1 -> 4936.7326 | F40: =E40-G40 -> 1931.2511 | G40: =H39*C$12 -> 3005.4816 | H40: =H39-F40 -> 73431.225 | L40: (-) | M40: Paid up Capital: | R40: =-C7 -> -5000
B41: =DATE(YEAR(E$24),MONTH(E$24)+D41+0,DAY(E$24)) -> 46125 | C41: =TEXT(B41,"mmm-yyyy") -> Apr-2026 | D41: 14 | E41: =C$1 -> 4936.7326 | F41: =E41-G41 -> 2008.27 | G41: =H40*C$12 -> 2928.4626 | H41: =H40-F41 -> 71422.955 | L41: (-) | M41: Service Fee | R41: =-C5 -> -7012.5 | X41: LOAN ID: | AF41: DEDUCTION CODE: | AR41: LOAN PURPOSE:
B42: =DATE(YEAR(E$24),MONTH(E$24)+D42+0,DAY(E$24)) -> 46155 | C42: =TEXT(B42,"mmm-yyyy") -> May-2026 | D42: 15 | E42: =C$1 -> 4936.7326 | F42: =E42-G42 -> 2088.3605 | G42: =H41*C$12 -> 2848.3721 | H42: =H41-F42 -> 69334.595 | L42: (-) | M42: Insurance Premium - Paramount | R42: =-C6 -> -2244 | X42: MEM ID: | AG42: Regular Member | AS42: Old Member
B43: =DATE(YEAR(E$24),MONTH(E$24)+D43+0,DAY(E$24)) -> 46186 | C43: =TEXT(B43,"mmm-yyyy") -> Jun-2026 | D43: 16 | E43: =C$1 -> 4936.7326 | F43: =E43-G43 -> 2171.6451 | G43: =H42*C$12 -> 2765.0876 | H43: =H42-F43 -> 67162.95 | L43: (-) | M43: Advance Interest | R43: =-C9 -> -1265.3667 | AG43: Associate Member | AS43: New Member
B44: =DATE(YEAR(E$24),MONTH(E$24)+D44+0,DAY(E$24)) -> 46216 | C44: =TEXT(B44,"mmm-yyyy") -> Jul-2026 | D44: 17 | E44: =C$1 -> 4936.7326 | F44: =E44-G44 -> 2258.251 | G44: =H43*C$12 -> 2678.4816 | H44: =H43-F44 -> 64904.699 | L44: NET PROCEEDS (Php): | R44: =SUM(R36:T43) -> 93500 | X44: BORROWER'S INFORMATION
B45: =DATE(YEAR(E$24),MONTH(E$24)+D45+0,DAY(E$24)) -> 46247 | C45: =TEXT(B45,"mmm-yyyy") -> Aug-2026 | D45: 18 | E45: =C$1 -> 4936.7326 | F45: =E45-G45 -> 2348.3108 | G45: =H44*C$12 -> 2588.4218 | H45: =H44-F45 -> 62556.388 | X45: MARQUEZ | AD45: MADONNA LYN | AN45: ORTEGA
...

Sheet LRV3YEAR
B1: Amortization | C1: ='DATA ENTRY'!E15 -> 1499.9958 | T1: pvap
B2: Timeline | C2: 0 | D2: 1 | E2: 2 | F2: 3 | G2: 4 | H2: 5 | I2: 6 | J2: 7 | K2: 8 | L2: 9 | M2: 10 | N2: 11 | O2: 12 | P2: 13 | Q2: 14 | R2: 15 | S2: 16 | T2: 17 | U2: 18 | V2: 19 | W2: 20 | X2: 21 | Y2: 22 | Z2: 23 | AA2: 24 | AB2: 25 | AC2: 26 | AD2: 27 | AE2: 28 | AF2: 29 | AG2: 30 | AH2: 31 | AI2: 32 | AJ2: 33 | AK2: 34 | AL2: 35 | AM2: 36
B3: GROSS AMOUNT | C3: ='DATA ENTRY'!E4 -> 53999.85
A4: 41 | B4: LOAN AMOUNT | C4: ='DATA ENTRY'!E12 -> 47517.037 | D4: =-$C1 -> -1499.9958 | E4: =-$C1 -> -1499.9958 | F4: =-$C1 -> -1499.9958 | G4: =-$C1 -> -1499.9958 | H4: =-$C1 -> -1499.9958 | I4: =-$C1 -> -1499.9958 | J4: =-$C1 -> -1499.9958 | K4: =-$C1 -> -1499.9958 | ... AM4: =-$C1 -> -1499.9958
B5: Service Fee | C5: ='DATA ENTRY'!E7 -> 2988.376
B6: Insurance | C6: ='DATA ENTRY'!E8 -> 1344.7692
B7: CapCon | C7: ='DATA ENTRY'!E9 -> 5000
B8: membership fee | C8: ='DATA ENTRY'!E10 -> 300
B9: Advance Interest | C9: ='DATA ENTRY'!E11 -> 529.19158
B10: NET PROCEEDS/CASH FLOW | C10: =C4-C5-C6-C7-C8-C9 -> 37354.7
B12: Interest Rate of Return | C12: =IRR(C4:AM4) -> 0.0070833333 | D12: =C12/5 -> 0.0014166667
B14: Loan Balance
B15: Monthly Interest Rate | C15: ='[3]Data Entry'!D12/12 -> 0.0070833333
B16: Effective Interest Rate | C16: ='[3]Data Entry'!D13 -> 0.08855359
B17: Term | C17: 36
C20: LOAN LEDGER CARD
C22: Name: | D22: TABAQUERO, ARTHUR I. | G22: Loan Voucher No. | H22: LV-059
C23: Serial Nr: | D23: O-7704 | E23: Address: | F23: #49 RICARTE ST. AFPOVAI WESTERN BICUTAN TAGUIG CITY METRO MANILA
C24: Posting date | D24: Date of Loan: | E24: 46031 | F24: Maturity Date | G24: =B63 -> 47186 | K24: PEOPLE'S MULTI-PURPOSE COOPERATIVE
D25: Term: | E25: 36 | F25: MOS | K25: 20-E 2nd Camarilla St. corner 15th Ave., Brgy. San Roque, Murphy Cubao, Quezon City | X25: 20-E 2nd Camarilla St corner 15th Avenue,
D26: Loan | E26: Installment | F26: Principal | G26: EIR | H26: Balance | X26: Brgy San Roque, Murphy Cubao, Quezon City
D27: Month 0 | H27: =C4 -> 47517.037 | K27: LOAN RELEASE VOUCHER | X27: Mobile No. (+63)953-033-1580 (GLOBE)
B28: =DATE(YEAR(E$24),MONTH(E$24)+D28+2,DAY(E$24)) -> 46121 | C28: =TEXT(B28,"mmm-yyyy") -> Apr-2026 | D28: 1 | E28: =C$1 -> 1499.9958 | F28: =E28-G28 -> 1163.4168 | G28: =H27*C$12 -> 336.57901 | H28: =H27-F28 -> 46353.62
B29: =DATE(YEAR(E$24),MONTH(E$24)+D29+2,DAY(E$24)) -> 46151 | C29: =TEXT(B29,"mmm-yyyy") -> May-2026 | D29: 2 | E29: =C$1 -> 1499.9958 | F29: =E29-G29 -> 1171.6577 | G29: =H28*C$12 -> 328.33814 | H29: =H28-F29 -> 45181.962 | R29: Date: | S29: 01/09/2026 | X29: LOAN APPLICATION FORM
B30: =DATE(YEAR(E$24),MONTH(E$24)+D30+2,DAY(E$24)) -> 46182 | C30: =TEXT(B30,"mmm-yyyy") -> Jun-2026 | D30: 3 | E30: =C$1 -> 1499.9958 | F30: =E30-G30 -> 1179.9569 | G30: =H29*C$12 -> 320.0389 | H30: =H29-F30 -> 44002.005 | R30: LV No: | S30: =H22 -> LV-059 | AU30: Date: | AW30: 0 | AX30: 1 | AY30: 0 | AZ30: 9 | BA30: 2 | BB30: 0 | BC30: 2 | BD30: 6
B31: =DATE(YEAR(E$24),MONTH(E$24)+D31+2,DAY(E$24)) -> 46212 | C31: =TEXT(B31,"mmm-yyyy") -> Jul-2026 | D31: 4 | E31: =C$1 -> 1499.9958 | F31: =E31-G31 -> 1188.315 | G31: =H30*C$12 -> 311.68087 | H31: =H30-F31 -> 42813.69 | AW31: m | AX31: m | AY31: d | AZ31: d | BA31: y | BB31: y | BC31: y | BD31: y
B32: =DATE(YEAR(E$24),MONTH(E$24)+D32+2,DAY(E$24)) -> 46243 | C32: =TEXT(B32,"mmm-yyyy") -> Aug-2026 | D32: 5 | E32: =C$1 -> 1499.9958 | F32: =E32-G32 -> 1196.7322 | G32: =H31*C$12 -> 303.26364 | H32: =H31-F32 -> 41616.958 | K32: Name of Borrower: | N32: =D22 -> TABAQUERO, ARTHUR I. | X32: APPLICATION TYPE | AE32: LOAN CLASSIFICATION | AM32: TERM | AT32: RELEASE OF LOAN PROCEEDS
B33: =DATE(YEAR(E$24),MONTH(E$24)+D33+2,DAY(E$24)) -> 46274 | C33: =TEXT(B33,"mmm-yyyy") -> Sep-2026 | D33: 6 | E33: =C$1 -> 1499.9958 | F33: =E33-G33 -> 1205.209 | G33: =H32*C$12 -> 294.78679 | H33: =H32-F33 -> 40411.749 | K33: Serial No.: | N33: =D23 -> O-7704 | Y33: New | AF33: Salary Loan | AN33: 12 Months | AU33: Check
B34: =DATE(YEAR(E$24),MONTH(E$24)+D34+2,DAY(E$24)) -> 46304 | C34: =TEXT(B34,"mmm-yyyy") -> Oct-2026 | D34: 7 | E34: =C$1 -> 1499.9958 | F34: =E34-G34 -> 1213.7459 | G34: =H33*C$12 -> 286.24989 | H34: =H33-F34 -> 39198.003 | K34: Address: | N34: =F23 -> #49 RICARTE ST. AFPOVAI WESTERN BICUTAN TAGUIG CITY METRO MANILA | Y34: Renewal | AF34: Pension Loan | AN34: 24 Months | AU34: Bank Electronic Transfer to Borrowers Account
B35: =DATE(YEAR(E$24),MONTH(E$24)+D35+2,DAY(E$24)) -> 46335 | C35: =TEXT(B35,"mmm-yyyy") -> Nov-2026 | D35: 8 | E35: =C$1 -> 1499.9958 | F35: =E35-G35 -> 1222.3433 | G35: =H34*C$12 -> 277.65252 | H35: =H34-F35 -> 37975.66 | Y35: Additional | AF35: Emergency | AN35: 36 Months | AU35: Others:
B36: =DATE(YEAR(E$24),MONTH(E$24)+D36+2,DAY(E$24)) -> 46365 | C36: =TEXT(B36,"mmm-yyyy") -> Dec-2026 | D36: 9 | E36: =C$1 -> 1499.9958 | F36: =E36-G36 -> 1231.0016 | G36: =H35*C$12 -> 268.99426 | H36: =H35-F36 -> 36744.658 | L36: Principal Amount | R36: =C4 -> 47517.037 | Y36: Reloan | AF36: Health Assistance Loan | AN36: 48 Months
B37: =DATE(YEAR(E$24),MONTH(E$24)+D37+2,DAY(E$24)) -> 46396 | C37: =TEXT(B37,"mmm-yyyy") -> Jan-2027 | D37: 10 | E37: =C$1 -> 1499.9958 | F37: =E37-G37 -> 1239.7212 | G37: =H36*C$12 -> 260.27466 | H37: =H36-F37 -> 35504.937 | Y37: Restructure | AF37: Educational Loan | AN37: 60 Months
B38: =DATE(YEAR(E$24),MONTH(E$24)+D38+2,DAY(E$24)) -> 46427 | C38: =TEXT(B38,"mmm-yyyy") -> Feb-2027 | D38: 11 | E38: =C$1 -> 1499.9958 | F38: =E38-G38 -> 1248.5025 | G38: =H37*C$12 -> 251.4933 | H38: =H37-F38 -> 34256.435 | L38: (-) | M38: Balance Old Loan(s) | R38: =-C14 -> 0 | AF38: Others: | AN38: Others:
B39: =DATE(YEAR(E$24),MONTH(E$24)+D39+2,DAY(E$24)) -> 46455 | C39: =TEXT(B39,"mmm-yyyy") -> Mar-2027 | D39: 12 | E39: =C$1 -> 1499.9958 | F39: =E39-G39 -> 1257.3461 | G39: =H38*C$12 -> 242.64974 | H39: =H38-F39 -> 32999.088 | L39: (-) | M39: Membership Fee: | R39: =-C8 -> -300 | X39: AMOUNT APPLIED: | AB39: =R44 -> 37354.7 | AN39: MONTHLY AMORTIZATION: | AT39: =R49 -> 1499.9958
B40: =DATE(YEAR(E$24),MONTH(E$24)+D40+2,DAY(E$24)) -> 46486 | C40: =TEXT(B40,"mmm-yyyy") -> Apr-2027 | D40: 13 | E40: =C$1 -> 1499.9958 | F40: =E40-G40 -> 1266.2523 | G40: =H39*C$12 -> 233.74354 | H40: =H39-F40 -> 31732.836 | L40: (-) | M40: Paid up Capital: | R40: =-C7 -> -5000
B41: =DATE(YEAR(E$24),MONTH(E$24)+D41+2,DAY(E$24)) -> 46516 | C41: =TEXT(B41,"mmm-yyyy") -> May-2027 | D41: 14 | E41: =C$1 -> 1499.9958 | F41: =E41-G41 -> 1275.2216 | G41: =H40*C$12 -> 224.77426 | H41: =H40-F41 -> 30457.615 | L41: (-) | M41: Service Fee | R41: =-C5 -> -2988.376 | X41: LOAN ID: | AF41: DEDUCTION CODE: | AJ41: 691 PL | AR41: LOAN PURPOSE:
B42: =DATE(YEAR(E$24),MONTH(E$24)+D42+2,DAY(E$24)) -> 46547 | C42: =TEXT(B42,"mmm-yyyy") -> Jun-2027 | D42: 15 | E42: =C$1 -> 1499.9958 | F42: =E42-G42 -> 1284.2544 | G42: =H41*C$12 -> 215.74144 | H42: =H41-F42 -> 29173.36 | L42: (-) | M42: Insurance Premium - Paramount | R42: =-C6 -> -1344.7692 | X42: MEM ID: | AG42: Regular Member | AS42: Old Member
B43: =DATE(YEAR(E$24),MONTH(E$24)+D43+2,DAY(E$24)) -> 46577 | C43: =TEXT(B43,"mmm-yyyy") -> Jul-2027 | D43: 16 | E43: =C$1 -> 1499.9958 | F43: =E43-G43 -> 1293.3512 | G43: =H42*C$12 -> 206.64463 | H43: =H42-F43 -> 27880.009 | L43: (-) | M43: Advance Interest | R43: =-C9 -> -529.19158 | AG43: Associate Member | AS43: New Member
B44: =DATE(YEAR(E$24),MONTH(E$24)+D44+2,DAY(E$24)) -> 46608 | C44: =TEXT(B44,"mmm-yyyy") -> Aug-2027 | D44: 17 | E44: =C$1 -> 1499.9958 | F44: =E44-G44 -> 1302.5124 | G44: =H43*C$12 -> 197.4834 | H44: =H43-F44 -> 26577.497 | L44: NET PROCEEDS (Php): | R44: =SUM(R36:T43) -> 37354.7 | X44: BORROWER'S INFORMATION
B45: =DATE(YEAR(E$24),MONTH(E$24)+D45+2,DAY(E$24)) -> 46639 | C45: =TEXT(B45,"mmm-yyyy") -> Sep-2027 | D45: 18 | E45: =C$1 -> 1499.9958 | F45: =E45-G45 -> 1311.7386 | G45: =H44*C$12 -> 188.25727 | H45: =H44-F45 -> 25265.758 | X45: TABAQUERO | AD45: ARTHUR | AN45: IBANEZ
...

Sheet LRV4YEAR
B1: Amortization | C1: ='DATA ENTRY'!F15 -> 2771.3809 | T1: pvap
B2: Timeline | C2: 0 | D2: 1 | E2: 2 | F2: 3 | G2: 4 | H2: 5 | I2: 6 | J2: 7 | K2: 8 | L2: 9 | M2: 10 | N2: 11 | O2: 12 | P2: 13 | Q2: 14 | R2: 15 | S2: 16 | T2: 17 | U2: 18 | V2: 19 | W2: 20 | X2: 21 | Y2: 22 | Z2: 23 | AA2: 24 | AB2: 25 | AC2: 26 | AD2: 27 | AE2: 28 | AF2: 29 | AG2: 30 | AH2: 31 | AI2: 32 | AJ2: 33 | AK2: 34 | AL2: 35 | AM2: 36 | AN2: 37 | AO2: 38 | AP2: 39 | AQ2: 40 | AR2: 41 | AS2: 42 | AT2: 43 | AU2: 44 | AV2: 45 | AW2: 46 | AX2: 47 | AY2: 48
B3: GROSS AMOUNT | C3: ='DATA ENTRY'!F4 -> 133026.28
