Workbook

Sheet Data Entry
B1: CDEA DATA ENTRY
C2: 1 Yr | D2: 2 Yrs | E2: 3 Yrs
B3: GROSS AMOUNT | C3: ='Computation Table'!C56 -> 33568.249 | D3: ='Computation Table'!C30 -> 66388.013 | E3: ='Computation Table'!C4 -> 70983.871
B4: NET PROCEEDS | C4: 25000 | D4: 50000 | E4: 50000
B5: Add:
B6: Service Fee | C6: ='Computation Table'!C58 -> 1500 | D6: ='Computation Table'!C32 -> 4000 | E6: ='Computation Table'!C6 -> 5500
B7: Insurance | C7: ='Computation Table'!C59 -> 300 | D7: ='Computation Table'!C33 -> 1200 | E7: ='Computation Table'!C7 -> 1800
B8: CapCon | C8: 5000 | D8: 5000 | E8: 5000
B9: membership fee | D9: 300
B10: Advance Interest | C10: ='Computation Table'!C62 -> 187.5 | D10: ='Computation Table'!C36 -> 354.16667 | E10: ='Computation Table'!C10 -> 345.83333
B11: LOAN AMOUNT | C11: =SUM(C4:C10) -> 31987.5 | D11: =SUM(D4:D10) -> 60854.167 | E11: =SUM(E4:E10) -> 62645.833
B12: Annual Interest Rate | C12: ='Computation Table'!C64 -> 0.09 | D12: ='Computation Table'!C38 -> 0.085 | E12: ='Computation Table'!C12 -> 0.083
B13: Effective Interest Rate | C13: ='Computation Table'!C65 -> 0.093806898 | D13: ='Computation Table'!C39 -> 0.08855359 | E13: ='Computation Table'!C13 -> 0.086438012
B14: Monthly Amortization | C14: ='Computation Table'!C74 -> 2797.3541 | D14: ='Computation Table'!C48 -> 2766.1672 | E14: ='Computation Table'!C22 -> 1971.7742
B15: Service Fee | C15: =11% -> 0.11 | D15: 0.06 | E15: 0.05

Sheet Computation Table
C1: DATA ENTRY
B3: 3 Yrs
B4: GROSS | C4: =C22*C16 -> 70983.871 | D4: =D22*D16 -> 32659.191 | E4: =E22*E16 -> 65318.381 | F4: =F22*F16 -> 97977.572 | G4: =G22*G16 -> 130636.76 | H4: =H22*H16 -> 163295.95 | I4: =I22*I16 -> 195955.14 | J4: =J22*J16 -> 228614.33 | ... AT4: =AT22*AT16 -> 1404345.2
B5: NET | C5: ='Data Entry'!E4 -> 50000 | D5: 25000 | E5: 50000 | F5: 75000 | G5: 100000 | H5: 125000 | I5: 150000 | J5: 175000 | K5: 200000 | L5: 225000 | M5: 250000 | N5: 275000 | O5: 300000 | P5: 325000 | Q5: 350000 | R5: 375000 | S5: 400000 | T5: 425000 | U5: 450000 | V5: 475000 | W5: 500000 | X5: 525000 | Y5: 550000 | Z5: 575000 | AA5: 600000 | AB5: 625000 | AC5: 650000 | AD5: 675000 | AE5: 700000 | AF5: 725000 | AG5: 750000 | AH5: 775000 | AI5: 800000 | AJ5: 825000 | AK5: 850000 | AL5: 875000 | AM5: 900000 | AN5: 925000 | AO5: 950000 | AP5: 975000 | AQ5: 1000000 | AR5: 1025000 | AS5: 1050000 | AT5: 1075000
B6: SF | C6: =C5*0.11 -> 5500 | D6: =D5*0.11 -> 2750 | E6: =E5*0.11 -> 5500 | F6: =F5*0.11 -> 8250 | G6: =G5*0.11 -> 11000 | H6: =H5*0.11 -> 13750 | I6: =I5*0.11 -> 16500 | J6: =J5*0.11 -> 19250 | ... AT6: =AT5*0.11 -> 118250
B7: Insurance | C7: =(C5/1000)*C16 -> 1800 | D7: =(D5/1000)*D16 -> 900 | E7: =(E5/1000)*E16 -> 1800 | F7: =(F5/1000)*F16 -> 2700 | G7: =(G5/1000)*G16 -> 3600 | H7: =(H5/1000)*H16 -> 4500 | I7: =(I5/1000)*I16 -> 5400 | J7: =(J5/1000)*J16 -> 6300 | ... AT7: =(AT5/1000)*AT16 -> 38700
B8: CapCon | C8: ='Data Entry'!E8 -> 5000
B9: membership fee | C9: ='Data Entry'!E9 -> 0
B10: Advance Interest | C10: =C15*C5*1 -> 345.83333 | D10: =D15*D5*1 -> 172.91667 | E10: =E15*E5*1 -> 345.83333 | F10: =F15*F5*1 -> 518.75 | G10: =G15*G5*1 -> 691.66667 | H10: =H15*H5*1 -> 864.58333 | I10: =I15*I5*1 -> 1037.5 | J10: =J15*J5*1 -> 1210.4167 | ... AT10: =AT15*AT5*1 -> 7435.4167
B11: LOAN AMOUNT | C11: =SUM(C5:C10) -> 62645.833 | D11: =SUM(D5:D10) -> 28822.917 | E11: =SUM(E5:E10) -> 57645.833 | F11: =SUM(F5:F10) -> 86468.75 | G11: =SUM(G5:G10) -> 115291.67 | H11: =SUM(H5:H10) -> 144114.58 | I11: =SUM(I5:I10) -> 172937.5 | J11: =SUM(J5:J10) -> 201760.42 | ... AT11: =SUM(AT5:AT10) -> 1239385.4
B12: Annual Interest | C12: 0.083 | D12: 0.083 | E12: =C12 -> 0.083 | F12: =E12 -> 0.083 | G12: =F12 -> 0.083 | H12: =G12 -> 0.083 | I12: =H12 -> 0.083 | J12: =I12 -> 0.083 | K12: =J12 -> 0.083 | L12: =K12 -> 0.083 | M12: =L12 -> 0.083 | ... AT12: =AS12 -> 0.083
B13: Effective Interest rate | C13: =(1+C12/C16)^C16-1 -> 0.086438012 | D13: =(1+D12/D16)^D16-1 -> 0.086438012 | E13: =(1+E12/E16)^E16-1 -> 0.086438012 | F13: =(1+F12/F16)^F16-1 -> 0.086438012 | G13: =(1+G12/G16)^G16-1 -> 0.086438012 | H13: =(1+H12/H16)^H16-1 -> 0.086438012 | I13: =(1+I12/I16)^I16-1 -> 0.086438012 | J13: =(1+J12/J16)^J16-1 -> 0.086438012 | ... AT13: =(1+AT12/AT16)^AT16-1 -> 0.086438012
B14: Loan Term | C14: 3 | D14: 3 | E14: 3 | F14: 3 | G14: 3 | H14: 3 | I14: 3 | J14: 3 | K14: =G14 -> 3 | L14: =H14 -> 3 | M14: =J14 -> 3 | N14: =J14 -> 3 | O14: =K14 -> 3 | P14: =L14 -> 3 | Q14: =M14 -> 3 | R14: =N14 -> 3 | S14: =O14 -> 3 | T14: =P14 -> 3 | U14: =Q14 -> 3 | ... AT14: =AP14 -> 3
B15: Monthly Interest Rate | C15: =C12/12 -> 0.0069166667 | D15: =D12/12 -> 0.0069166667 | E15: =E12/12 -> 0.0069166667 | F15: =F12/12 -> 0.0069166667 | G15: =G12/12 -> 0.0069166667 | H15: =H12/12 -> 0.0069166667 | I15: =I12/12 -> 0.0069166667 | J15: =J12/12 -> 0.0069166667 | ... AT15: =AT12/12 -> 0.0069166667
B16: Nr of Payments | C16: =C14*12 -> 36 | D16: =D14*12 -> 36 | E16: =E14*12 -> 36 | F16: =F14*12 -> 36 | G16: =G14*12 -> 36 | H16: =H14*12 -> 36 | I16: =I14*12 -> 36 | J16: =J14*12 -> 36 | ... AT16: =AT14*12 -> 36
B18: Monthly Amortization | C18: =(1+C15)^C16 -> 1.281643 | D18: =(1+D15)^D16 -> 1.281643 | E18: =(1+E15)^E16 -> 1.281643 | F18: =(1+F15)^F16 -> 1.281643 | G18: =(1+G15)^G16 -> 1.281643 | H18: =(1+H15)^H16 -> 1.281643 | I18: =(1+I15)^I16 -> 1.281643 | J18: =(1+J15)^J16 -> 1.281643 | ... AT18: =(1+AT15)^AT16 -> 1.281643
C19: =C18*C15 -> 0.0088646972 | D19: =D18*D15 -> 0.0088646972 | E19: =E18*E15 -> 0.0088646972 | F19: =F18*F15 -> 0.0088646972 | G19: =G18*G15 -> 0.0088646972 | H19: =H18*H15 -> 0.0088646972 | I19: =I18*I15 -> 0.0088646972 | J19: =J18*J15 -> 0.0088646972 | ... AT19: =AT18*AT15 -> 0.0088646972
C20: =C18-1 -> 0.28164297 | D20: =D18-1 -> 0.28164297 | E20: =E18-1 -> 0.28164297 | F20: =F18-1 -> 0.28164297 | G20: =G18-1 -> 0.28164297 | H20: =H18-1 -> 0.28164297 | I20: =I18-1 -> 0.28164297 | J20: =J18-1 -> 0.28164297 | ... AT20: =AT18-1 -> 0.28164297
C21: =C19/C20 -> 0.031474946 | D21: =D19/D20 -> 0.031474946 | E21: =E19/E20 -> 0.031474946 | F21: =F19/F20 -> 0.031474946 | G21: =G19/G20 -> 0.031474946 | H21: =H19/H20 -> 0.031474946 | I21: =I19/I20 -> 0.031474946 | J21: =J19/J20 -> 0.031474946 | ... AT21: =AT19/AT20 -> 0.031474946
B22: Monthly Amortization | C22: =C21*C11 -> 1971.7742 | D22: =D21*D11 -> 907.19974 | E22: =E21*E11 -> 1814.3995 | F22: =F21*F11 -> 2721.5992 | G22: =G21*G11 -> 3628.799 | H22: =H21*H11 -> 4535.9987 | I22: =I21*I11 -> 5443.1984 | J22: =J21*J11 -> 6350.3982 | ... AT22: =AT21*AT11 -> 39009.589
B24: Income | C24: =C4-C5 -> 20983.871 | D24: =D4-D5 -> 7659.1906 | E24: =E4-E5 -> 15318.381 | F24: =F4-F5 -> 22977.572 | G24: =G4-G5 -> 30636.762 | H24: =H4-H5 -> 38295.953 | I24: =I4-I5 -> 45955.144 | J24: =J4-J5 -> 53614.334 | ... AT24: =AT4-AT5 -> 329345.2
B25: % Income | C25: =C24/C4 -> 0.29561464 | D25: =D24/D4 -> 0.23451869 | E25: =E24/E4 -> 0.23451869 | F25: =F24/F4 -> 0.23451869 | G25: =G24/G4 -> 0.23451869 | H25: =H24/H4 -> 0.23451869 | I25: =I24/I4 -> 0.23451869 | J25: =J24/J4 -> 0.23451869 | ... AT25: =AT24/AT4 -> 0.23451869
B29: 2 Yrs
B30: GROSS | C30: =C48*C42 -> 66388.013 | D30: =D48*D42 -> 30303.026 | E30: =E48*E42 -> 60606.051 | F30: =F48*F42 -> 90909.077 | G30: =G48*G42 -> 121212.1 | H30: =H48*H42 -> 151515.13 | I30: =I48*I42 -> 181818.15 | J30: =J48*J42 -> 212121.18 | ... AT30: =AT48*AT42 -> 1303030.1
B31: NET | C31: ='Data Entry'!D4 -> 50000 | D31: 25000 | E31: 50000 | F31: 75000 | G31: 100000 | H31: 125000 | I31: 150000 | J31: 175000 | K31: 200000 | L31: 225000 | M31: 250000 | N31: 275000 | O31: 300000 | P31: 325000 | Q31: 350000 | R31: 375000 | S31: 400000 | T31: 425000 | U31: 450000 | V31: 475000 | W31: 500000 | X31: 525000 | Y31: 550000 | Z31: 575000 | AA31: 600000 | AB31: 625000 | AC31: 650000 | AD31: 675000 | AE31: 700000 | AF31: 725000 | AG31: 750000 | AH31: 775000 | AI31: 800000 | AJ31: 825000 | AK31: 850000 | AL31: 875000 | AM31: 900000 | AN31: 925000 | AO31: 950000 | AP31: 975000 | AQ31: 1000000 | AR31: 1025000 | AS31: 1050000 | AT31: 1075000
B32: SF | C32: =C31*0.08 -> 4000 | D32: =D31*0.08 -> 2000 | E32: =E31*0.08 -> 4000 | F32: =F31*0.08 -> 6000 | G32: =G31*0.08 -> 8000 | H32: =H31*0.08 -> 10000 | I32: =I31*0.08 -> 12000 | J32: =J31*0.08 -> 14000 | ... AT32: =AT31*0.08 -> 86000
B33: Insurance | C33: =(C31/1000)*C42 -> 1200 | D33: =(D31/1000)*D42 -> 600 | E33: =(E31/1000)*E42 -> 1200 | F33: =(F31/1000)*F42 -> 1800 | G33: =(G31/1000)*G42 -> 2400 | H33: =(H31/1000)*H42 -> 3000 | I33: =(I31/1000)*I42 -> 3600 | J33: =(J31/1000)*J42 -> 4200 | ... AT33: =(AT31/1000)*AT42 -> 25800
B34: CapCon | C34: ='Data Entry'!D8 -> 5000
B35: membership fee | C35: ='Data Entry'!D9 -> 300
B36: Advance Interest | C36: =C41*C31*1 -> 354.16667 | D36: =D41*D31*1 -> 177.08333 | E36: =E41*E31*1 -> 354.16667 | F36: =F41*F31*1 -> 531.25 | G36: =G41*G31*1 -> 708.33333 | H36: =H41*H31*1 -> 885.41667 | I36: =I41*I31*1 -> 1062.5 | J36: =J41*J31*1 -> 1239.5833 | ... AT36: =AT41*AT31*1 -> 7614.5833
B37: LOAN AMOUNT | C37: =SUM(C31:C36) -> 60854.167 | D37: =SUM(D31:D36) -> 27777.083 | E37: =SUM(E31:E36) -> 55554.167 | F37: =SUM(F31:F36) -> 83331.25 | G37: =SUM(G31:G36) -> 111108.33 | H37: =SUM(H31:H36) -> 138885.42 | I37: =SUM(I31:I36) -> 166662.5 | J37: =SUM(J31:J36) -> 194439.58 | ... AT37: =SUM(AT31:AT36) -> 1194414.6
B38: Annual Interest | C38: 0.085 | D38: 0.085 | E38: =C38 -> 0.085 | F38: =E38 -> 0.085 | G38: =F38 -> 0.085 | H38: =G38 -> 0.085 | I38: =H38 -> 0.085 | J38: =I38 -> 0.085 | K38: =J38 -> 0.085 | L38: =K38 -> 0.085 | M38: =L38 -> 0.085 | ... AT38: =AS38 -> 0.085
B39: Effective Interest rate | C39: =(1+C38/C42)^C42-1 -> 0.08855359 | D39: =(1+D38/D42)^D42-1 -> 0.08855359 | E39: =(1+E38/E42)^E42-1 -> 0.08855359 | F39: =(1+F38/F42)^F42-1 -> 0.08855359 | G39: =(1+G38/G42)^G42-1 -> 0.08855359 | H39: =(1+H38/H42)^H42-1 -> 0.08855359 | I39: =(1+I38/I42)^I42-1 -> 0.08855359 | J39: =(1+J38/J42)^J42-1 -> 0.08855359 | ... AT39: =(1+AT38/AT42)^AT42-1 -> 0.08855359
B40: Loan Term | C40: 2 | D40: 2 | E40: 2 | F40: 2 | G40: 2 | H40: 2 | I40: 2 | J40: 2 | K40: =G40 -> 2 | L40: =H40 -> 2 | M40: =J40 -> 2 | N40: =J40 -> 2 | O40: =K40 -> 2 | P40: =L40 -> 2 | Q40: =M40 -> 2 | R40: =N40 -> 2 | S40: =O40 -> 2 | T40: =P40 -> 2 | U40: =Q40 -> 2 | ... AT40: =AP40 -> 2
B41: Monthly Interest Rate | C41: =C38/12 -> 0.0070833333 | D41: =D38/12 -> 0.0070833333 | E41: =E38/12 -> 0.0070833333 | F41: =F38/12 -> 0.0070833333 | G41: =G38/12 -> 0.0070833333 | H41: =H38/12 -> 0.0070833333 | I41: =I38/12 -> 0.0070833333 | J41: =J38/12 -> 0.0070833333 | ... AT41: =AT38/12 -> 0.0070833333
B42: Nr of Payments | C42: =C40*12 -> 24 | D42: =D40*12 -> 24 | E42: =E40*12 -> 24 | F42: =F40*12 -> 24 | G42: =G40*12 -> 24 | H42: =H40*12 -> 24 | I42: =I40*12 -> 24 | J42: =J40*12 -> 24 | ... AT42: =AT40*12 -> 24
B44: Monthly Amortization | C44: =(1+C41)^C42 -> 1.1845948 | D44: =(1+D41)^D42 -> 1.1845948 | E44: =(1+E41)^E42 -> 1.1845948 | F44: =(1+F41)^F42 -> 1.1845948 | G44: =(1+G41)^G42 -> 1.1845948 | H44: =(1+H41)^H42 -> 1.1845948 | I44: =(1+I41)^I42 -> 1.1845948 | J44: =(1+J41)^J42 -> 1.1845948 | ... AT44: =(1+AT41)^AT42 -> 1.1845948
C45: =C44*C41 -> 0.0083908796 | D45: =D44*D41 -> 0.0083908796 | E45: =E44*E41 -> 0.0083908796 | F45: =F44*F41 -> 0.0083908796 | G45: =G44*G41 -> 0.0083908796 | H45: =H44*H41 -> 0.0083908796 | I45: =I44*I41 -> 0.0083908796 | J45: =J44*J41 -> 0.0083908796 | ... AT45: =AT44*AT41 -> 0.0083908796
C46: =C44-1 -> 0.18459476 | D46: =D44-1 -> 0.18459476 | E46: =E44-1 -> 0.18459476 | F46: =F44-1 -> 0.18459476 | G46: =G44-1 -> 0.18459476 | H46: =H44-1 -> 0.18459476 | I46: =I44-1 -> 0.18459476 | J46: =J44-1 -> 0.18459476 | ... AT46: =AT44-1 -> 0.18459476
C47: =C45/C46 -> 0.045455675 | D47: =D45/D46 -> 0.045455675 | E47: =E45/E46 -> 0.045455675 | F47: =F45/F46 -> 0.045455675 | G47: =G45/G46 -> 0.045455675 | H47: =H45/H46 -> 0.045455675 | I47: =I45/I46 -> 0.045455675 | J47: =J45/J46 -> 0.045455675 | ... AT47: =AT45/AT46 -> 0.045455675
...

Sheet Amortization  Table
B1: PEOPLE'S MULTI-PURPOSE COOPERATIVE EFFECTIVE ON JANUARY 16, 2025
B4: CDEA, OCD LOAN TABLE
B5: Net Proceeds | C5: 1 Yr 12 Months | D5: 2 Yrs 36 Months | E5: 3 Yrs 36 Months
B7: 25000 | C7: ='Computation Table'!D74 -> 2360.0967 | D7: ='Computation Table'!D48 -> 1262.6261 | E7: ='Computation Table'!D22 -> 907.19974
B8: 50000 | C8: ='Computation Table'!E74 -> 4720.1935 | D8: ='Computation Table'!E48 -> 2525.2521 | E8: ='Computation Table'!E22 -> 1814.3995
B9: 75000 | C9: ='Computation Table'!F74 -> 7080.2902 | D9: ='Computation Table'!F48 -> 3787.8782 | E9: ='Computation Table'!F22 -> 2721.5992
B10: 100000 | C10: ='Computation Table'!G74 -> 9440.3869 | D10: ='Computation Table'!G48 -> 5050.5043 | E10: ='Computation Table'!G22 -> 3628.799
B11: 150000 | C11: ='Computation Table'!I74 -> 14160.58 | D11: ='Computation Table'!I48 -> 7575.7564 | E11: ='Computation Table'!I22 -> 5443.1984
B12: 200000 | C12: ='Computation Table'!K74 -> 18880.774 | D12: ='Computation Table'!K48 -> 10101.009 | E12: ='Computation Table'!K22 -> 7257.5979
B13: 250000 | C13: ='Computation Table'!M74 -> 23600.967 | D13: ='Computation Table'!M48 -> 12626.261 | E13: ='Computation Table'!M22 -> 9071.9974
B14: 300000 | C14: ='Computation Table'!O74 -> 28321.161 | D14: ='Computation Table'!O48 -> 15151.513 | E14: ='Computation Table'!O22 -> 10886.397
B15: 350000 | C15: ='Computation Table'!Q74 -> 33041.354 | D15: ='Computation Table'!Q48 -> 17676.765 | E15: ='Computation Table'!Q22 -> 12700.796
B16: 400000 | C16: ='Computation Table'!S74 -> 37761.548 | D16: ='Computation Table'!S48 -> 20202.017 | E16: ='Computation Table'!S22 -> 14515.196
B17: 450000 | C17: ='Computation Table'!U74 -> 42481.741 | D17: ='Computation Table'!U48 -> 22727.269 | E17: ='Computation Table'!U22 -> 16329.595
B18: 500000 | C18: ='Computation Table'!W74 -> 47201.935 | D18: ='Computation Table'!W48 -> 25252.521 | E18: ='Computation Table'!W22 -> 18143.995
B19: 550000 | C19: ='[1]Computation Table'!X126 -> 51417.378 | D19: ='[1]Computation Table'!X100 -> 27716.937 | E19: ='[1]Computation Table'!X74 -> 19566.156
B20: 600000 | C20: ='[1]Computation Table'!Z126 -> 56049.895 | D20: ='[1]Computation Table'!Z100 -> 30214.976 | E20: ='[1]Computation Table'!Z74 -> 21329.888
B21: 650000 | C21: ='[1]Computation Table'!AB126 -> 60682.412 | D21: ='[1]Computation Table'!AB100 -> 32713.016 | E21: ='[1]Computation Table'!AB74 -> 23093.62
B22: 700000 | C22: ='[1]Computation Table'!AD126 -> 65314.929 | D22: ='[1]Computation Table'!AD100 -> 35211.056 | E22: ='[1]Computation Table'!AD74 -> 24857.351
B23: 750000 | C23: ='[1]Computation Table'!AF126 -> 69947.446 | D23: ='[1]Computation Table'!AF100 -> 37709.096 | E23: ='[1]Computation Table'!AF74 -> 26621.083
B24: 800000 | C24: ='[1]Computation Table'!AH126 -> 74579.963 | D24: ='[1]Computation Table'!AH100 -> 40207.136 | E24: ='[1]Computation Table'!AH74 -> 28384.815
B25: 850000 | C25: ='[1]Computation Table'!AJ126 -> 79212.48 | D25: ='[1]Computation Table'!AJ100 -> 42705.176 | E25: ='[1]Computation Table'!AJ74 -> 30148.547
B26: 900000 | C26: ='[1]Computation Table'!AL126 -> 83844.997 | D26: ='[1]Computation Table'!AL100 -> 45203.216 | E26: ='[1]Computation Table'!AL74 -> 31912.278
B27: 950000 | C27: ='[1]Computation Table'!AN126 -> 88477.514 | D27: ='[1]Computation Table'!AN100 -> 47701.256 | E27: ='[1]Computation Table'!AN74 -> 33676.01
B28: 1000000 | C28: ='[1]Computation Table'!AP126 -> 93110.031 | D28: ='[1]Computation Table'!AP100 -> 50199.296 | E28: ='[1]Computation Table'!AP74 -> 35439.742

Sheet 1 Yr
B1: Amortization | C1: ='Data Entry'!C14 -> 2797.3541 | T1: pvap
B2: Timeline | C2: 0 | D2: 1 | E2: 2 | F2: 3 | G2: 4 | H2: 5 | I2: 6 | J2: 7 | K2: 8 | L2: 9 | M2: 10 | N2: 11 | O2: 12
B3: GROSS AMOUNT | C3: ='Data Entry'!C3 -> 33568.249
B4: LOAN AMOUNT | C4: ='Data Entry'!C11 -> 31987.5 | D4: =D10 -> -2797.3541 | E4: =E10 -> -2797.3541 | F4: =F10 -> -2797.3541 | G4: =G10 -> -2797.3541 | H4: =H10 -> -2797.3541 | I4: =I10 -> -2797.3541 | J4: =J10 -> -2797.3541 | K4: =K10 -> -2797.3541 | ... O4: =O10 -> -2797.3541
B5: Service Fee | C5: ='Data Entry'!C6 -> 1500
B6: Insurance | C6: ='Data Entry'!C7 -> 300
B7: CapCon | C7: ='Data Entry'!C8 -> 5000
B8: membership fee | C8: ='Data Entry'!C9 -> 0
B9: Advance Interest | C9: ='Data Entry'!C10 -> 187.5
B10: NET PROCEEDS/CASH FLOW | C10: =C4-C5-C6-C7-C8-C9 -> 25000 | D10: =-$C1 -> -2797.3541 | E10: =-$C1 -> -2797.3541 | F10: =-$C1 -> -2797.3541 | G10: =-$C1 -> -2797.3541 | H10: =-$C1 -> -2797.3541 | I10: =-$C1 -> -2797.3541 | J10: =-$C1 -> -2797.3541 | K10: =-$C1 -> -2797.3541 | ... O10: =-$C1 -> -2797.3541
B12: Interest Rate of Return | C12: =IRR(C4:O4) -> 0.0075 | D12: =C12/5 -> 0.0015
B14: Loan Balance
B15: Monthly Interest Rate | C15: ='Data Entry'!C12 -> 0.09
B16: Effective Interest Rate | C16: ='Data Entry'!C13 -> 0.093806898
C18: 1
C20: LOAN LEDGER CARD
C22: Name: | D22: RHODA SAMIANA PAGGABAO | G22: Loan Voucher No. | H22: CDEA - 009
C23: Serial Nr: | D23: 1988 - 006 | E23: Address: | F23: BLK 9 LOT 13 PH D. FRANCISCO HOMES SAN JOSE DEL MONTE BULACAN | G23: Amount: | H23: =C10 -> 25000
C24: Posting date | D24: Date of Loan: | E24: 45838 | F24: Maturity Date | G24: =B39 -> 46203 | K24: PEOPLE'S MULTI-PURPOSE COOPERATIVE
D25: Term: | E25: 12 | F25: MOS | K25: 20-E 2nd Camarilla St. corner 15th Ave., Brgy. San Roque, Murphy Cubao, Quezon City | X25: 20-E 2nd Camarilla St corner 15th Avenue,
D26: Loan | E26: Installment | F26: Principal | G26: EIR | H26: Balance | X26: Brgy San Roque, Murphy Cubao, Quezon City
D27: Month 0 | H27: =C4 -> 31987.5 | K27: LOAN RELEASE VOUCHER | X27: Mobile No. (+63)953-033-1580 (GLOBE)
B28: =DATE(YEAR(E$24),MONTH(E$24)+D28+0,DAY(E$24)) -> 45868 | C28: =TEXT(B28,"mmm-yyyy") -> Jul-2025 | D28: 1 | E28: =C$1 -> 2797.3541 | F28: =E28-G28 -> 2557.4479 | G28: =H27*C$12 -> 239.90625 | H28: =H27-F28 -> 29430.052
B29: =DATE(YEAR(E$24),MONTH(E$24)+D29+0,DAY(E$24)) -> 45899 | C29: =TEXT(B29,"mmm-yyyy") -> Aug-2025 | D29: 2 | E29: =C$1 -> 2797.3541 | F29: =E29-G29 -> 2576.6287 | G29: =H28*C$12 -> 220.72539 | H29: =H28-F29 -> 26853.423 | R29: Date: | S29: =E24 -> 45838 | X29: LOAN APPLICATION FORM
B30: =DATE(YEAR(E$24),MONTH(E$24)+D30+0,DAY(E$24)) -> 45930 | C30: =TEXT(B30,"mmm-yyyy") -> Sep-2025 | D30: 3 | E30: =C$1 -> 2797.3541 | F30: =E30-G30 -> 2595.9534 | G30: =H29*C$12 -> 201.40068 | H30: =H29-F30 -> 24257.47 | R30: LV No: | S30: =H22 -> CDEA - 009 | AU30: Date: | AW30: 0 | AX30: 6 | AY30: 3 | AZ30: 0 | BA30: 2 | BB30: 0 | BC30: 2 | BD30: 5
B31: =DATE(YEAR(E$24),MONTH(E$24)+D31+0,DAY(E$24)) -> 45960 | C31: =TEXT(B31,"mmm-yyyy") -> Oct-2025 | D31: 4 | E31: =C$1 -> 2797.3541 | F31: =E31-G31 -> 2615.4231 | G31: =H30*C$12 -> 181.93102 | H31: =H30-F31 -> 21642.047 | AW31: m | AX31: m | AY31: d | AZ31: d | BA31: y | BB31: y | BC31: y | BD31: y
B32: =DATE(YEAR(E$24),MONTH(E$24)+D32+0,DAY(E$24)) -> 45991 | C32: =TEXT(B32,"mmm-yyyy") -> Nov-2025 | D32: 5 | E32: =C$1 -> 2797.3541 | F32: =E32-G32 -> 2635.0388 | G32: =H31*C$12 -> 162.31535 | H32: =H31-F32 -> 19007.008 | K32: Name of Borrower: | N32: =D22 -> RHODA SAMIANA PAGGABAO | X32: APPLICATION TYPE | AE32: LOAN CLASSIFICATION | AM32: TERM | AT32: RELEASE OF LOAN PROCEEDS
B33: =DATE(YEAR(E$24),MONTH(E$24)+D33+0,DAY(E$24)) -> 46021 | C33: =TEXT(B33,"mmm-yyyy") -> Dec-2025 | D33: 6 | E33: =C$1 -> 2797.3541 | F33: =E33-G33 -> 2654.8016 | G33: =H32*C$12 -> 142.55256 | H33: =H32-F33 -> 16352.207 | K33: Serial No.: | N33: =D23 -> 1988 - 006 | Y33: New | AF33: Salary Loan | AN33: 12 Months | AU33: Check
B34: =DATE(YEAR(E$24),MONTH(E$24)+D34+0,DAY(E$24)) -> 46052 | C34: =TEXT(B34,"mmm-yyyy") -> Jan-2026 | D34: 7 | E34: =C$1 -> 2797.3541 | F34: =E34-G34 -> 2674.7126 | G34: =H33*C$12 -> 122.64155 | H34: =H33-F34 -> 13677.494 | K34: Address: | N34: =F23 -> BLK 9 LOT 13 PH D. FRANCISCO HOMES SAN JOSE DEL MONTE BULACAN | Y34: Renewal | AF34: Pension Loan | AN34: 24 Months | AU34: Bank Electronic Transfer to Borrowers Account
B35: =DATE(YEAR(E$24),MONTH(E$24)+D35+0,DAY(E$24)) -> 46083 | C35: =TEXT(B35,"mmm-yyyy") -> Mar-2026 | D35: 8 | E35: =C$1 -> 2797.3541 | F35: =E35-G35 -> 2694.7729 | G35: =H34*C$12 -> 102.58121 | H35: =H34-F35 -> 10982.721 | Y35: Additional | AF35: Emergency | AN35: 36 Months | AU35: Others:
B36: =DATE(YEAR(E$24),MONTH(E$24)+D36+0,DAY(E$24)) -> 46111 | C36: =TEXT(B36,"mmm-yyyy") -> Mar-2026 | D36: 9 | E36: =C$1 -> 2797.3541 | F36: =E36-G36 -> 2714.9837 | G36: =H35*C$12 -> 82.370408 | H36: =H35-F36 -> 8267.7374 | L36: Principal Amount | R36: =C4 -> 31987.5 | Y36: Reloan | AF36: Health Assistance Loan | AN36: 48 Months
B37: =DATE(YEAR(E$24),MONTH(E$24)+D37+0,DAY(E$24)) -> 46142 | C37: =TEXT(B37,"mmm-yyyy") -> Apr-2026 | D37: 10 | E37: =C$1 -> 2797.3541 | F37: =E37-G37 -> 2735.3461 | G37: =H36*C$12 -> 62.00803 | H37: =H36-F37 -> 5532.3913 | Y37: Restructure | AF37: Educational Loan | AN37: 60 Months
B38: =DATE(YEAR(E$24),MONTH(E$24)+D38+0,DAY(E$24)) -> 46172 | C38: =TEXT(B38,"mmm-yyyy") -> May-2026 | D38: 11 | E38: =C$1 -> 2797.3541 | F38: =E38-G38 -> 2755.8612 | G38: =H37*C$12 -> 41.492935 | H38: =H37-F38 -> 2776.5301 | L38: (-) | M38: Balance Old Loan(s) | R38: =-C14 -> 0 | AF38: Others: | AN38: Others:
B39: =DATE(YEAR(E$24),MONTH(E$24)+D39+0,DAY(E$24)) -> 46203 | C39: =TEXT(B39,"mmm-yyyy") -> Jun-2026 | D39: 12 | E39: =C$1 -> 2797.3541 | F39: =E39-G39 -> 2776.5301 | G39: =H38*C$12 -> 20.823976 | H39: =H38-F39 -> -1.3642421e-11 | L39: (-) | M39: Membership Fee: | R39: =-C8 -> 0 | X39: AMOUNT APPLIED: | AB39: =C10 -> 25000 | AN39: MONTHLY AMORTIZATION: | AT39: =R49 -> 2797.3541
E40: =SUM(E28:E39) -> 33568.249 | F40: =SUM(F28:F39) -> 31987.5 | G40: =SUM(G28:G39) -> 1580.7494 | L40: (-) | M40: Paid up Capital: | R40: =-C7 -> -5000
L41: (-) | M41: Service Fee | R41: =-C5 -> -1500 | X41: LOAN ID: | Z41: =S30 -> CDEA - 009 | AF41: DEDUCTION CODE: | AR41: LOAN PURPOSE:
L42: (-) | M42: Insurance Premium - Paramount | R42: =-C6 -> -300 | X42: MEM ID: | AG42: Regular Member | AS42: Old Member
L43: (-) | M43: Advance Interest | R43: =-C9 -> -187.5 | AG43: Associate Member | AS43: New Member
L44: NET PROCEEDS (Php): | R44: =SUM(R36:T43) -> 25000 | X44: BORROWER'S INFORMATION
X45: PAGGABAO | AD45: RHODA | AN45: SAMIANA
...

Sheet 2 Yrs
B1: Amortization | C1: ='Data Entry'!D14 -> 2766.1672 | T1: pvap
B2: Timeline | C2: 0 | D2: 1 | E2: 2 | F2: 3 | G2: 4 | H2: 5 | I2: 6 | J2: 7 | K2: 8 | L2: 9 | M2: 10 | N2: 11 | O2: 12 | P2: 13 | Q2: 14 | R2: 15 | S2: 16 | T2: 17 | U2: 18 | V2: 19 | W2: 20 | X2: 21 | Y2: 22 | Z2: 23 | AA2: 24
B3: GROSS AMOUNT | C3: ='Data Entry'!D3 -> 66388.013
B4: LOAN AMOUNT | C4: ='Data Entry'!D11 -> 60854.167
B5: Service Fee | C5: ='Data Entry'!D6 -> 4000
B6: Insurance | C6: ='Data Entry'!D7 -> 1200
B7: CapCon | C7: ='Data Entry'!D8 -> 5000
B8: membership fee | C8: ='Data Entry'!D9 -> 300
B9: Advance Interest | C9: ='Data Entry'!D10 -> 354.16667
B10: NET PROCEEDS/CASH FLOW | C10: =C4-C5-C6-C7-C8-C9 -> 50000 | D10: =-$C1 -> -2766.1672 | E10: =-$C1 -> -2766.1672 | F10: =-$C1 -> -2766.1672 | G10: =-$C1 -> -2766.1672 | H10: =-$C1 -> -2766.1672 | I10: =-$C1 -> -2766.1672 | J10: =-$C1 -> -2766.1672 | K10: =-$C1 -> -2766.1672 | ... AA10: =-$C1 -> -2766.1672
B12: Interest Rate of Return | C12: =IRR(C10:AA10) -> 0.024042929 | D12: =C12/5 -> 0.0048085858
B14: Loan Balance
B15: Monthly Interest Rate | C15: ='Data Entry'!D12/12 -> 0.0070833333
B16: Effective Interest Rate | C16: ='Data Entry'!D13 -> 0.08855359
B17: Term | C17: 24
C20: LOAN LEDGER CARD
C22: Name: | D22: MARY ANN ELVEÑA MENDEZ | G22: Loan Voucher No. | H22: CDEA-006
C23: Serial Nr: | D23: 2012-039 | E23: Address: | F23: 043 ZONE 2, PC HILL, ROSARY HEIGHTS I, COTABATO CITY
C24: Posting date | D24: Date of Loan: | E24: 45771 | F24: Maturity Date | G24: =B51 -> 46501 | K24: PEOPLE'S MULTI-PURPOSE COOPERATIVE
D25: Term: | E25: =C17 -> 24 | F25: MOS | K25: 20-E 2nd Camarilla St. corner 15th Ave., Brgy. San Roque, Murphy Cubao, Quezon City | X25: 20-E 2nd Camarilla St corner 15th Avenue,
D26: Loan | E26: Installment | F26: Principal | G26: EIR | H26: Balance | X26: Brgy San Roque, Murphy Cubao, Quezon City
D27: Month 0 | H27: =C10 -> 50000 | K27: LOAN RELEASE VOUCHER | X27: Mobile No. (+63)953-033-1580 (GLOBE)
B28: =DATE(YEAR(E$24),MONTH(E$24)+D28+0,DAY(E$24)) -> 45801 | C28: =TEXT(B28,"mmm-yyyy") -> May-2025 | D28: 1 | E28: =C$1 -> 2766.1672 | F28: =E28-G28 -> 1564.0208 | G28: =H27*C$12 -> 1202.1464 | H28: =H27-F28 -> 48435.979
B29: =DATE(YEAR(E$24),MONTH(E$24)+D29+0,DAY(E$24)) -> 45832 | C29: =TEXT(B29,"mmm-yyyy") -> Jun-2025 | D29: 2 | E29: =C$1 -> 2766.1672 | F29: =E29-G29 -> 1601.6244 | G29: =H28*C$12 -> 1164.5428 | H29: =H28-F29 -> 46834.355 | R29: Date: | S29: =E24 -> 45771 | X29: LOAN APPLICATION FORM
B30: =DATE(YEAR(E$24),MONTH(E$24)+D30+0,DAY(E$24)) -> 45862 | C30: =TEXT(B30,"mmm-yyyy") -> Jul-2025 | D30: 3 | E30: =C$1 -> 2766.1672 | F30: =E30-G30 -> 1640.1321 | G30: =H29*C$12 -> 1126.0351 | H30: =H29-F30 -> 45194.223 | R30: LV No: | S30: =H22 -> CDEA-006 | AU30: Date: | AW30: 0 | AX30: 4 | AY30: 2 | AZ30: 4 | BA30: 2 | BB30: 0 | BC30: 2 | BD30: 5
B31: =DATE(YEAR(E$24),MONTH(E$24)+D31+0,DAY(E$24)) -> 45893 | C31: =TEXT(B31,"mmm-yyyy") -> Aug-2025 | D31: 4 | E31: =C$1 -> 2766.1672 | F31: =E31-G31 -> 1679.5657 | G31: =H30*C$12 -> 1086.6015 | H31: =H30-F31 -> 43514.657 | AW31: m | AX31: m | AY31: d | AZ31: d | BA31: y | BB31: y | BC31: y | BD31: y
B32: =DATE(YEAR(E$24),MONTH(E$24)+D32+0,DAY(E$24)) -> 45924 | C32: =TEXT(B32,"mmm-yyyy") -> Sep-2025 | D32: 5 | E32: =C$1 -> 2766.1672 | F32: =E32-G32 -> 1719.9474 | G32: =H31*C$12 -> 1046.2198 | H32: =H31-F32 -> 41794.71 | K32: Name of Borrower: | N32: =D22 -> MARY ANN ELVEÑA MENDEZ | X32: APPLICATION TYPE | AE32: LOAN CLASSIFICATION | AM32: TERM | AT32: RELEASE OF LOAN PROCEEDS
B33: =DATE(YEAR(E$24),MONTH(E$24)+D33+0,DAY(E$24)) -> 45954 | C33: =TEXT(B33,"mmm-yyyy") -> Oct-2025 | D33: 6 | E33: =C$1 -> 2766.1672 | F33: =E33-G33 -> 1761.3 | G33: =H32*C$12 -> 1004.8672 | H33: =H32-F33 -> 40033.41 | K33: Serial No.: | N33: =D23 -> 2012-039 | Y33: New | AF33: Salary Loan | AN33: 12 Months | AU33: Check
B34: =DATE(YEAR(E$24),MONTH(E$24)+D34+0,DAY(E$24)) -> 45985 | C34: =TEXT(B34,"mmm-yyyy") -> Nov-2025 | D34: 7 | E34: =C$1 -> 2766.1672 | F34: =E34-G34 -> 1803.6468 | G34: =H33*C$12 -> 962.52042 | H34: =H33-F34 -> 38229.763 | K34: Address: | N34: =F23 -> 043 ZONE 2, PC HILL, ROSARY HEIGHTS I, COTABATO CITY | Y34: Renewal | AF34: Pension Loan | AN34: 24 Months | AU34: Bank Electronic Transfer to Borrowers Account
B35: =DATE(YEAR(E$24),MONTH(E$24)+D35+0,DAY(E$24)) -> 46015 | C35: =TEXT(B35,"mmm-yyyy") -> Dec-2025 | D35: 8 | E35: =C$1 -> 2766.1672 | F35: =E35-G35 -> 1847.0117 | G35: =H34*C$12 -> 919.15547 | H35: =H34-F35 -> 36382.751 | Y35: Additional | AF35: Emergency | AN35: 36 Months | AU35: Others:
B36: =DATE(YEAR(E$24),MONTH(E$24)+D36+0,DAY(E$24)) -> 46046 | C36: =TEXT(B36,"mmm-yyyy") -> Jan-2026 | D36: 9 | E36: =C$1 -> 2766.1672 | F36: =E36-G36 -> 1891.4193 | G36: =H35*C$12 -> 874.7479 | H36: =H35-F36 -> 34491.332 | L36: Principal Amount | R36: =C4 -> 60854.167 | Y36: Reloan | AF36: Health Assistance Loan | AN36: 48 Months
B37: =DATE(YEAR(E$24),MONTH(E$24)+D37+0,DAY(E$24)) -> 46077 | C37: =TEXT(B37,"mmm-yyyy") -> Feb-2026 | D37: 10 | E37: =C$1 -> 2766.1672 | F37: =E37-G37 -> 1936.8946 | G37: =H36*C$12 -> 829.27264 | H37: =H36-F37 -> 32554.437 | Y37: Restructure | AF37: Educational Loan | AN37: 60 Months
B38: =DATE(YEAR(E$24),MONTH(E$24)+D38+0,DAY(E$24)) -> 46105 | C38: =TEXT(B38,"mmm-yyyy") -> Mar-2026 | D38: 11 | E38: =C$1 -> 2766.1672 | F38: =E38-G38 -> 1983.4632 | G38: =H37*C$12 -> 782.70402 | H38: =H37-F38 -> 30570.974 | L38: (-) | M38: Balance Old Loan(s) | R38: =-C14 -> 0 | AF38: Others: | AN38: Others:
B39: =DATE(YEAR(E$24),MONTH(E$24)+D39+0,DAY(E$24)) -> 46136 | C39: =TEXT(B39,"mmm-yyyy") -> Apr-2026 | D39: 12 | E39: =C$1 -> 2766.1672 | F39: =E39-G39 -> 2031.1515 | G39: =H38*C$12 -> 735.01576 | H39: =H38-F39 -> 28539.822 | L39: (-) | M39: Membership Fee: | R39: =-C8 -> -300 | X39: AMOUNT APPLIED: | AB39: =R44 -> 50000 | AN39: MONTHLY AMORTIZATION: | AT39: =R49 -> 2766.1672
B40: =DATE(YEAR(E$24),MONTH(E$24)+D40+0,DAY(E$24)) -> 46166 | C40: =TEXT(B40,"mmm-yyyy") -> May-2026 | D40: 13 | E40: =C$1 -> 2766.1672 | F40: =E40-G40 -> 2079.9863 | G40: =H39*C$12 -> 686.18093 | H40: =H39-F40 -> 26459.836 | L40: (-) | M40: Paid up Capital: | R40: =-C7 -> -5000
B41: =DATE(YEAR(E$24),MONTH(E$24)+D41+0,DAY(E$24)) -> 46197 | C41: =TEXT(B41,"mmm-yyyy") -> Jun-2026 | D41: 14 | E41: =C$1 -> 2766.1672 | F41: =E41-G41 -> 2129.9953 | G41: =H40*C$12 -> 636.17196 | H41: =H40-F41 -> 24329.841 | L41: (-) | M41: Service Fee | R41: =-C5 -> -4000 | X41: LOAN ID: | AF41: DEDUCTION CODE: | AR41: LOAN PURPOSE:
B42: =DATE(YEAR(E$24),MONTH(E$24)+D42+0,DAY(E$24)) -> 46227 | C42: =TEXT(B42,"mmm-yyyy") -> Jul-2026 | D42: 15 | E42: =C$1 -> 2766.1672 | F42: =E42-G42 -> 2181.2066 | G42: =H41*C$12 -> 584.96064 | H42: =H41-F42 -> 22148.634 | L42: (-) | M42: Insurance Premium - Paramount | R42: =-C6 -> -1200 | X42: MEM ID: | AG42: Regular Member | AS42: Old Member
B43: =DATE(YEAR(E$24),MONTH(E$24)+D43+0,DAY(E$24)) -> 46258 | C43: =TEXT(B43,"mmm-yyyy") -> Aug-2026 | D43: 16 | E43: =C$1 -> 2766.1672 | F43: =E43-G43 -> 2233.6492 | G43: =H42*C$12 -> 532.51804 | H43: =H42-F43 -> 19914.985 | L43: (-) | M43: Advance Interest | R43: =-C9 -> -354.16667 | AG43: Associate Member | AS43: New Member
B44: =DATE(YEAR(E$24),MONTH(E$24)+D44+0,DAY(E$24)) -> 46289 | C44: =TEXT(B44,"mmm-yyyy") -> Sep-2026 | D44: 17 | E44: =C$1 -> 2766.1672 | F44: =E44-G44 -> 2287.3526 | G44: =H43*C$12 -> 478.81457 | H44: =H43-F44 -> 17627.633 | L44: NET PROCEEDS (Php): | R44: =SUM(R36:T43) -> 50000 | X44: BORROWER'S INFORMATION
B45: =DATE(YEAR(E$24),MONTH(E$24)+D45+0,DAY(E$24)) -> 46319 | C45: =TEXT(B45,"mmm-yyyy") -> Oct-2026 | D45: 18 | E45: =C$1 -> 2766.1672 | F45: =E45-G45 -> 2342.3473 | G45: =H44*C$12 -> 423.81992 | H45: =H44-F45 -> 15285.285 | X45: MENDEZ | AD45: MARY ANN | AN45: ELVEÑA
...

Sheet 3 years
B1: Amortization | C1: ='Data Entry'!E14 -> 1971.7742 | T1: pvap
B2: Timeline | C2: 0 | D2: 1 | E2: 2 | F2: 3 | G2: 4 | H2: 5 | I2: 6 | J2: 7 | K2: 8 | L2: 9 | M2: 10 | N2: 11 | O2: 12 | P2: 13 | Q2: 14 | R2: 15 | S2: 16 | T2: 17 | U2: 18 | V2: 19 | W2: 20 | X2: 21 | Y2: 22 | Z2: 23 | AA2: 24 | AB2: 25 | AC2: 26 | AD2: 27 | AE2: 28 | AF2: 29 | AG2: 30 | AH2: 31 | AI2: 32 | AJ2: 33 | AK2: 34 | AL2: 35 | AM2: 36
B3: GROSS AMOUNT | C3: ='Data Entry'!E3 -> 70983.871
B4: LOAN AMOUNT | C4: ='Data Entry'!E11 -> 62645.833
B5: Service Fee | C5: ='Data Entry'!E6 -> 5500
B6: Insurance | C6: ='Data Entry'!E7 -> 1800
B7: CapCon | C7: ='Data Entry'!E8 -> 5000
B8: membership fee | C8: ='Data Entry'!E9 -> 0
B9: Advance Interest | C9: ='Data Entry'!E10 -> 345.83333
B10: NET PROCEEDS/CASH FLOW | C10: =C4-C5-C6-C7-C8-C9 -> 50000 | D10: =-$C1 -> -1971.7742 | E10: =-$C1 -> -1971.7742 | F10: =-$C1 -> -1971.7742 | G10: =-$C1 -> -1971.7742 | H10: =-$C1 -> -1971.7742 | I10: =-$C1 -> -1971.7742 | J10: =-$C1 -> -1971.7742 | K10: =-$C1 -> -1971.7742 | ... AM10: =-$C1 -> -1971.7742
B12: Interest Rate of Return | C12: =IRR(C10:AM10) -> 0.020321151 | D12: =C12/5 -> 0.0040642302
B14: Loan Balance
B15: Monthly Interest Rate | C15: ='Data Entry'!D12/12 -> 0.0070833333
B16: Effective Interest Rate | C16: ='Data Entry'!D13 -> 0.08855359
B17: Term | C17: 36
C20: LOAN LEDGER CARD
C22: Name: | D22: KELVIN ART T OFRECIO | G22: Loan Voucher No. | H22: CDEA-005
C23: Serial Nr: | D23: 2012-015 | E23: Address: | F23: BLK 8, LOT 36, PHASE O, FRANCISCO HOMES- NARRA, CSJDM, BULACAN
C24: Posting date | D24: Date of Loan: | E24: 45754 | F24: Maturity Date | G24: =B51 -> 46484 | K24: PEOPLE'S MULTI-PURPOSE COOPERATIVE
D25: Term: | E25: 36 | F25: MOS | K25: 20-E 2nd Camarilla St. corner 15th Ave., Brgy. San Roque, Murphy Cubao, Quezon City | X25: 20-E 2nd Camarilla St corner 15th Avenue,
D26: Loan | E26: Installment | F26: Principal | G26: EIR | H26: Balance | X26: Brgy San Roque, Murphy Cubao, Quezon City
D27: Month 0 | H27: =C10 -> 50000 | K27: LOAN RELEASE VOUCHER | X27: Mobile No. (+63)953-033-1580 (GLOBE)
B28: =DATE(YEAR(E$24),MONTH(E$24)+D28+0,DAY(E$24)) -> 45784 | C28: =TEXT(B28,"mmm-yyyy") -> May-2025 | D28: 1 | E28: =C$1 -> 1971.7742 | F28: =E28-G28 -> 955.71667 | G28: =H27*C$12 -> 1016.0575 | H28: =H27-F28 -> 49044.283
B29: =DATE(YEAR(E$24),MONTH(E$24)+D29+0,DAY(E$24)) -> 45815 | C29: =TEXT(B29,"mmm-yyyy") -> Jun-2025 | D29: 2 | E29: =C$1 -> 1971.7742 | F29: =E29-G29 -> 975.13793 | G29: =H28*C$12 -> 996.63628 | H29: =H28-F29 -> 48069.145 | R29: Date: | S29: =E24 -> 45754 | X29: LOAN APPLICATION FORM
B30: =DATE(YEAR(E$24),MONTH(E$24)+D30+0,DAY(E$24)) -> 45845 | C30: =TEXT(B30,"mmm-yyyy") -> Jul-2025 | D30: 3 | E30: =C$1 -> 1971.7742 | F30: =E30-G30 -> 994.95386 | G30: =H29*C$12 -> 976.82035 | H30: =H29-F30 -> 47074.192 | R30: LV No: | S30: =H22 -> CDEA-005 | AU30: Date: | AW30: 0 | AX30: 4 | AY30: 0 | AZ30: 7 | BA30: 2 | BB30: 0 | BC30: 2 | BD30: 5
B31: =DATE(YEAR(E$24),MONTH(E$24)+D31+0,DAY(E$24)) -> 45876 | C31: =TEXT(B31,"mmm-yyyy") -> Aug-2025 | D31: 4 | E31: =C$1 -> 1971.7742 | F31: =E31-G31 -> 1015.1725 | G31: =H30*C$12 -> 956.60174 | H31: =H30-F31 -> 46059.019 | AW31: m | AX31: m | AY31: d | AZ31: d | BA31: y | BB31: y | BC31: y | BD31: y
B32: =DATE(YEAR(E$24),MONTH(E$24)+D32+0,DAY(E$24)) -> 45907 | C32: =TEXT(B32,"mmm-yyyy") -> Sep-2025 | D32: 5 | E32: =C$1 -> 1971.7742 | F32: =E32-G32 -> 1035.8019 | G32: =H31*C$12 -> 935.97227 | H32: =H31-F32 -> 45023.217 | K32: Name of Borrower: | N32: =D22 -> KELVIN ART T OFRECIO | X32: APPLICATION TYPE | AE32: LOAN CLASSIFICATION | AM32: TERM | AT32: RELEASE OF LOAN PROCEEDS
B33: =DATE(YEAR(E$24),MONTH(E$24)+D33+0,DAY(E$24)) -> 45937 | C33: =TEXT(B33,"mmm-yyyy") -> Oct-2025 | D33: 6 | E33: =C$1 -> 1971.7742 | F33: =E33-G33 -> 1056.8506 | G33: =H32*C$12 -> 914.92358 | H33: =H32-F33 -> 43966.367 | K33: Serial No.: | N33: =D23 -> 2012-015 | Y33: New | AF33: Salary Loan | AN33: 12 Months | AU33: Check
B34: =DATE(YEAR(E$24),MONTH(E$24)+D34+0,DAY(E$24)) -> 45968 | C34: =TEXT(B34,"mmm-yyyy") -> Nov-2025 | D34: 7 | E34: =C$1 -> 1971.7742 | F34: =E34-G34 -> 1078.327 | G34: =H33*C$12 -> 893.44716 | H34: =H33-F34 -> 42888.039 | K34: Address: | N34: =F23 -> BLK 8, LOT 36, PHASE O, FRANCISCO HOMES- NARRA, CSJDM, BULACAN | Y34: Renewal | AF34: Pension Loan | AN34: 24 Months | AU34: Bank Electronic Transfer to Borrowers Account
B35: =DATE(YEAR(E$24),MONTH(E$24)+D35+0,DAY(E$24)) -> 45998 | C35: =TEXT(B35,"mmm-yyyy") -> Dec-2025 | D35: 8 | E35: =C$1 -> 1971.7742 | F35: =E35-G35 -> 1100.2399 | G35: =H34*C$12 -> 871.53432 | H35: =H34-F35 -> 41787.8 | Y35: Additional | AF35: Emergency | AN35: 36 Months | AU35: Others:
B36: =DATE(YEAR(E$24),MONTH(E$24)+D36+0,DAY(E$24)) -> 46029 | C36: =TEXT(B36,"mmm-yyyy") -> Jan-2026 | D36: 9 | E36: =C$1 -> 1971.7742 | F36: =E36-G36 -> 1122.598 | G36: =H35*C$12 -> 849.17617 | H36: =H35-F36 -> 40665.202 | L36: Principal Amount | R36: =C4 -> 62645.833 | Y36: Reloan | AF36: Health Assistance Loan | AN36: 48 Months
B37: =DATE(YEAR(E$24),MONTH(E$24)+D37+0,DAY(E$24)) -> 46060 | C37: =TEXT(B37,"mmm-yyyy") -> Feb-2026 | D37: 10 | E37: =C$1 -> 1971.7742 | F37: =E37-G37 -> 1145.4105 | G37: =H36*C$12 -> 826.36369 | H37: =H36-F37 -> 39519.791 | Y37: Restructure | AF37: Educational Loan | AN37: 60 Months
B38: =DATE(YEAR(E$24),MONTH(E$24)+D38+0,DAY(E$24)) -> 46088 | C38: =TEXT(B38,"mmm-yyyy") -> Mar-2026 | D38: 11 | E38: =C$1 -> 1971.7742 | F38: =E38-G38 -> 1168.6866 | G38: =H37*C$12 -> 803.08763 | H38: =H37-F38 -> 38351.104 | L38: (-) | M38: Balance Old Loan(s) | R38: =-C14 -> 0 | AF38: Others: | AN38: Others:
B39: =DATE(YEAR(E$24),MONTH(E$24)+D39+0,DAY(E$24)) -> 46119 | C39: =TEXT(B39,"mmm-yyyy") -> Apr-2026 | D39: 12 | E39: =C$1 -> 1971.7742 | F39: =E39-G39 -> 1192.4356 | G39: =H38*C$12 -> 779.33858 | H39: =H38-F39 -> 37158.669 | L39: (-) | M39: Membership Fee: | R39: =-C8 -> 0 | X39: AMOUNT APPLIED: | AB39: ='Data Entry'!E4 -> 50000 | AN39: MONTHLY AMORTIZATION: | AT39: =R49 -> 1971.7742
B40: =DATE(YEAR(E$24),MONTH(E$24)+D40+0,DAY(E$24)) -> 46149 | C40: =TEXT(B40,"mmm-yyyy") -> May-2026 | D40: 13 | E40: =C$1 -> 1971.7742 | F40: =E40-G40 -> 1216.6673 | G40: =H39*C$12 -> 755.10691 | H40: =H39-F40 -> 35942.002 | L40: (-) | M40: Paid up Capital: | R40: =-C7 -> -5000
B41: =DATE(YEAR(E$24),MONTH(E$24)+D41+0,DAY(E$24)) -> 46180 | C41: =TEXT(B41,"mmm-yyyy") -> Jun-2026 | D41: 14 | E41: =C$1 -> 1971.7742 | F41: =E41-G41 -> 1241.3914 | G41: =H40*C$12 -> 730.38283 | H41: =H40-F41 -> 34700.61 | L41: (-) | M41: Service Fee | R41: =-C5 -> -5500 | X41: LOAN ID: | Z41: =S30 -> CDEA-005 | AF41: DEDUCTION CODE: | AR41: LOAN PURPOSE:
B42: =DATE(YEAR(E$24),MONTH(E$24)+D42+0,DAY(E$24)) -> 46210 | C42: =TEXT(B42,"mmm-yyyy") -> Jul-2026 | D42: 15 | E42: =C$1 -> 1971.7742 | F42: =E42-G42 -> 1266.6179 | G42: =H41*C$12 -> 705.15633 | H42: =H41-F42 -> 33433.992 | L42: (-) | M42: Insurance Premium - Paramount | R42: =-C6 -> -1800 | X42: MEM ID: | AG42: Regular Member | AS42: Old Member
B43: =DATE(YEAR(E$24),MONTH(E$24)+D43+0,DAY(E$24)) -> 46241 | C43: =TEXT(B43,"mmm-yyyy") -> Aug-2026 | D43: 16 | E43: =C$1 -> 1971.7742 | F43: =E43-G43 -> 1292.357 | G43: =H42*C$12 -> 679.4172 | H43: =H42-F43 -> 32141.635 | L43: (-) | M43: Advance Interest | R43: =-C9 -> -345.83333 | AG43: Associate Member | AS43: New Member
B44: =DATE(YEAR(E$24),MONTH(E$24)+D44+0,DAY(E$24)) -> 46272 | C44: =TEXT(B44,"mmm-yyyy") -> Sep-2026 | D44: 17 | E44: =C$1 -> 1971.7742 | F44: =E44-G44 -> 1318.6192 | G44: =H43*C$12 -> 653.15502 | H44: =H43-F44 -> 30823.016 | L44: NET PROCEEDS (Php): | R44: =SUM(R36:T43) -> 50000 | X44: BORROWER'S INFORMATION
B45: =DATE(YEAR(E$24),MONTH(E$24)+D45+0,DAY(E$24)) -> 46302 | C45: =TEXT(B45,"mmm-yyyy") -> Oct-2026 | D45: 18 | E45: =C$1 -> 1971.7742 | F45: =E45-G45 -> 1345.4151 | G45: =H44*C$12 -> 626.35916 | H45: =H44-F45 -> 29477.601 | X45: OFRECIO | AD45: KELVIN ART | AN45: TEOFISTO
...

Sheet Marquez 
B1: Amortization | C1: ='[2]Data Entry'!E14 -> 5610.0156 | T1: pvap
B2: Timeline | C2: 0 | D2: 1 | E2: 2 | F2: 3 | G2: 4 | H2: 5 | I2: 6 | J2: 7 | K2: 8 | L2: 9 | M2: 10 | N2: 11 | O2: 12 | P2: 13 | Q2: 14 | R2: 15 | S2: 16 | T2: 17 | U2: 18 | V2: 19 | W2: 20 | X2: 21 | Y2: 22 | Z2: 23 | AA2: 24 | AB2: 25 | AC2: 26 | AD2: 27 | AE2: 28 | AF2: 29 | AG2: 30 | AH2: 31 | AI2: 32 | AJ2: 33 | AK2: 34 | AL2: 35 | AM2: 36
B3: GROSS AMOUNT | C3: ='[2]Data Entry'!E3 -> 201960.56
A4: 41 | B4: LOAN AMOUNT | C4: ='[2]Data Entry'!E11 -> 178237.5
B5: Service Fee | C5: ='[2]Data Entry'!E6 -> 16500
B6: Insurance | C6: ='[2]Data Entry'!E7 -> 5400
B7: CapCon | C7: ='[2]Data Entry'!E8 -> 5000
B8: membership fee | C8: ='[2]Data Entry'!E9 -> 300
B9: Advance Interest | C9: ='[2]Data Entry'!E10 -> 1037.5
B10: NET PROCEEDS/CASH FLOW | C10: =C4-C5-C6-C7-C8-C9 -> 150000 | D10: =-$C1 -> -5610.0156 | E10: =-$C1 -> -5610.0156 | F10: =-$C1 -> -5610.0156 | G10: =-$C1 -> -5610.0156 | H10: =-$C1 -> -5610.0156 | I10: =-$C1 -> -5610.0156 | J10: =-$C1 -> -5610.0156 | K10: =-$C1 -> -5610.0156 | ... AM10: =-$C1 -> -5610.0156
B12: Interest Rate of Return | C12: =IRR(C10:AM10) -> 0.01705281 | D12: =C12/5 -> 0.003410562
B14: Loan Balance
B15: Monthly Interest Rate | C15: ='[2]Data Entry'!D12/12 -> 0.0070833333
B16: Effective Interest Rate | C16: ='[2]Data Entry'!D13 -> 0.08855359
B17: Term | C17: 24
C20: LOAN LEDGER CARD
C22: Name: | D22: MADONNA LYN ORTEGA MARQUEZ | G22: Loan Voucher No. | H22: CDEA-001
C23: Serial Nr: | D23: 2004-023 | E23: Address: | F23: BLK 1 LOT 8 JOSHUA ST., BEYOND HOMES BRGY SAN FRANCISCO, GENERAL TRIAS, CAVITE
C24: Posting date | D24: Date of Loan: | E24: 45701 | F24: Maturity Date | G24: =B51 -> 46431 | K24: PEOPLE'S MULTI-PURPOSE COOPERATIVE
D25: Term: | E25: 36 | F25: MOS | K25: 20-E 2nd Camarilla St. corner 15th Ave., Brgy. San Roque, Murphy Cubao, Quezon City | X25: 20-E 2nd Camarilla St corner 15th Avenue,
D26: Loan | E26: Installment | F26: Principal | G26: EIR | H26: Balance | X26: Brgy San Roque, Murphy Cubao, Quezon City
D27: Month 0 | H27: =C10 -> 150000 | K27: LOAN RELEASE VOUCHER | X27: Mobile No. (+63)953-033-1580 (GLOBE)
B28: =DATE(YEAR(E$24),MONTH(E$24)+D28+0,DAY(E$24)) -> 45729 | C28: =TEXT(B28,"mmm-yyyy") -> Mar-2025 | D28: 1 | E28: =C$1 -> 5610.0156 | F28: =E28-G28 -> 3052.0942 | G28: =H27*C$12 -> 2557.9215 | H28: =H27-F28 -> 146947.91
B29: =DATE(YEAR(E$24),MONTH(E$24)+D29+0,DAY(E$24)) -> 45760 | C29: =TEXT(B29,"mmm-yyyy") -> Apr-2025 | D29: 2 | E29: =C$1 -> 5610.0156 | F29: =E29-G29 -> 3104.1409 | G29: =H28*C$12 -> 2505.8747 | H29: =H28-F29 -> 143843.76 | R29: Date: | S29: =E24 -> 45701 | X29: LOAN APPLICATION FORM
B30: =DATE(YEAR(E$24),MONTH(E$24)+D30+0,DAY(E$24)) -> 45790 | C30: =TEXT(B30,"mmm-yyyy") -> May-2025 | D30: 3 | E30: =C$1 -> 5610.0156 | F30: =E30-G30 -> 3157.0753 | G30: =H29*C$12 -> 2452.9404 | H30: =H29-F30 -> 140686.69 | R30: LV No: | S30: =D23 -> 2004-023 | AU30: Date: | AW30: 0 | AX30: 2 | AY30: 1 | AZ30: 3 | BA30: 2 | BB30: 0 | BC30: 2 | BD30: 5
B31: =DATE(YEAR(E$24),MONTH(E$24)+D31+0,DAY(E$24)) -> 45821 | C31: =TEXT(B31,"mmm-yyyy") -> Jun-2025 | D31: 4 | E31: =C$1 -> 5610.0156 | F31: =E31-G31 -> 3210.9123 | G31: =H30*C$12 -> 2399.1034 | H31: =H30-F31 -> 137475.78 | AW31: m | AX31: m | AY31: d | AZ31: d | BA31: y | BB31: y | BC31: y | BD31: y
B32: =DATE(YEAR(E$24),MONTH(E$24)+D32+0,DAY(E$24)) -> 45851 | C32: =TEXT(B32,"mmm-yyyy") -> Jul-2025 | D32: 5 | E32: =C$1 -> 5610.0156 | F32: =E32-G32 -> 3265.6674 | G32: =H31*C$12 -> 2344.3483 | H32: =H31-F32 -> 134210.11 | K32: Name of Borrower: | N32: =D22 -> MADONNA LYN ORTEGA MARQUEZ | X32: APPLICATION TYPE | AE32: LOAN CLASSIFICATION | AM32: TERM | AT32: RELEASE OF LOAN PROCEEDS
B33: =DATE(YEAR(E$24),MONTH(E$24)+D33+0,DAY(E$24)) -> 45882 | C33: =TEXT(B33,"mmm-yyyy") -> Aug-2025 | D33: 6 | E33: =C$1 -> 5610.0156 | F33: =E33-G33 -> 3321.3562 | G33: =H32*C$12 -> 2288.6595 | H33: =H32-F33 -> 130888.75 | K33: Serial No.: | N33: =D23 -> 2004-023 | Y33: New | AF33: Salary Loan | AN33: 12 Months | AU33: Check
B34: =DATE(YEAR(E$24),MONTH(E$24)+D34+0,DAY(E$24)) -> 45913 | C34: =TEXT(B34,"mmm-yyyy") -> Sep-2025 | D34: 7 | E34: =C$1 -> 5610.0156 | F34: =E34-G34 -> 3377.9946 | G34: =H33*C$12 -> 2232.021 | H34: =H33-F34 -> 127510.76 | K34: Address: | N34: =F23 -> BLK 1 LOT 8 JOSHUA ST., BEYOND HOMES BRGY SAN FRANCISCO, GENERAL TRIAS, CAVITE | Y34: Renewal | AF34: Pension Loan | AN34: 24 Months | AU34: Bank Electronic Transfer to Borrowers Account
B35: =DATE(YEAR(E$24),MONTH(E$24)+D35+0,DAY(E$24)) -> 45943 | C35: =TEXT(B35,"mmm-yyyy") -> Oct-2025 | D35: 8 | E35: =C$1 -> 5610.0156 | F35: =E35-G35 -> 3435.5989 | G35: =H34*C$12 -> 2174.4167 | H35: =H34-F35 -> 124075.16 | Y35: Additional | AF35: Emergency | AN35: 36 Months | AU35: Others:
B36: =DATE(YEAR(E$24),MONTH(E$24)+D36+0,DAY(E$24)) -> 45974 | C36: =TEXT(B36,"mmm-yyyy") -> Nov-2025 | D36: 9 | E36: =C$1 -> 5610.0156 | F36: =E36-G36 -> 3494.1855 | G36: =H35*C$12 -> 2115.8301 | H36: =H35-F36 -> 120580.97 | L36: Principal Amount | R36: =C4 -> 178237.5 | Y36: Reloan | AF36: Health Assistance Loan | AN36: 48 Months
B37: =DATE(YEAR(E$24),MONTH(E$24)+D37+0,DAY(E$24)) -> 46004 | C37: =TEXT(B37,"mmm-yyyy") -> Dec-2025 | D37: 10 | E37: =C$1 -> 5610.0156 | F37: =E37-G37 -> 3553.7712 | G37: =H36*C$12 -> 2056.2444 | H37: =H36-F37 -> 117027.2 | Y37: Restructure | AF37: Educational Loan | AN37: 60 Months
B38: =DATE(YEAR(E$24),MONTH(E$24)+D38+0,DAY(E$24)) -> 46035 | C38: =TEXT(B38,"mmm-yyyy") -> Jan-2026 | D38: 11 | E38: =C$1 -> 5610.0156 | F38: =E38-G38 -> 3614.373 | G38: =H37*C$12 -> 1995.6427 | H38: =H37-F38 -> 113412.83 | L38: (-) | M38: Balance Old Loan(s) | R38: =-C14 -> 0 | AF38: Others: | AN38: Others:
B39: =DATE(YEAR(E$24),MONTH(E$24)+D39+0,DAY(E$24)) -> 46066 | C39: =TEXT(B39,"mmm-yyyy") -> Feb-2026 | D39: 12 | E39: =C$1 -> 5610.0156 | F39: =E39-G39 -> 3676.0082 | G39: =H38*C$12 -> 1934.0074 | H39: =H38-F39 -> 109736.82 | L39: (-) | M39: Membership Fee: | R39: =-C8 -> -300 | X39: AMOUNT APPLIED: | AB39: ='[2]Data Entry'!E4 -> 150000 | AN39: MONTHLY AMORTIZATION: | AT39: =R49 -> 5610.0156
B40: =DATE(YEAR(E$24),MONTH(E$24)+D40+0,DAY(E$24)) -> 46094 | C40: =TEXT(B40,"mmm-yyyy") -> Mar-2026 | D40: 13 | E40: =C$1 -> 5610.0156 | F40: =E40-G40 -> 3738.6945 | G40: =H39*C$12 -> 1871.3212 | H40: =H39-F40 -> 105998.13 | L40: (-) | M40: Paid up Capital: | R40: =-C7 -> -5000
B41: =DATE(YEAR(E$24),MONTH(E$24)+D41+0,DAY(E$24)) -> 46125 | C41: =TEXT(B41,"mmm-yyyy") -> Apr-2026 | D41: 14 | E41: =C$1 -> 5610.0156 | F41: =E41-G41 -> 3802.4497 | G41: =H40*C$12 -> 1807.5659 | H41: =H40-F41 -> 102195.68 | L41: (-) | M41: Service Fee | R41: =-C5 -> -16500 | X41: LOAN ID: | AF41: DEDUCTION CODE: | AR41: LOAN PURPOSE:
B42: =DATE(YEAR(E$24),MONTH(E$24)+D42+0,DAY(E$24)) -> 46155 | C42: =TEXT(B42,"mmm-yyyy") -> May-2026 | D42: 15 | E42: =C$1 -> 5610.0156 | F42: =E42-G42 -> 3867.2922 | G42: =H41*C$12 -> 1742.7235 | H42: =H41-F42 -> 98328.386 | L42: (-) | M42: Insurance Premium - Paramount | R42: =-C6 -> -5400 | X42: MEM ID: | AG42: Regular Member | AS42: Old Member
B43: =DATE(YEAR(E$24),MONTH(E$24)+D43+0,DAY(E$24)) -> 46186 | C43: =TEXT(B43,"mmm-yyyy") -> Jun-2026 | D43: 16 | E43: =C$1 -> 5610.0156 | F43: =E43-G43 -> 3933.2404 | G43: =H42*C$12 -> 1676.7753 | H43: =H42-F43 -> 94395.146 | L43: (-) | M43: Advance Interest | R43: =-C9 -> -1037.5 | AG43: Associate Member | AS43: New Member
B44: =DATE(YEAR(E$24),MONTH(E$24)+D44+0,DAY(E$24)) -> 46216 | C44: =TEXT(B44,"mmm-yyyy") -> Jul-2026 | D44: 17 | E44: =C$1 -> 5610.0156 | F44: =E44-G44 -> 4000.3132 | G44: =H43*C$12 -> 1609.7025 | H44: =H43-F44 -> 90394.832 | L44: NET PROCEEDS (Php): | R44: =SUM(R36:T43) -> 150000 | X44: BORROWER'S INFORMATION
B45: =DATE(YEAR(E$24),MONTH(E$24)+D45+0,DAY(E$24)) -> 46247 | C45: =TEXT(B45,"mmm-yyyy") -> Aug-2026 | D45: 18 | E45: =C$1 -> 5610.0156 | F45: =E45-G45 -> 4068.5298 | G45: =H44*C$12 -> 1541.4859 | H45: =H44-F45 -> 86326.303 | X45: MARQUEZ | AD45: MADONNA LYN | AN45: ORTEGA
...
