Workbook

Sheet DATA ENTRY
B1: Editable
C3: 1 Yr | D3: 2 Yrs | E3: 3 Yrs | F3: 4 Yrs | G3: 5 Yrs | L3: 5 Yrs
B4: GROSS AMOUNT | C4: ='Computation Table'!C108 -> 29373.41 | D4: ='Computation Table'!C82 -> 22799.949 | E4: ='Computation Table'!C56 -> 31566.88 | F4: ='Computation Table'!C29 -> 40936.742 | G4: ='Computation Table'!C3 -> 92480.964 | K4: GROSS AMOUNT | L4: =G4 -> 92480.964
B5: NET PROCEEDS | C5: 25000 | D5: 15979.6 | E5: 25000 | F5: 25000 | G5: 37000 | K5: NET PROCEEDS | L5: 1000000
B6: Add: | K6: Add:
B7: Previous Loan Balance | K7: Previous Loan Balance
B8: Service Fee | C8: ='Computation Table'!C110 -> 1750 | D8: ='Computation Table'!C84 -> 1198.47 | E8: ='Computation Table'!E58 -> 2000 | F8: ='Computation Table'!C31 -> 2550 | G8: ='Computation Table'!C5 -> 4477 | K8: Service Fee | L8: =G8 -> 4477
B9: Insurance | C9: ='Computation Table'!C111 -> 300 | D9: ='Computation Table'!C85 -> 383.5104 | E9: ='Computation Table'!C59 -> 900 | F9: ='Computation Table'!C32 -> 1200 | G9: ='Computation Table'!C6 -> 2220 | K9: Insurance | L9: =G9 -> 2220
B10: CapCon | D10: 2000 | F10: 5000 | G10: 30000 | K10: CapCon | L10: 30000
B11: membership fee | D11: 300 | F11: 300 | K11: membership fee
B12: Advance Interest | C12: ='Computation Table'!C114 -> 500 | D12: ='Computation Table'!C88 -> 319.592 | E12: ='Computation Table'!C62 -> 500 | F12: ='Computation Table'!C35 -> 365.83333 | G12: ='Computation Table'!C9 -> 555 | K12: Advance Interest | L12: =G12 -> 555
B13: LOAN AMOUNT | C13: =SUM(C5:C11) -> 27050 | D13: =SUM(D5:D12) -> 20181.172 | E13: =SUM(E5:E12) -> 28400 | F13: =SUM(F5:F12) -> 34415.833 | G13: =SUM(G5:G12) -> 74252 | K13: LOAN AMOUNT | L13: =SUM(L5:L12) -> 1037252
B14: Annual Interest Rate | C14: ='Computation Table'!C116 -> 0.12 | D14: ='Computation Table'!C90 -> 0.12 | E14: ='Computation Table'!C64 -> 0.12 | F14: ='Computation Table'!C37 -> 0.0878 | G14: ='Computation Table'!C11 -> 0.09 | K14: Annual Interest Rate | L14: ='Computation Table'!H11 -> 0.09
B15: Effective Interest Rate | C15: ='Computation Table'!C117 -> 0.12682503 | D15: ='Computation Table'!F91 -> 0.12715978 | E15: ='Computation Table'!F65 -> 0.12727187 | F15: ='Computation Table'!C38 -> 0.091682187 | G15: ='Computation Table'!C12 -> 0.094100503 | K15: Effective Interest Rate | L15: ='Computation Table'!H12 -> 0.094100503
B16: Monthly Amortization | C16: ='Computation Table'!C126 -> 2447.7841 | D16: ='Computation Table'!C100 -> 949.99786 | E16: ='Computation Table'!C74 -> 876.85778 | F16: ='Computation Table'!C47 -> 852.84879 | G16: ='Computation Table'!C21 -> 1541.3494 | K16: Monthly Amortization | L16: =G16 -> 1541.3494

Sheet DEL ROSARIO
B1: Amortization | C1: ='DATA ENTRY'!G16 -> 1541.3494
B2: Timeline | C2: 0 | D2: 1 | E2: 2 | F2: 3 | G2: 4 | H2: 5 | I2: 6 | J2: 7 | K2: 8 | L2: 9 | M2: 10 | N2: 11 | O2: 12 | P2: 13 | Q2: 14 | R2: 15 | S2: 16 | T2: 17 | U2: 18 | V2: 19 | W2: 20 | X2: 21 | Y2: 22 | Z2: 23 | AA2: 24 | AB2: 25 | AC2: 26 | AD2: 27 | AE2: 28 | AF2: 29 | AG2: 30 | AH2: 31 | AI2: 32 | AJ2: 33 | AK2: 34 | AL2: 35 | AM2: 36 | AN2: 37 | AO2: 38 | AP2: 39 | AQ2: 40 | AR2: 41 | AS2: 42 | AT2: 43 | AU2: 44 | AV2: 45 | AW2: 46 | AX2: 47 | AY2: 48 | AZ2: 49 | BA2: 50 | BB2: 51 | BC2: 52 | BD2: 53 | BE2: 54 | BF2: 55 | BG2: 56 | BH2: 57 | BI2: 58 | BJ2: 59 | BK2: 60
B3: GROSS AMOUNT | C3: ='DATA ENTRY'!G4 -> 92480.964
B4: LOAN AMOUNT | C4: ='DATA ENTRY'!G13 -> 74252 | D4: -25449.744 | E4: -25449.744 | F4: -25449.744 | G4: -25449.744 | H4: -25449.744 | I4: -25449.744 | J4: -25449.744 | K4: -25449.744 | L4: -25449.744 | M4: -25449.744 | N4: -25449.744 | O4: -25449.744 | P4: -25449.744 | Q4: -25449.744 | R4: -25449.744 | S4: -25449.744 | T4: -25449.744 | U4: -25449.744 | V4: -25449.744 | W4: -25449.744 | X4: -25449.744 | Y4: -25449.744 | Z4: -25449.744 | AA4: -25449.744 | AB4: -25449.744 | AC4: -25449.744 | AD4: -25449.744 | AE4: -25449.744 | AF4: -25449.744 | AG4: -25449.744 | AH4: -25449.744 | AI4: -25449.744 | AJ4: -25449.744 | AK4: -25449.744 | AL4: -25449.744 | AM4: -25449.744 | AN4: -25449.744 | AO4: -25449.744 | AP4: -25449.744 | AQ4: -25449.744 | AR4: -25449.744 | AS4: -25449.744 | AT4: -25449.744 | AU4: -25449.744 | AV4: -25449.744 | AW4: -25449.744 | AX4: -25449.744 | AY4: -25449.744 | AZ4: -25449.744 | BA4: -25449.744 | BB4: -25449.744 | BC4: -25449.744 | BD4: -25449.744 | BE4: -25449.744 | BF4: -25449.744 | BG4: -25449.744 | BH4: -25449.744 | BI4: -25449.744 | BJ4: -25449.744 | BK4: -25449.744
B5: Service Fee | C5: ='DATA ENTRY'!G8 -> 4477
B6: Insurance | C6: ='DATA ENTRY'!G9 -> 2220
B7: CapCon | C7: ='DATA ENTRY'!G10 -> 30000
B8: membership fee | C8: ='DATA ENTRY'!G11 -> 0
B9: Advance Interest | C9: ='DATA ENTRY'!G12 -> 555
B10: NET PROCEEDS/CASH FLOW | C10: =C4-C5-C6-C7-C8-C9 -> 37000 | D10: =-$C1 -> -1541.3494 | E10: =-$C1 -> -1541.3494 | F10: =-$C1 -> -1541.3494 | G10: =-$C1 -> -1541.3494 | H10: =-$C1 -> -1541.3494 | I10: =-$C1 -> -1541.3494 | J10: =-$C1 -> -1541.3494 | K10: =-$C1 -> -1541.3494 | ... BK10: =-$C1 -> -1541.3494
B12: Interest Rate of Return | C12: =IRR(C4:BK4) -> 0.34274825
B14: Loan Balance
B15: Monthly Interest Rate | C15: ='DATA ENTRY'!G14 -> 0.09
B16: Effective Interest Rate | C16: ='DATA ENTRY'!G15 -> 0.094100503
C20: LOAN LEDGER CARD
C22: Name: | D22: Del Rosario, Isagani Sioson | G22: Loan Voucher No.
C23: Serial Nr: | D23: O-13567 | E23: Address: | F23: Blk 16 Lot 15 City Homes Subd. Alibagu, Ilagan Isabela | G23: Amount: | H23: =C3 -> 92480.964
C24: Posting date | D24: Date of Loan: | E24: 45847 | F24: Maturity Date | G24: =B87 -> 47704 | K24: PEOPLE'S MULTI-PURPOSE COOPERATIVE
D25: Term: | E25: 60 | F25: MOS | K25: 20-E 2nd Camarilla St. corner 15th Ave., Brgy. San Roque, Murphy Cubao, Quezon City
D26: Loan | E26: Installment | F26: Principal | G26: EIR | H26: Balance
D27: Month 0 | H27: =C4 -> 74252 | K27: LOAN RELEASE VOUCHER
B28: =DATE(YEAR(E$24),MONTH(E$24)+D28+1,DAY(E$24)) -> 45909 | C28: =TEXT(B28,"mmm-yyyy") -> Sep-2025 | D28: 1 | E28: =C$1 -> 1541.3494 | F28: =E28-G28 -> -23908.394 | G28: =H27*C$12 -> 25449.743 | H28: =H27-F28 -> 98160.394
B29: =DATE(YEAR(E$24),MONTH(E$24)+D29+1,DAY(E$24)) -> 45939 | C29: =TEXT(B29,"mmm-yyyy") -> Oct-2025 | D29: 2 | E29: =C$1 -> 1541.3494 | F29: =E29-G29 -> -32102.954 | G29: =H28*C$12 -> 33644.303 | H29: =H28-F29 -> 130263.35 | R29: Date: | S29: =E24 -> 45847
B30: =DATE(YEAR(E$24),MONTH(E$24)+D30+1,DAY(E$24)) -> 45970 | C30: =TEXT(B30,"mmm-yyyy") -> Nov-2025 | D30: 3 | E30: =C$1 -> 1541.3494 | F30: =E30-G30 -> -43106.185 | G30: =H29*C$12 -> 44647.534 | H30: =H29-F30 -> 173369.53 | R30: LV No: | S30: 0001
B31: =DATE(YEAR(E$24),MONTH(E$24)+D31+1,DAY(E$24)) -> 46000 | C31: =TEXT(B31,"mmm-yyyy") -> Dec-2025 | D31: 4 | E31: =C$1 -> 1541.3494 | F31: =E31-G31 -> -57880.754 | G31: =H30*C$12 -> 59422.103 | H31: =H30-F31 -> 231250.29
B32: =DATE(YEAR(E$24),MONTH(E$24)+D32+1,DAY(E$24)) -> 46031 | C32: =TEXT(B32,"mmm-yyyy") -> Jan-2026 | D32: 5 | E32: =C$1 -> 1541.3494 | F32: =E32-G32 -> -77719.281 | G32: =H31*C$12 -> 79260.631 | H32: =H31-F32 -> 308969.57 | K32: Name of Borrower: | N32: =D22 -> Del Rosario, Isagani Sioson
B33: =DATE(YEAR(E$24),MONTH(E$24)+D33+1,DAY(E$24)) -> 46062 | C33: =TEXT(B33,"mmm-yyyy") -> Feb-2026 | D33: 6 | E33: =C$1 -> 1541.3494 | F33: =E33-G33 -> -104357.43 | G33: =H32*C$12 -> 105898.78 | H33: =H32-F33 -> 413327 | K33: Serial No.: | N33: =D23 -> O-13567
B34: =DATE(YEAR(E$24),MONTH(E$24)+D34+1,DAY(E$24)) -> 46090 | C34: =TEXT(B34,"mmm-yyyy") -> Mar-2026 | D34: 7 | E34: =C$1 -> 1541.3494 | F34: =E34-G34 -> -140125.75 | G34: =H33*C$12 -> 141667.1 | H34: =H33-F34 -> 553452.75 | K34: Address: | N34: =F23 -> Blk 16 Lot 15 City Homes Subd. Alibagu, Ilagan Isabela
B35: =DATE(YEAR(E$24),MONTH(E$24)+D35+1,DAY(E$24)) -> 46121 | C35: =TEXT(B35,"mmm-yyyy") -> Apr-2026 | D35: 8 | E35: =C$1 -> 1541.3494 | F35: =E35-G35 -> -188153.61 | G35: =H34*C$12 -> 189694.96 | H35: =H34-F35 -> 741606.36
B36: =DATE(YEAR(E$24),MONTH(E$24)+D36+1,DAY(E$24)) -> 46151 | C36: =TEXT(B36,"mmm-yyyy") -> May-2026 | D36: 9 | E36: =C$1 -> 1541.3494 | F36: =E36-G36 -> -252642.93 | G36: =H35*C$12 -> 254184.28 | H36: =H35-F36 -> 994249.3 | L36: Principal Amount | R36: =C4 -> 74252
B37: =DATE(YEAR(E$24),MONTH(E$24)+D37+1,DAY(E$24)) -> 46182 | C37: =TEXT(B37,"mmm-yyyy") -> Jun-2026 | D37: 10 | E37: =C$1 -> 1541.3494 | F37: =E37-G37 -> -339235.86 | G37: =H36*C$12 -> 340777.2 | H37: =H36-F37 -> 1333485.2
B38: =DATE(YEAR(E$24),MONTH(E$24)+D38+1,DAY(E$24)) -> 46212 | C38: =TEXT(B38,"mmm-yyyy") -> Jul-2026 | D38: 11 | E38: =C$1 -> 1541.3494 | F38: =E38-G38 -> -455508.35 | G38: =H37*C$12 -> 457049.7 | H38: =H37-F38 -> 1788993.5 | L38: (-) | M38: Balance Old Loan(s) | R38: =-C14 -> 0
B39: =DATE(YEAR(E$24),MONTH(E$24)+D39+1,DAY(E$24)) -> 46243 | C39: =TEXT(B39,"mmm-yyyy") -> Aug-2026 | D39: 12 | E39: =C$1 -> 1541.3494 | F39: =E39-G39 -> -611633.04 | G39: =H38*C$12 -> 613174.39 | H39: =H38-F39 -> 2400626.5 | L39: (-) | M39: Membership Fee: | R39: =-C8 -> 0
B40: =DATE(YEAR(E$24),MONTH(E$24)+D40+1,DAY(E$24)) -> 46274 | C40: =TEXT(B40,"mmm-yyyy") -> Sep-2026 | D40: 13 | E40: =C$1 -> 1541.3494 | F40: =E40-G40 -> -821269.19 | G40: =H39*C$12 -> 822810.54 | H40: =H39-F40 -> 3221895.7 | L40: (-) | M40: Paid up Capital: | R40: =-C7 -> -30000
B41: =DATE(YEAR(E$24),MONTH(E$24)+D41+1,DAY(E$24)) -> 46304 | C41: =TEXT(B41,"mmm-yyyy") -> Oct-2026 | D41: 14 | E41: =C$1 -> 1541.3494 | F41: =E41-G41 -> -1102757.8 | G41: =H40*C$12 -> 1104299.1 | H41: =H40-F41 -> 4324653.5 | L41: (-) | M41: Service Fee | R41: =-C5 -> -4477
B42: =DATE(YEAR(E$24),MONTH(E$24)+D42+1,DAY(E$24)) -> 46335 | C42: =TEXT(B42,"mmm-yyyy") -> Nov-2026 | D42: 15 | E42: =C$1 -> 1541.3494 | F42: =E42-G42 -> -1480726.1 | G42: =H41*C$12 -> 1482267.4 | H42: =H41-F42 -> 5805379.6 | L42: (-) | M42: Insurance Premium - Paramount | R42: =-C6 -> -2220
B43: =DATE(YEAR(E$24),MONTH(E$24)+D43+1,DAY(E$24)) -> 46365 | C43: =TEXT(B43,"mmm-yyyy") -> Dec-2026 | D43: 16 | E43: =C$1 -> 1541.3494 | F43: =E43-G43 -> -1988242.3 | G43: =H42*C$12 -> 1989783.7 | H43: =H42-F43 -> 7793621.9 | L43: (-) | M43: Advance Interest | R43: =-C9 -> -555
B44: =DATE(YEAR(E$24),MONTH(E$24)+D44+1,DAY(E$24)) -> 46396 | C44: =TEXT(B44,"mmm-yyyy") -> Jan-2027 | D44: 17 | E44: =C$1 -> 1541.3494 | F44: =E44-G44 -> -2669708.9 | G44: =H43*C$12 -> 2671250.3 | H44: =H43-F44 -> 10463331 | L44: NET PROCEEDS (Php): | R44: =SUM(R36:T43) -> 37000
B45: =DATE(YEAR(E$24),MONTH(E$24)+D45+1,DAY(E$24)) -> 46427 | C45: =TEXT(B45,"mmm-yyyy") -> Feb-2027 | D45: 18 | E45: =C$1 -> 1541.3494 | F45: =E45-G45 -> -3584747 | G45: =H44*C$12 -> 3586288.3 | H45: =H44-F45 -> 14048078
B46: =DATE(YEAR(E$24),MONTH(E$24)+D46+1,DAY(E$24)) -> 46455 | C46: =TEXT(B46,"mmm-yyyy") -> Mar-2027 | D46: 19 | E46: =C$1 -> 1541.3494 | F46: =E46-G46 -> -4813412.7 | G46: =H45*C$12 -> 4814954.1 | H46: =H45-F46 -> 18861491 | K46: PAYMENT
...

Sheet Amortization  Table
B1: PEOPLE'S MULTI-PURPOSE COOPERATIVE EFFECTIVE ON JANUARY 16, 2025
B4: PENSIONERS LOAN TABLE
B5: Net Proceeds | C5: 1 Yr 12 Months | D5: 2 Yrs 24 Months | E5: 3 Yrs 36 Months | F5: 4 Yrs 48 Months | G5: 5 Yrs 60 Months
B7: 25000 | C7: ='Computation Table'!E126 -> 2918.6827 | D7: ='Computation Table'!E100 -> 1566.3698 | E7: ='Computation Table'!E74 -> 1119.3222 | F7: ='Computation Table'!E47 -> 852.84879 | G7: ='Computation Table'!E21 -> 730.6941
B8: 50000 | C8: ='Computation Table'!F126 -> 5366.4668 | D8: ='Computation Table'!F100 -> 2883.2502 | E8: ='Computation Table'!F74 -> 2054.3051 | F8: ='Computation Table'!F47 -> 1574.3598 | G8: ='Computation Table'!F21 -> 1351.3689
B9: 75000 | C9: ='Computation Table'!G126 -> 7814.251 | D9: ='Computation Table'!G100 -> 4200.1306 | E9: ='Computation Table'!G74 -> 2993.4397 | F9: ='Computation Table'!G47 -> 2295.8708 | G9: ='Computation Table'!G21 -> 1972.0437
B10: 100000 | C10: ='Computation Table'!H126 -> 10262.035 | D10: ='Computation Table'!H100 -> 5517.0109 | E10: ='Computation Table'!H74 -> 3932.5743 | F10: ='Computation Table'!H47 -> 3017.3819 | G10: ='Computation Table'!H21 -> 2592.7186
B11: 150000 | C11: ='Computation Table'!J126 -> 15157.603 | D11: ='Computation Table'!J100 -> 8150.7717 | E11: ='Computation Table'!J74 -> 5810.8435 | F11: ='Computation Table'!J47 -> 4460.4039 | G11: ='Computation Table'!J21 -> 3834.0682
B12: 200000 | C12: ='Computation Table'!L126 -> 20053.172 | D12: ='Computation Table'!L100 -> 10784.532 | E12: ='Computation Table'!L74 -> 7689.1127 | F12: ='Computation Table'!L47 -> 5903.426 | G12: ='Computation Table'!L21 -> 5075.4179
B13: 250000 | C13: ='Computation Table'!N126 -> 24948.74 | D13: ='Computation Table'!N100 -> 13418.293 | E13: ='Computation Table'!N74 -> 9567.3819 | F13: ='Computation Table'!N47 -> 7346.448 | G13: ='Computation Table'!N21 -> 6316.7675
B14: 300000 | C14: ='Computation Table'!P126 -> 29844.308 | D14: ='Computation Table'!P100 -> 16052.054 | E14: ='Computation Table'!P74 -> 11445.651 | F14: ='Computation Table'!P47 -> 8789.4701 | G14: ='Computation Table'!P21 -> 7558.1171
B15: 350000 | C15: ='Computation Table'!R126 -> 34739.876 | D15: ='Computation Table'!R100 -> 18685.815 | E15: ='Computation Table'!R74 -> 13323.92 | F15: ='Computation Table'!R47 -> 10232.492 | G15: ='Computation Table'!R21 -> 8799.4668
B16: 400000 | C16: ='Computation Table'!T126 -> 39635.445 | D16: ='Computation Table'!T100 -> 21319.576 | E16: ='Computation Table'!T74 -> 15202.19 | F16: ='Computation Table'!T47 -> 11675.514 | G16: ='Computation Table'!T21 -> 10040.816
B17: 450000 | C17: ='Computation Table'!V126 -> 44531.013 | D17: ='Computation Table'!V100 -> 23953.336 | E17: ='Computation Table'!V74 -> 17080.459 | F17: ='Computation Table'!V47 -> 13118.536 | G17: ='Computation Table'!V21 -> 11282.166
B18: 500000 | C18: ='Computation Table'!X126 -> 49426.581 | D18: ='Computation Table'!X100 -> 26587.097 | E18: ='Computation Table'!X74 -> 18958.728 | F18: ='Computation Table'!X47 -> 14561.558 | G18: ='Computation Table'!X21 -> 12409.345
B19: 550000 | C19: ='Computation Table'!Z126 -> 54322.149 | D19: ='Computation Table'!Z100 -> 29220.858 | E19: ='Computation Table'!Z74 -> 20836.997 | F19: ='Computation Table'!Z47 -> 16004.58 | G19: ='Computation Table'!Z21 -> 13764.865
B20: 600000 | C20: ='Computation Table'!AB126 -> 59217.718 | D20: ='Computation Table'!AB100 -> 31854.619 | E20: ='Computation Table'!AB74 -> 22715.266 | F20: ='Computation Table'!AB47 -> 17447.602 | G20: ='Computation Table'!AB21 -> 15006.215
B21: 650000 | C21: ='Computation Table'!AD126 -> 64113.286 | D21: ='Computation Table'!AD100 -> 34488.379 | E21: ='Computation Table'!AD74 -> 24593.536 | F21: ='Computation Table'!AD47 -> 18890.624 | G21: ='Computation Table'!AD21 -> 16247.565
B22: 700000 | C22: ='Computation Table'!AF126 -> 69008.854 | D22: ='Computation Table'!AF100 -> 37122.14 | E22: ='Computation Table'!AF74 -> 26471.805 | F22: ='Computation Table'!AF47 -> 20333.646 | G22: ='Computation Table'!AF21 -> 17488.914
B23: 750000 | C23: ='Computation Table'!AH126 -> 73904.422 | D23: ='Computation Table'!AH100 -> 39755.901 | E23: ='Computation Table'!AH74 -> 28350.074 | F23: ='Computation Table'!AH47 -> 21776.668 | G23: ='Computation Table'!AH21 -> 18730.264
B24: 800000 | C24: ='Computation Table'!AJ126 -> 78799.991 | D24: ='Computation Table'!AJ100 -> 42389.662 | E24: ='Computation Table'!AJ74 -> 30228.343 | F24: ='Computation Table'!AJ47 -> 23219.691 | G24: ='Computation Table'!AJ21 -> 19971.614
B25: 850000 | C25: ='Computation Table'!AL126 -> 83695.559 | D25: ='Computation Table'!AL100 -> 45023.423 | E25: ='Computation Table'!AL74 -> 32106.613 | F25: ='Computation Table'!AL47 -> 24662.713 | G25: ='Computation Table'!AL21 -> 21212.963
B26: 900000 | C26: ='Computation Table'!AN126 -> 88591.127 | D26: ='Computation Table'!AN100 -> 47657.183 | E26: ='Computation Table'!AN74 -> 33984.882 | F26: ='Computation Table'!AN47 -> 26105.735 | G26: ='Computation Table'!AN21 -> 22454.313
B27: 950000 | C27: ='Computation Table'!AP126 -> 93486.695 | D27: ='Computation Table'!AP100 -> 50290.944 | E27: ='Computation Table'!AP74 -> 35863.151 | F27: ='Computation Table'!AP47 -> 27548.757 | G27: ='Computation Table'!AP21 -> 23695.662
B28: 1000000 | C28: ='Computation Table'!AR126 -> 98382.264 | D28: ='Computation Table'!AR100 -> 52924.705 | E28: ='Computation Table'!AR74 -> 37741.42 | F28: ='Computation Table'!AR47 -> 28991.779 | G28: ='Computation Table'!AR21 -> 24708.67

Sheet Computation Table
B2: 5 Yrs
B3: GROSS | C3: =C21*C15 -> 92480.964 | E3: =E21*E15 -> 43841.646 | F3: =F21*F15 -> 81082.136 | G3: =G21*G15 -> 118322.62 | H3: =H21*H15 -> 155563.11 | I3: =I21*I15 -> 192803.6 | J3: =J21*J15 -> 230044.09 | K3: =K21*K15 -> 267284.58 | L3: =L21*L15 -> 304525.07 | ... AR3: =AR21*AR15 -> 1482520.2
B4: NET | C4: ='DATA ENTRY'!G5 -> 37000 | E4: 25000 | F4: 50000 | G4: 75000 | H4: 100000 | I4: 125000 | J4: 150000 | K4: 175000 | L4: 200000 | M4: 225000 | N4: 250000 | O4: 275000 | P4: 300000 | Q4: 325000 | R4: 350000 | S4: 375000 | T4: 400000 | U4: 425000 | V4: 450000 | W4: 475000 | X4: 500000 | Y4: 525000 | Z4: 550000 | AA4: 575000 | AB4: 600000 | AC4: 625000 | AD4: 650000 | AE4: 675000 | AF4: 700000 | AG4: 725000 | AH4: 750000 | AI4: 775000 | AJ4: 800000 | AK4: 825000 | AL4: 850000 | AM4: 875000 | AN4: 900000 | AO4: 925000 | AP4: 950000 | AQ4: 975000 | AR4: 1000000
B5: SF | C5: =C4*0.121 -> 4477 | E5: =E4*0.121 -> 3025 | F5: =F4*0.121 -> 6050 | G5: =G4*0.121 -> 9075 | H5: =H4*0.121 -> 12100 | I5: =I4*0.121 -> 15125 | J5: =J4*0.121 -> 18150 | K5: =K4*0.121 -> 21175 | L5: =L4*0.121 -> 24200 | ... W5: =W4*0.121 -> 57475 | X5: =X4*0.11 -> 55000 | Y5: =Y4*0.121 -> 63525 | Z5: =Z4*0.121 -> 66550 | AA5: =AA4*0.121 -> 69575 | AB5: =AB4*0.121 -> 72600 | AC5: =AC4*0.121 -> 75625 | AD5: =AD4*0.121 -> 78650 | AE5: =AE4*0.121 -> 81675 | AF5: =AF4*0.121 -> 84700 | ... AQ5: =AQ4*0.121 -> 117975 | AR5: =AR4*0.11 -> 110000
B6: Insurance | C6: =(C4/1000)*C15 -> 2220 | E6: =(E4/1000)*E15 -> 1500 | F6: =(F4/1000)*F15 -> 3000 | G6: =(G4/1000)*G15 -> 4500 | H6: =(H4/1000)*H15 -> 6000 | I6: =(I4/1000)*I15 -> 7500 | J6: =(J4/1000)*J15 -> 9000 | K6: =(K4/1000)*K15 -> 10500 | L6: =(L4/1000)*L15 -> 12000 | ... AR6: =(AR4/1000)*AR15 -> 60000
B7: CapCon | C7: ='DATA ENTRY'!G10 -> 30000 | E7: 5000 | F7: 5000 | G7: 5000 | H7: 5000 | I7: 5000 | J7: 5000 | K7: 5000 | L7: 5000 | M7: 5000 | N7: 5000 | O7: 5000 | P7: 5000 | Q7: =O7 -> 5000 | R7: =P7 -> 5000 | S7: =Q7 -> 5000 | T7: =R7 -> 5000 | U7: =S7 -> 5000 | V7: =T7 -> 5000 | W7: =U7 -> 5000 | X7: =V7 -> 5000 | ... AR7: =AP7 -> 5000
B8: membership fee | C8: ='DATA ENTRY'!G11 -> 0 | E8: 300 | F8: 300 | G8: 300 | H8: 300 | I8: 300 | J8: 300 | K8: 300 | L8: 300 | M8: 300 | N8: 300 | O8: 300 | P8: 300 | Q8: =O8 -> 300 | R8: =P8 -> 300 | S8: =Q8 -> 300 | T8: =R8 -> 300 | U8: =S8 -> 300 | V8: =T8 -> 300 | W8: =U8 -> 300 | X8: =V8 -> 300 | ... AR8: =AP8 -> 300
B9: Advance Interest | C9: =C14*C4*2 -> 555 | E9: =E14*E4*2 -> 375 | F9: =F14*F4*2 -> 750 | G9: =G14*G4*2 -> 1125 | H9: =H14*H4*2 -> 1500 | I9: =I14*I4*2 -> 1875 | J9: =J14*J4*2 -> 2250 | K9: =K14*K4*2 -> 2625 | L9: =L14*L4*2 -> 3000 | ... AR9: =AR14*AR4*2 -> 15000
B10: LOAN AMOUNT | C10: =SUM(C4:C9) -> 74252 | E10: =SUM(E4:E9) -> 35200 | F10: =SUM(F4:F9) -> 65100 | G10: =SUM(G4:G9) -> 95000 | H10: =SUM(H4:H9) -> 124900 | I10: =SUM(I4:I9) -> 154800 | J10: =SUM(J4:J9) -> 184700 | K10: =SUM(K4:K9) -> 214600 | L10: =SUM(L4:L9) -> 244500 | ... AR10: =SUM(AR4:AR9) -> 1190300
B11: Annual Interest | C11: 0.09 | E11: =C11 -> 0.09 | F11: =C11 -> 0.09 | G11: =F11 -> 0.09 | H11: =G11 -> 0.09 | I11: =H11 -> 0.09 | J11: =I11 -> 0.09 | K11: =J11 -> 0.09 | L11: =K11 -> 0.09 | M11: =L11 -> 0.09 | N11: =M11 -> 0.09 | ... W11: =V11 -> 0.09 | X11: 0.09 | Y11: =W11 -> 0.09 | Z11: =Y11 -> 0.09 | AA11: =Z11 -> 0.09 | AB11: =AA11 -> 0.09 | AC11: =AB11 -> 0.09 | AD11: =AC11 -> 0.09 | AE11: =AD11 -> 0.09 | AF11: =AE11 -> 0.09 | AG11: =AF11 -> 0.09 | ... AQ11: =AP11 -> 0.09 | AR11: 0.09
B12: Effective Interest rate | C12: =(1+C11/C15)^C15-1 -> 0.094100503 | E12: =(1+E11/E15)^E15-1 -> 0.094100503 | F12: =(1+F11/F15)^F15-1 -> 0.094100503 | G12: =(1+G11/G15)^G15-1 -> 0.094100503 | H12: =(1+H11/H15)^H15-1 -> 0.094100503 | I12: =(1+I11/I15)^I15-1 -> 0.094100503 | J12: =(1+J11/J15)^J15-1 -> 0.094100503 | K12: =(1+K11/K15)^K15-1 -> 0.094100503 | L12: =(1+L11/L15)^L15-1 -> 0.094100503 | ... AR12: =(1+AR11/AR15)^AR15-1 -> 0.094100503
B13: Loan Term | C13: 5 | E13: 5 | F13: 5 | G13: 5 | H13: 5 | I13: 5 | J13: 5 | K13: 5 | L13: 5 | M13: 5 | N13: 5 | O13: 5 | P13: 5 | Q13: 5 | R13: 5 | S13: 5 | T13: =P13 -> 5 | U13: =Q13 -> 5 | V13: =R13 -> 5 | W13: =S13 -> 5 | X13: =T13 -> 5 | Y13: =U13 -> 5 | Z13: =V13 -> 5 | AA13: =W13 -> 5 | ... AR13: =AN13 -> 5
B14: Monthly Interest Rate | C14: =C11/12 -> 0.0075 | E14: =E11/12 -> 0.0075 | F14: =F11/12 -> 0.0075 | G14: =G11/12 -> 0.0075 | H14: =H11/12 -> 0.0075 | I14: =I11/12 -> 0.0075 | J14: =J11/12 -> 0.0075 | K14: =K11/12 -> 0.0075 | L14: =L11/12 -> 0.0075 | ... AR14: =AR11/12 -> 0.0075
B15: Nr of Payments | C15: =C13*12 -> 60 | E15: =E13*12 -> 60 | F15: =F13*12 -> 60 | G15: =G13*12 -> 60 | H15: =H13*12 -> 60 | I15: =I13*12 -> 60 | J15: =J13*12 -> 60 | K15: =K13*12 -> 60 | L15: =L13*12 -> 60 | ... AR15: =AR13*12 -> 60
B17: Monthly Amortization | C17: =(1+C14)^C15 -> 1.565681 | E17: =(1+E14)^E15 -> 1.565681 | F17: =(1+F14)^F15 -> 1.565681 | G17: =(1+G14)^G15 -> 1.565681 | H17: =(1+H14)^H15 -> 1.565681 | I17: =(1+I14)^I15 -> 1.565681 | J17: =(1+J14)^J15 -> 1.565681 | K17: =(1+K14)^K15 -> 1.565681 | L17: =(1+L14)^L15 -> 1.565681 | ... AR17: =(1+AR14)^AR15 -> 1.565681
C18: =C17*C14 -> 0.011742608 | E18: =E17*E14 -> 0.011742608 | F18: =F17*F14 -> 0.011742608 | G18: =G17*G14 -> 0.011742608 | H18: =H17*H14 -> 0.011742608 | I18: =I17*I14 -> 0.011742608 | J18: =J17*J14 -> 0.011742608 | K18: =K17*K14 -> 0.011742608 | L18: =L17*L14 -> 0.011742608 | ... AR18: =AR17*AR14 -> 0.011742608
C19: =C17-1 -> 0.56568103 | E19: =E17-1 -> 0.56568103 | F19: =F17-1 -> 0.56568103 | G19: =G17-1 -> 0.56568103 | H19: =H17-1 -> 0.56568103 | I19: =I17-1 -> 0.56568103 | J19: =J17-1 -> 0.56568103 | K19: =K17-1 -> 0.56568103 | L19: =L17-1 -> 0.56568103 | ... AR19: =AR17-1 -> 0.56568103
C20: =C18/C19 -> 0.020758355 | E20: =E18/E19 -> 0.020758355 | F20: =F18/F19 -> 0.020758355 | G20: =G18/G19 -> 0.020758355 | H20: =H18/H19 -> 0.020758355 | I20: =I18/I19 -> 0.020758355 | J20: =J18/J19 -> 0.020758355 | K20: =K18/K19 -> 0.020758355 | L20: =L18/L19 -> 0.020758355 | ... AR20: =AR18/AR19 -> 0.020758355
B21: Monthly Amortization | C21: =C20*C10 -> 1541.3494 | E21: =E20*E10 -> 730.6941 | F21: =F20*F10 -> 1351.3689 | G21: =G20*G10 -> 1972.0437 | H21: =H20*H10 -> 2592.7186 | I21: =I20*I10 -> 3213.3934 | J21: =J20*J10 -> 3834.0682 | K21: =K20*K10 -> 4454.743 | L21: =L20*L10 -> 5075.4179 | ... AR21: =AR20*AR10 -> 24708.67
B23: Income | C23: =C3-C4 -> 55480.964 | E23: =E3-E4 -> 18841.646 | F23: =F3-F4 -> 31082.136 | G23: =G3-G4 -> 43322.625 | H23: =H3-H4 -> 55563.114 | I23: =I3-I4 -> 67803.603 | J23: =J3-J4 -> 80044.093 | K23: =K3-K4 -> 92284.582 | L23: =L3-L4 -> 104525.07 | ... AR23: =AR3-AR4 -> 482520.21
B24: % Income | C24: =C23/C3 -> 0.59991766 | E24: =E23/E3 -> 0.42976594 | F24: =F23/F3 -> 0.38334135 | G24: =G23/G3 -> 0.36613982 | H24: =H23/H3 -> 0.35717409 | I24: =I23/I3 -> 0.35167187 | J24: =J23/J3 -> 0.34795109 | K24: =K23/K3 -> 0.34526714 | L24: =L23/L3 -> 0.34323962 | ... AR24: =AR23/AR3 -> 0.32547294
B28: 4 yrs
B29: GROSS | C29: =C47*C41 -> 40936.742 | E29: =E47*E41 -> 40936.742 | F29: =F47*F41 -> 75569.271 | G29: =G47*G41 -> 110201.8 | H29: =H47*H41 -> 144834.33 | I29: =I47*I41 -> 179466.86 | J29: =J47*J41 -> 214099.39 | K29: =K47*K41 -> 248731.92 | L29: =L47*L41 -> 283364.45 | ... AR29: =AR47*AR41 -> 1391605.4
B30: NET | C30: ='DATA ENTRY'!F5 -> 25000 | E30: 25000 | F30: 50000 | G30: 75000 | H30: 100000 | I30: 125000 | J30: 150000 | K30: 175000 | L30: 200000 | M30: 225000 | N30: 250000 | O30: 275000 | P30: 300000 | Q30: 325000 | R30: 350000 | S30: 375000 | T30: 400000 | U30: 425000 | V30: 450000 | W30: 475000 | X30: 500000 | Y30: 525000 | Z30: 550000 | AA30: 575000 | AB30: 600000 | AC30: 625000 | AD30: 650000 | AE30: 675000 | AF30: 700000 | AG30: 725000 | AH30: 750000 | AI30: 775000 | AJ30: 800000 | AK30: 825000 | AL30: 850000 | AM30: 875000 | AN30: 900000 | AO30: 925000 | AP30: 950000 | AQ30: 975000 | AR30: 1000000
B31: SF | C31: =C30*0.102 -> 2550 | E31: =E30*0.102 -> 2550 | F31: =F30*0.102 -> 5100 | G31: =G30*0.102 -> 7650 | H31: =H30*0.102 -> 10200 | I31: =I30*0.102 -> 12750 | J31: =J30*0.102 -> 15300 | K31: =K30*0.102 -> 17850 | L31: =L30*0.102 -> 20400 | ... AR31: =AR30*0.102 -> 102000
B32: Insurance | C32: =(C30/1000)*C41 -> 1200 | E32: =(E30/1000)*E41 -> 1200 | F32: =(F30/1000)*F41 -> 2400 | G32: =(G30/1000)*G41 -> 3600 | H32: =(H30/1000)*H41 -> 4800 | I32: =(I30/1000)*I41 -> 6000 | J32: =(J30/1000)*J41 -> 7200 | K32: =(K30/1000)*K41 -> 8400 | L32: =(L30/1000)*L41 -> 9600 | ... AR32: =(AR30/1000)*AR41 -> 48000
B33: CapCon | C33: ='DATA ENTRY'!F10 -> 5000 | E33: 5000 | F33: 5000 | G33: 5000 | H33: 5000 | I33: 5000 | J33: 5000 | K33: 5000 | L33: 5000 | M33: 5000 | N33: 5000 | O33: 5000 | P33: 5000 | Q33: =O33 -> 5000 | R33: =P33 -> 5000 | S33: =Q33 -> 5000 | T33: =R33 -> 5000 | U33: =S33 -> 5000 | V33: =T33 -> 5000 | W33: =U33 -> 5000 | X33: =V33 -> 5000 | ... AR33: =AP33 -> 5000
B34: membership fee | C34: ='DATA ENTRY'!F11 -> 300 | E34: 300 | F34: 300 | G34: 300 | H34: 300 | I34: 300 | J34: 300 | K34: 300 | L34: 300 | M34: 300 | N34: 300 | O34: 300 | P34: 300 | Q34: =O34 -> 300 | R34: =P34 -> 300 | S34: =Q34 -> 300 | T34: =R34 -> 300 | U34: =S34 -> 300 | V34: =T34 -> 300 | W34: =U34 -> 300 | X34: =V34 -> 300 | ... AR34: =AP34 -> 300
B35: Advance Interest | C35: =C40*C30*2 -> 365.83333 | E35: =E40*E30*2 -> 365.83333 | F35: =F40*F30*2 -> 731.66667 | G35: =G40*G30*2 -> 1097.5 | H35: =H40*H30*2 -> 1463.3333 | I35: =I40*I30*2 -> 1829.1667 | J35: =J40*J30*2 -> 2195 | K35: =K40*K30*2 -> 2560.8333 | L35: =L40*L30*2 -> 2926.6667 | ... AR35: =AR40*AR30*2 -> 14633.333
B36: LOAN AMOUNT | C36: =SUM(C30:C35) -> 34415.833 | E36: =SUM(E30:E35) -> 34415.833 | F36: =SUM(F30:F35) -> 63531.667 | G36: =SUM(G30:G35) -> 92647.5 | H36: =SUM(H30:H35) -> 121763.33 | I36: =SUM(I30:I35) -> 150879.17 | J36: =SUM(J30:J35) -> 179995 | K36: =SUM(K30:K35) -> 209110.83 | L36: =SUM(L30:L35) -> 238226.67 | ... AR36: =SUM(AR30:AR35) -> 1169933.3
B37: Annual Interest | C37: 0.0878 | E37: 0.0878 | F37: =C37 -> 0.0878 | G37: =F37 -> 0.0878 | H37: =F37 -> 0.0878 | I37: =G37 -> 0.0878 | J37: =H37 -> 0.0878 | K37: =I37 -> 0.0878 | L37: =J37 -> 0.0878 | M37: =K37 -> 0.0878 | N37: =L37 -> 0.0878 | O37: =M37 -> 0.0878 | ... AR37: =AP37 -> 0.0878
B38: Effective Interest rate | C38: =(1+C37/C41)^C41-1 -> 0.091682187 | E38: =(1+E37/E41)^E41-1 -> 0.091682187 | F38: =(1+F37/F41)^F41-1 -> 0.091682187 | G38: =(1+G37/G41)^G41-1 -> 0.091682187 | H38: =(1+H37/H41)^H41-1 -> 0.091682187 | I38: =(1+I37/I41)^I41-1 -> 0.091682187 | J38: =(1+J37/J41)^J41-1 -> 0.091682187 | K38: =(1+K37/K41)^K41-1 -> 0.091682187 | L38: =(1+L37/L41)^L41-1 -> 0.091682187 | ... AR38: =(1+AR37/AR41)^AR41-1 -> 0.091682187
B39: Loan Term | C39: 4 | E39: 4 | F39: 4 | G39: 4 | H39: 4 | I39: 4 | J39: 4 | K39: 4 | L39: =H39 -> 4 | M39: =I39 -> 4 | N39: =K39 -> 4 | O39: =K39 -> 4 | P39: =L39 -> 4 | Q39: =M39 -> 4 | R39: =N39 -> 4 | S39: =O39 -> 4 | T39: =P39 -> 4 | U39: =Q39 -> 4 | V39: =R39 -> 4 | ... AR39: =AN39 -> 4
B40: Monthly Interest Rate | C40: =C37/12 -> 0.0073166667 | E40: =E37/12 -> 0.0073166667 | F40: =F37/12 -> 0.0073166667 | G40: =G37/12 -> 0.0073166667 | H40: =H37/12 -> 0.0073166667 | I40: =I37/12 -> 0.0073166667 | J40: =J37/12 -> 0.0073166667 | K40: =K37/12 -> 0.0073166667 | L40: =L37/12 -> 0.0073166667 | ... AR40: =AR37/12 -> 0.0073166667
B41: Nr of Payments | C41: =C39*12 -> 48 | E41: =E39*12 -> 48 | F41: =F39*12 -> 48 | G41: =G39*12 -> 48 | H41: =H39*12 -> 48 | I41: =I39*12 -> 48 | J41: =J39*12 -> 48 | K41: =K39*12 -> 48 | L41: =L39*12 -> 48 | ... AR41: =AR39*12 -> 48
B43: Monthly Amortization | C43: =(1+C40)^C41 -> 1.4189561 | E43: =(1+E40)^E41 -> 1.4189561 | F43: =(1+F40)^F41 -> 1.4189561 | G43: =(1+G40)^G41 -> 1.4189561 | H43: =(1+H40)^H41 -> 1.4189561 | I43: =(1+I40)^I41 -> 1.4189561 | J43: =(1+J40)^J41 -> 1.4189561 | K43: =(1+K40)^K41 -> 1.4189561 | L43: =(1+L40)^L41 -> 1.4189561 | ... AR43: =(1+AR40)^AR41 -> 1.4189561
C44: =C43*C40 -> 0.010382028 | E44: =E43*E40 -> 0.010382028 | F44: =F43*F40 -> 0.010382028 | G44: =G43*G40 -> 0.010382028 | H44: =H43*H40 -> 0.010382028 | I44: =I43*I40 -> 0.010382028 | J44: =J43*J40 -> 0.010382028 | K44: =K43*K40 -> 0.010382028 | L44: =L43*L40 -> 0.010382028 | ... AR44: =AR43*AR40 -> 0.010382028
C45: =C43-1 -> 0.41895605 | E45: =E43-1 -> 0.41895605 | F45: =F43-1 -> 0.41895605 | G45: =G43-1 -> 0.41895605 | H45: =H43-1 -> 0.41895605 | I45: =I43-1 -> 0.41895605 | J45: =J43-1 -> 0.41895605 | K45: =K43-1 -> 0.41895605 | L45: =L43-1 -> 0.41895605 | ... AR45: =AR43-1 -> 0.41895605
C46: =C44/C45 -> 0.02478071 | E46: =E44/E45 -> 0.02478071 | F46: =F44/F45 -> 0.02478071 | G46: =G44/G45 -> 0.02478071 | H46: =H44/H45 -> 0.02478071 | I46: =I44/I45 -> 0.02478071 | J46: =J44/J45 -> 0.02478071 | K46: =K44/K45 -> 0.02478071 | L46: =L44/L45 -> 0.02478071 | ... AR46: =AR44/AR45 -> 0.02478071
B47: Monthly Amortization | C47: =C46*C36 -> 852.84879 | E47: =E46*E36 -> 852.84879 | F47: =F46*F36 -> 1574.3598 | G47: =G46*G36 -> 2295.8708 | H47: =H46*H36 -> 3017.3819 | I47: =I46*I36 -> 3738.8929 | J47: =J46*J36 -> 4460.4039 | K47: =K46*K36 -> 5181.9149 | L47: =L46*L36 -> 5903.426 | ... AR47: =AR46*AR36 -> 28991.779
...

Sheet GARCIA, CARLITO
B1: Amortization | C1: ='DATA ENTRY'!F16 -> 852.84879
B2: Timeline | C2: 0 | D2: 1 | E2: 2 | F2: 3 | G2: 4 | H2: 5 | I2: 6 | J2: 7 | K2: 8 | L2: 9 | M2: 10 | N2: 11 | O2: 12 | P2: 13 | Q2: 14 | R2: 15 | S2: 16 | T2: 17 | U2: 18 | V2: 19 | W2: 20 | X2: 21 | Y2: 22 | Z2: 23 | AA2: 24 | AB2: 25 | AC2: 26 | AD2: 27 | AE2: 28 | AF2: 29 | AG2: 30 | AH2: 31 | AI2: 32 | AJ2: 33 | AK2: 34 | AL2: 35 | AM2: 36 | AN2: 37 | AO2: 38 | AP2: 39 | AQ2: 40 | AR2: 41 | AS2: 42 | AT2: 43 | AU2: 44 | AV2: 45 | AW2: 46 | AX2: 47 | AY2: 48 | AZ2: 49 | BA2: 50 | BB2: 51 | BC2: 52 | BD2: 53 | BE2: 54 | BF2: 55 | BG2: 56 | BH2: 57 | BI2: 58 | BJ2: 59 | BK2: 60
B3: GROSS AMOUNT | C3: ='DATA ENTRY'!F4 -> 40936.742
B4: LOAN AMOUNT | C4: ='DATA ENTRY'!F13 -> 34415.833
B5: Service Fee | C5: ='DATA ENTRY'!F8 -> 2550
B6: Insurance | C6: ='DATA ENTRY'!F9 -> 1200
B7: CapCon
B8: membership fee | C8: ='DATA ENTRY'!G11 -> 0
B9: Advance Interest | C9: ='DATA ENTRY'!F12 -> 365.83333
B10: NET PROCEEDS/CASH FLOW | C10: =C4-C5-C6-C7-C8-C9 -> 30300 | D10: =-$C1 -> -852.84879 | E10: =-$C1 -> -852.84879 | F10: =-$C1 -> -852.84879 | G10: =-$C1 -> -852.84879 | H10: =-$C1 -> -852.84879 | I10: =-$C1 -> -852.84879 | J10: =-$C1 -> -852.84879 | K10: =-$C1 -> -852.84879 | ... BK10: =-$C1 -> -852.84879
B12: Interest Rate of Return | C12: =IRR(C10:BK10) -> 0.019103335 | D12: =C12/5 -> 0.0038206671
B14: Loan Balance
B15: Monthly Interest Rate | C15: ='DATA ENTRY'!G14/12 -> 0.0075
B16: Effective Interest Rate | C16: ='DATA ENTRY'!G15 -> 0.094100503
C20: LOAN LEDGER CARD
C22: Name: | D22: Garcia,Carlito Vasquez | G22: Loan Voucher No.
C23: Serial Nr: | D23: O-121478 | E23: Address: | F23: Lot 1 Blk 221 GRP, Zone 13, Pembo Makati City | G23: Amount: | H23: =C10 -> 30300
C24: Posting date | D24: Date of Loan: | E24: 45842 | F24: Maturity Date | G24: =B87 -> 47699 | K24: PEOPLE'S MULTI-PURPOSE COOPERATIVE
D25: Term: | E25: 48 | F25: MOS | K25: 20-E 2nd Camarilla St. corner 15th Ave., Brgy. San Roque, Murphy Cubao, Quezon City
D26: Loan | E26: Installment | F26: Principal | G26: EIR | H26: Balance
D27: Month 0 | H27: =C10 -> 30300 | K27: LOAN RELEASE VOUCHER
B28: =DATE(YEAR(E$24),MONTH(E$24)+D28+1,DAY(E$24)) -> 45904 | C28: =TEXT(B28,"mmm-yyyy") -> Sep-2025 | D28: 1 | E28: =C$1 -> 852.84879 | F28: =E28-G28 -> 274.01773 | G28: =H27*C$12 -> 578.83106 | H28: =H27-F28 -> 30025.982
B29: =DATE(YEAR(E$24),MONTH(E$24)+D29+1,DAY(E$24)) -> 45934 | C29: =TEXT(B29,"mmm-yyyy") -> Oct-2025 | D29: 2 | E29: =C$1 -> 852.84879 | F29: =E29-G29 -> 279.25238 | G29: =H28*C$12 -> 573.59641 | H29: =H28-F29 -> 29746.73 | R29: Date: | S29: =E24 -> 45842
B30: =DATE(YEAR(E$24),MONTH(E$24)+D30+1,DAY(E$24)) -> 45965 | C30: =TEXT(B30,"mmm-yyyy") -> Nov-2025 | D30: 3 | E30: =C$1 -> 852.84879 | F30: =E30-G30 -> 284.58703 | G30: =H29*C$12 -> 568.26176 | H30: =H29-F30 -> 29462.143 | R30: LV No: | S30: 0001
B31: =DATE(YEAR(E$24),MONTH(E$24)+D31+1,DAY(E$24)) -> 45995 | C31: =TEXT(B31,"mmm-yyyy") -> Dec-2025 | D31: 4 | E31: =C$1 -> 852.84879 | F31: =E31-G31 -> 290.02359 | G31: =H30*C$12 -> 562.8252 | H31: =H30-F31 -> 29172.119
B32: =DATE(YEAR(E$24),MONTH(E$24)+D32+1,DAY(E$24)) -> 46026 | C32: =TEXT(B32,"mmm-yyyy") -> Jan-2026 | D32: 5 | E32: =C$1 -> 852.84879 | F32: =E32-G32 -> 295.56401 | G32: =H31*C$12 -> 557.28478 | H32: =H31-F32 -> 28876.555 | K32: Name of Borrower: | N32: =D22 -> Garcia,Carlito Vasquez
B33: =DATE(YEAR(E$24),MONTH(E$24)+D33+1,DAY(E$24)) -> 46057 | C33: =TEXT(B33,"mmm-yyyy") -> Feb-2026 | D33: 6 | E33: =C$1 -> 852.84879 | F33: =E33-G33 -> 301.21027 | G33: =H32*C$12 -> 551.63852 | H33: =H32-F33 -> 28575.345 | K33: Serial No.: | N33: =D23 -> O-121478
B34: =DATE(YEAR(E$24),MONTH(E$24)+D34+1,DAY(E$24)) -> 46085 | C34: =TEXT(B34,"mmm-yyyy") -> Mar-2026 | D34: 7 | E34: =C$1 -> 852.84879 | F34: =E34-G34 -> 306.96439 | G34: =H33*C$12 -> 545.8844 | H34: =H33-F34 -> 28268.381 | K34: Address: | N34: =F23 -> Lot 1 Blk 221 GRP, Zone 13, Pembo Makati City
B35: =DATE(YEAR(E$24),MONTH(E$24)+D35+1,DAY(E$24)) -> 46116 | C35: =TEXT(B35,"mmm-yyyy") -> Apr-2026 | D35: 8 | E35: =C$1 -> 852.84879 | F35: =E35-G35 -> 312.82843 | G35: =H34*C$12 -> 540.02035 | H35: =H34-F35 -> 27955.552
B36: =DATE(YEAR(E$24),MONTH(E$24)+D36+1,DAY(E$24)) -> 46146 | C36: =TEXT(B36,"mmm-yyyy") -> May-2026 | D36: 9 | E36: =C$1 -> 852.84879 | F36: =E36-G36 -> 318.8045 | G36: =H35*C$12 -> 534.04429 | H36: =H35-F36 -> 27636.748 | L36: Principal Amount | R36: =C4 -> 34415.833
B37: =DATE(YEAR(E$24),MONTH(E$24)+D37+1,DAY(E$24)) -> 46177 | C37: =TEXT(B37,"mmm-yyyy") -> Jun-2026 | D37: 10 | E37: =C$1 -> 852.84879 | F37: =E37-G37 -> 324.89473 | G37: =H36*C$12 -> 527.95406 | H37: =H36-F37 -> 27311.853
B38: =DATE(YEAR(E$24),MONTH(E$24)+D38+1,DAY(E$24)) -> 46207 | C38: =TEXT(B38,"mmm-yyyy") -> Jul-2026 | D38: 11 | E38: =C$1 -> 852.84879 | F38: =E38-G38 -> 331.1013 | G38: =H37*C$12 -> 521.74749 | H38: =H37-F38 -> 26980.752 | L38: (-) | M38: Balance Old Loan(s) | R38: =-C14 -> 0
B39: =DATE(YEAR(E$24),MONTH(E$24)+D39+1,DAY(E$24)) -> 46238 | C39: =TEXT(B39,"mmm-yyyy") -> Aug-2026 | D39: 12 | E39: =C$1 -> 852.84879 | F39: =E39-G39 -> 337.42644 | G39: =H38*C$12 -> 515.42235 | H39: =H38-F39 -> 26643.325 | L39: (-) | M39: Membership Fee: | R39: =-C8 -> 0
B40: =DATE(YEAR(E$24),MONTH(E$24)+D40+1,DAY(E$24)) -> 46269 | C40: =TEXT(B40,"mmm-yyyy") -> Sep-2026 | D40: 13 | E40: =C$1 -> 852.84879 | F40: =E40-G40 -> 343.87241 | G40: =H39*C$12 -> 508.97638 | H40: =H39-F40 -> 26299.453 | L40: (-) | M40: Paid up Capital: | R40: =-C7 -> 0
B41: =DATE(YEAR(E$24),MONTH(E$24)+D41+1,DAY(E$24)) -> 46299 | C41: =TEXT(B41,"mmm-yyyy") -> Oct-2026 | D41: 14 | E41: =C$1 -> 852.84879 | F41: =E41-G41 -> 350.44152 | G41: =H40*C$12 -> 502.40727 | H41: =H40-F41 -> 25949.011 | L41: (-) | M41: Service Fee | R41: =-C5 -> -2550
B42: =DATE(YEAR(E$24),MONTH(E$24)+D42+1,DAY(E$24)) -> 46330 | C42: =TEXT(B42,"mmm-yyyy") -> Nov-2026 | D42: 15 | E42: =C$1 -> 852.84879 | F42: =E42-G42 -> 357.13612 | G42: =H41*C$12 -> 495.71266 | H42: =H41-F42 -> 25591.875 | L42: (-) | M42: Insurance Premium - Paramount | R42: =-C6 -> -1200
B43: =DATE(YEAR(E$24),MONTH(E$24)+D43+1,DAY(E$24)) -> 46360 | C43: =TEXT(B43,"mmm-yyyy") -> Dec-2026 | D43: 16 | E43: =C$1 -> 852.84879 | F43: =E43-G43 -> 363.95861 | G43: =H42*C$12 -> 488.89017 | H43: =H42-F43 -> 25227.917 | L43: (-) | M43: Advance Interest | R43: =-C9 -> -365.83333
B44: =DATE(YEAR(E$24),MONTH(E$24)+D44+1,DAY(E$24)) -> 46391 | C44: =TEXT(B44,"mmm-yyyy") -> Jan-2027 | D44: 17 | E44: =C$1 -> 852.84879 | F44: =E44-G44 -> 370.91144 | G44: =H43*C$12 -> 481.93735 | H44: =H43-F44 -> 24857.005 | L44: NET PROCEEDS (Php): | R44: =SUM(R36:T43) -> 30300
B45: =DATE(YEAR(E$24),MONTH(E$24)+D45+1,DAY(E$24)) -> 46422 | C45: =TEXT(B45,"mmm-yyyy") -> Feb-2027 | D45: 18 | E45: =C$1 -> 852.84879 | F45: =E45-G45 -> 377.99708 | G45: =H44*C$12 -> 474.8517 | H45: =H44-F45 -> 24479.008
B46: =DATE(YEAR(E$24),MONTH(E$24)+D46+1,DAY(E$24)) -> 46450 | C46: =TEXT(B46,"mmm-yyyy") -> Mar-2027 | D46: 19 | E46: =C$1 -> 852.84879 | F46: =E46-G46 -> 385.21809 | G46: =H45*C$12 -> 467.6307 | H46: =H45-F46 -> 24093.79 | K46: PAYMENT
...

Sheet MARTIN, RICARDO
B1: Amortization | C1: ='DATA ENTRY'!G16 -> 1541.3494
B2: Timeline | C2: 0 | D2: 1 | E2: 2 | F2: 3 | G2: 4 | H2: 5 | I2: 6 | J2: 7 | K2: 8 | L2: 9 | M2: 10 | N2: 11 | O2: 12 | P2: 13 | Q2: 14 | R2: 15 | S2: 16 | T2: 17 | U2: 18 | V2: 19 | W2: 20 | X2: 21 | Y2: 22 | Z2: 23 | AA2: 24 | AB2: 25 | AC2: 26 | AD2: 27 | AE2: 28 | AF2: 29 | AG2: 30 | AH2: 31 | AI2: 32 | AJ2: 33 | AK2: 34 | AL2: 35 | AM2: 36 | AN2: 37 | AO2: 38 | AP2: 39 | AQ2: 40 | AR2: 41 | AS2: 42 | AT2: 43 | AU2: 44 | AV2: 45 | AW2: 46 | AX2: 47 | AY2: 48 | AZ2: 49 | BA2: 50 | BB2: 51 | BC2: 52 | BD2: 53 | BE2: 54 | BF2: 55 | BG2: 56 | BH2: 57 | BI2: 58 | BJ2: 59 | BK2: 60
B3: GROSS AMOUNT | C3: ='DATA ENTRY'!G4 -> 92480.964
B4: LOAN AMOUNT | C4: ='DATA ENTRY'!G13 -> 74252
B5: Service Fee | C5: ='DATA ENTRY'!G8 -> 4477
B6: Insurance | C6: ='DATA ENTRY'!G9 -> 2220
B7: CapCon | C7: ='DATA ENTRY'!G10 -> 30000
B8: membership fee | C8: ='DATA ENTRY'!G11 -> 0
B9: Advance Interest | C9: ='DATA ENTRY'!G12 -> 555
B10: NET PROCEEDS/CASH FLOW | C10: =C4-C5-C6-C7-C8-C9 -> 37000 | D10: =-$C1 -> -1541.3494 | E10: =-$C1 -> -1541.3494 | F10: =-$C1 -> -1541.3494 | G10: =-$C1 -> -1541.3494 | H10: =-$C1 -> -1541.3494 | I10: =-$C1 -> -1541.3494 | J10: =-$C1 -> -1541.3494 | K10: =-$C1 -> -1541.3494 | ... BK10: =-$C1 -> -1541.3494
B12: Interest Rate of Return | C12: =IRR(C10:BK10) -> 0.036929294 | D12: =C12/5 -> 0.0073858588
B14: Loan Balance
B15: Monthly Interest Rate | C15: ='DATA ENTRY'!G14/12 -> 0.0075
B16: Effective Interest Rate | C16: ='DATA ENTRY'!G15 -> 0.094100503
C20: LOAN LEDGER CARD
C22: Name: | D22: Martin, Ricardo Barroga | G22: Loan Voucher No.
C23: Serial Nr: | D23: O-127212 | E23: Address: | F23: B4 L14 Derosa St MS2, LNC Brgy Navarro, Gen Trias Cavite | G23: Amount: | H23: =C10 -> 37000
C24: Posting date | D24: Date of Loan: | E24: 45832 | F24: Maturity Date | G24: =B87 -> 47688 | K24: PEOPLE'S MULTI-PURPOSE COOPERATIVE
D25: Term: | E25: 60 | F25: MOS | K25: 20-E 2nd Camarilla St. corner 15th Ave., Brgy. San Roque, Murphy Cubao, Quezon City
D26: Loan | E26: Installment | F26: Principal | G26: EIR | H26: Balance
D27: Month 0 | H27: =C10 -> 37000 | K27: LOAN RELEASE VOUCHER
B28: =DATE(YEAR(E$24),MONTH(E$24)+D28+1,DAY(E$24)) -> 45893 | C28: =TEXT(B28,"mmm-yyyy") -> Aug-2025 | D28: 1 | E28: =C$1 -> 1541.3494 | F28: =E28-G28 -> 174.96552 | G28: =H27*C$12 -> 1366.3839 | H28: =H27-F28 -> 36825.034
B29: =DATE(YEAR(E$24),MONTH(E$24)+D29+1,DAY(E$24)) -> 45924 | C29: =TEXT(B29,"mmm-yyyy") -> Sep-2025 | D29: 2 | E29: =C$1 -> 1541.3494 | F29: =E29-G29 -> 181.42687 | G29: =H28*C$12 -> 1359.9225 | H29: =H28-F29 -> 36643.608 | R29: Date: | S29: =E24 -> 45832
B30: =DATE(YEAR(E$24),MONTH(E$24)+D30+1,DAY(E$24)) -> 45954 | C30: =TEXT(B30,"mmm-yyyy") -> Oct-2025 | D30: 3 | E30: =C$1 -> 1541.3494 | F30: =E30-G30 -> 188.12684 | G30: =H29*C$12 -> 1353.2226 | H30: =H29-F30 -> 36455.481 | R30: LV No: | S30: 0001
B31: =DATE(YEAR(E$24),MONTH(E$24)+D31+1,DAY(E$24)) -> 45985 | C31: =TEXT(B31,"mmm-yyyy") -> Nov-2025 | D31: 4 | E31: =C$1 -> 1541.3494 | F31: =E31-G31 -> 195.07423 | G31: =H30*C$12 -> 1346.2752 | H31: =H30-F31 -> 36260.407
B32: =DATE(YEAR(E$24),MONTH(E$24)+D32+1,DAY(E$24)) -> 46015 | C32: =TEXT(B32,"mmm-yyyy") -> Dec-2025 | D32: 5 | E32: =C$1 -> 1541.3494 | F32: =E32-G32 -> 202.27818 | G32: =H31*C$12 -> 1339.0712 | H32: =H31-F32 -> 36058.128 | K32: Name of Borrower: | N32: =D22 -> Martin, Ricardo Barroga
B33: =DATE(YEAR(E$24),MONTH(E$24)+D33+1,DAY(E$24)) -> 46046 | C33: =TEXT(B33,"mmm-yyyy") -> Jan-2026 | D33: 6 | E33: =C$1 -> 1541.3494 | F33: =E33-G33 -> 209.74818 | G33: =H32*C$12 -> 1331.6012 | H33: =H32-F33 -> 35848.38 | K33: Serial No.: | N33: =D23 -> O-127212
B34: =DATE(YEAR(E$24),MONTH(E$24)+D34+1,DAY(E$24)) -> 46077 | C34: =TEXT(B34,"mmm-yyyy") -> Feb-2026 | D34: 7 | E34: =C$1 -> 1541.3494 | F34: =E34-G34 -> 217.49403 | G34: =H33*C$12 -> 1323.8554 | H34: =H33-F34 -> 35630.886 | K34: Address: | N34: =F23 -> B4 L14 Derosa St MS2, LNC Brgy Navarro, Gen Trias Cavite
B35: =DATE(YEAR(E$24),MONTH(E$24)+D35+1,DAY(E$24)) -> 46105 | C35: =TEXT(B35,"mmm-yyyy") -> Mar-2026 | D35: 8 | E35: =C$1 -> 1541.3494 | F35: =E35-G35 -> 225.52593 | G35: =H34*C$12 -> 1315.8235 | H35: =H34-F35 -> 35405.36
B36: =DATE(YEAR(E$24),MONTH(E$24)+D36+1,DAY(E$24)) -> 46136 | C36: =TEXT(B36,"mmm-yyyy") -> Apr-2026 | D36: 9 | E36: =C$1 -> 1541.3494 | F36: =E36-G36 -> 233.85444 | G36: =H35*C$12 -> 1307.495 | H36: =H35-F36 -> 35171.506 | L36: Principal Amount | R36: =C4 -> 74252
B37: =DATE(YEAR(E$24),MONTH(E$24)+D37+1,DAY(E$24)) -> 46166 | C37: =TEXT(B37,"mmm-yyyy") -> May-2026 | D37: 10 | E37: =C$1 -> 1541.3494 | F37: =E37-G37 -> 242.49052 | G37: =H36*C$12 -> 1298.8589 | H37: =H36-F37 -> 34929.015
B38: =DATE(YEAR(E$24),MONTH(E$24)+D38+1,DAY(E$24)) -> 46197 | C38: =TEXT(B38,"mmm-yyyy") -> Jun-2026 | D38: 11 | E38: =C$1 -> 1541.3494 | F38: =E38-G38 -> 251.44552 | G38: =H37*C$12 -> 1289.9039 | H38: =H37-F38 -> 34677.57 | L38: (-) | M38: Balance Old Loan(s) | R38: =-C14 -> 0
B39: =DATE(YEAR(E$24),MONTH(E$24)+D39+1,DAY(E$24)) -> 46227 | C39: =TEXT(B39,"mmm-yyyy") -> Jul-2026 | D39: 12 | E39: =C$1 -> 1541.3494 | F39: =E39-G39 -> 260.73123 | G39: =H38*C$12 -> 1280.6182 | H39: =H38-F39 -> 34416.839 | L39: (-) | M39: Membership Fee: | R39: =-C8 -> 0
B40: =DATE(YEAR(E$24),MONTH(E$24)+D40+1,DAY(E$24)) -> 46258 | C40: =TEXT(B40,"mmm-yyyy") -> Aug-2026 | D40: 13 | E40: =C$1 -> 1541.3494 | F40: =E40-G40 -> 270.35985 | G40: =H39*C$12 -> 1270.9895 | H40: =H39-F40 -> 34146.479 | L40: (-) | M40: Paid up Capital: | R40: =-C7 -> -30000
B41: =DATE(YEAR(E$24),MONTH(E$24)+D41+1,DAY(E$24)) -> 46289 | C41: =TEXT(B41,"mmm-yyyy") -> Sep-2026 | D41: 14 | E41: =C$1 -> 1541.3494 | F41: =E41-G41 -> 280.34405 | G41: =H40*C$12 -> 1261.0053 | H41: =H40-F41 -> 33866.135 | L41: (-) | M41: Service Fee | R41: =-C5 -> -4477
B42: =DATE(YEAR(E$24),MONTH(E$24)+D42+1,DAY(E$24)) -> 46319 | C42: =TEXT(B42,"mmm-yyyy") -> Oct-2026 | D42: 15 | E42: =C$1 -> 1541.3494 | F42: =E42-G42 -> 290.69696 | G42: =H41*C$12 -> 1250.6524 | H42: =H41-F42 -> 33575.438 | L42: (-) | M42: Insurance Premium - Paramount | R42: =-C6 -> -2220
B43: =DATE(YEAR(E$24),MONTH(E$24)+D43+1,DAY(E$24)) -> 46350 | C43: =TEXT(B43,"mmm-yyyy") -> Nov-2026 | D43: 16 | E43: =C$1 -> 1541.3494 | F43: =E43-G43 -> 301.43219 | G43: =H42*C$12 -> 1239.9172 | H43: =H42-F43 -> 33274.005 | L43: (-) | M43: Advance Interest | R43: =-C9 -> -555
B44: =DATE(YEAR(E$24),MONTH(E$24)+D44+1,DAY(E$24)) -> 46380 | C44: =TEXT(B44,"mmm-yyyy") -> Dec-2026 | D44: 17 | E44: =C$1 -> 1541.3494 | F44: =E44-G44 -> 312.56387 | G44: =H43*C$12 -> 1228.7855 | H44: =H43-F44 -> 32961.442 | L44: NET PROCEEDS (Php): | R44: =SUM(R36:T43) -> 37000
B45: =DATE(YEAR(E$24),MONTH(E$24)+D45+1,DAY(E$24)) -> 46411 | C45: =TEXT(B45,"mmm-yyyy") -> Jan-2027 | D45: 18 | E45: =C$1 -> 1541.3494 | F45: =E45-G45 -> 324.10663 | G45: =H44*C$12 -> 1217.2428 | H45: =H44-F45 -> 32637.335
B46: =DATE(YEAR(E$24),MONTH(E$24)+D46+1,DAY(E$24)) -> 46442 | C46: =TEXT(B46,"mmm-yyyy") -> Feb-2027 | D46: 19 | E46: =C$1 -> 1541.3494 | F46: =E46-G46 -> 336.07566 | G46: =H45*C$12 -> 1205.2737 | H46: =H45-F46 -> 32301.259 | K46: PAYMENT
...

Sheet YADAO, MELENCIO
B1: Amortization | C1: ='DATA ENTRY'!D16 -> 949.99786
B2: Timeline | C2: 0 | D2: 1 | E2: 2 | F2: 3 | G2: 4 | H2: 5 | I2: 6 | J2: 7 | K2: 8 | L2: 9 | M2: 10 | N2: 11 | O2: 12 | P2: 13 | Q2: 14 | R2: 15 | S2: 16 | T2: 17 | U2: 18 | V2: 19 | W2: 20 | X2: 21 | Y2: 22 | Z2: 23 | AA2: 24 | AB2: 25 | AC2: 26 | AD2: 27 | AE2: 28 | AF2: 29 | AG2: 30 | AH2: 31 | AI2: 32 | AJ2: 33 | AK2: 34 | AL2: 35 | AM2: 36 | AN2: 37 | AO2: 38 | AP2: 39 | AQ2: 40 | AR2: 41 | AS2: 42 | AT2: 43 | AU2: 44 | AV2: 45 | AW2: 46 | AX2: 47 | AY2: 48 | AZ2: 49 | BA2: 50 | BB2: 51 | BC2: 52 | BD2: 53 | BE2: 54 | BF2: 55 | BG2: 56 | BH2: 57 | BI2: 58 | BJ2: 59 | BK2: 60
B3: GROSS AMOUNT | C3: ='DATA ENTRY'!D4 -> 22799.949
B4: LOAN AMOUNT | C4: ='DATA ENTRY'!D13 -> 20181.172
B5: Service Fee | C5: ='DATA ENTRY'!D8 -> 1198.47
B6: Insurance | C6: ='DATA ENTRY'!D9 -> 383.5104
B7: CapCon | C7: ='DATA ENTRY'!D10 -> 2000
B8: membership fee | C8: ='DATA ENTRY'!D11 -> 300
B9: Advance Interest | C9: ='DATA ENTRY'!D12 -> 319.592
B10: NET PROCEEDS/CASH FLOW | C10: =C4-C5-C6-C7-C8-C9 -> 15979.6 | D10: =-$C1 -> -949.99786 | E10: =-$C1 -> -949.99786 | F10: =-$C1 -> -949.99786 | G10: =-$C1 -> -949.99786 | H10: =-$C1 -> -949.99786 | I10: =-$C1 -> -949.99786 | J10: =-$C1 -> -949.99786 | K10: =-$C1 -> -949.99786 | ... BK10: =-$C1 -> -949.99786
B12: Interest Rate of Return | C12: =IRR(C10:AA10) -> 0.030632826 | D12: =C12/5 -> 0.0061265651
B14: Loan Balance
B15: Monthly Interest Rate | C15: ='DATA ENTRY'!G14/12 -> 0.0075
B16: Effective Interest Rate | C16: ='DATA ENTRY'!G15 -> 0.094100503
C20: LOAN LEDGER CARD
C22: Name: | D22: YADAO, MELENCIO C. | G22: Loan Voucher No. | H22: LRV-060
C23: Serial Nr: | D23: 716611 | E23: Address: | F23: 2 CONCHITA ST., PASAY CITY | G23: Amount: | H23: =C10 -> 15979.6
C24: Posting date | D24: Date of Loan: | E24: 46035 | F24: Maturity Date | G24: =C51 -> Mar-2028 | K24: PEOPLE'S MULTI-PURPOSE COOPERATIVE
D25: Term: | E25: 24 | F25: MOS | K25: 20-E 2nd Camarilla St. corner 15th Ave., Brgy. San Roque, Murphy Cubao, Quezon City
D26: Loan | E26: Installment | F26: Principal | G26: EIR | H26: Balance
D27: Month 0 | H27: =C10 -> 15979.6 | K27: LOAN RELEASE VOUCHER
B28: =DATE(YEAR(E$24),MONTH(E$24)+D28+2,DAY(E$24)) -> 46125 | C28: =TEXT(B28,"mmm-yyyy") -> Apr-2026 | D28: 1 | E28: =C$1 -> 949.99786 | F28: =E28-G28 -> 460.49756 | G28: =H27*C$12 -> 489.5003 | H28: =H27-F28 -> 15519.102
B29: =DATE(YEAR(E$24),MONTH(E$24)+D29+2,DAY(E$24)) -> 46155 | C29: =TEXT(B29,"mmm-yyyy") -> May-2026 | D29: 2 | E29: =C$1 -> 949.99786 | F29: =E29-G29 -> 474.6039 | G29: =H28*C$12 -> 475.39396 | H29: =H28-F29 -> 15044.499 | R29: Date: | S29: =E24 -> 46035
B30: =DATE(YEAR(E$24),MONTH(E$24)+D30+2,DAY(E$24)) -> 46186 | C30: =TEXT(B30,"mmm-yyyy") -> Jun-2026 | D30: 3 | E30: =C$1 -> 949.99786 | F30: =E30-G30 -> 489.14236 | G30: =H29*C$12 -> 460.8555 | H30: =H29-F30 -> 14555.356 | R30: LV No: | S30: =H22 -> LRV-060
B31: =DATE(YEAR(E$24),MONTH(E$24)+D31+2,DAY(E$24)) -> 46216 | C31: =TEXT(B31,"mmm-yyyy") -> Jul-2026 | D31: 4 | E31: =C$1 -> 949.99786 | F31: =E31-G31 -> 504.12617 | G31: =H30*C$12 -> 445.87169 | H31: =H30-F31 -> 14051.23
B32: =DATE(YEAR(E$24),MONTH(E$24)+D32+2,DAY(E$24)) -> 46247 | C32: =TEXT(B32,"mmm-yyyy") -> Aug-2026 | D32: 5 | E32: =C$1 -> 949.99786 | F32: =E32-G32 -> 519.56898 | G32: =H31*C$12 -> 430.42888 | H32: =H31-F32 -> 13531.661 | K32: Name of Borrower: | N32: =D22 -> YADAO, MELENCIO C.
B33: =DATE(YEAR(E$24),MONTH(E$24)+D33+2,DAY(E$24)) -> 46278 | C33: =TEXT(B33,"mmm-yyyy") -> Sep-2026 | D33: 6 | E33: =C$1 -> 949.99786 | F33: =E33-G33 -> 535.48485 | G33: =H32*C$12 -> 414.51301 | H33: =H32-F33 -> 12996.176 | K33: Serial No.: | N33: =D23 -> 716611
B34: =DATE(YEAR(E$24),MONTH(E$24)+D34+2,DAY(E$24)) -> 46308 | C34: =TEXT(B34,"mmm-yyyy") -> Oct-2026 | D34: 7 | E34: =C$1 -> 949.99786 | F34: =E34-G34 -> 551.88826 | G34: =H33*C$12 -> 398.1096 | H34: =H33-F34 -> 12444.288 | K34: Address: | N34: =F23 -> 2 CONCHITA ST., PASAY CITY
B35: =DATE(YEAR(E$24),MONTH(E$24)+D35+2,DAY(E$24)) -> 46339 | C35: =TEXT(B35,"mmm-yyyy") -> Nov-2026 | D35: 8 | E35: =C$1 -> 949.99786 | F35: =E35-G35 -> 568.79416 | G35: =H34*C$12 -> 381.2037 | H35: =H34-F35 -> 11875.494
B36: =DATE(YEAR(E$24),MONTH(E$24)+D36+2,DAY(E$24)) -> 46369 | C36: =TEXT(B36,"mmm-yyyy") -> Dec-2026 | D36: 9 | E36: =C$1 -> 949.99786 | F36: =E36-G36 -> 586.21793 | G36: =H35*C$12 -> 363.77993 | H36: =H35-F36 -> 11289.276 | L36: Principal Amount | R36: =C4 -> 20181.172
B37: =DATE(YEAR(E$24),MONTH(E$24)+D37+2,DAY(E$24)) -> 46400 | C37: =TEXT(B37,"mmm-yyyy") -> Jan-2027 | D37: 10 | E37: =C$1 -> 949.99786 | F37: =E37-G37 -> 604.17544 | G37: =H36*C$12 -> 345.82242 | H37: =H36-F37 -> 10685.1
B38: =DATE(YEAR(E$24),MONTH(E$24)+D38+2,DAY(E$24)) -> 46431 | C38: =TEXT(B38,"mmm-yyyy") -> Feb-2027 | D38: 11 | E38: =C$1 -> 949.99786 | F38: =E38-G38 -> 622.68304 | G38: =H37*C$12 -> 327.31482 | H38: =H37-F38 -> 10062.417 | L38: (-) | M38: Balance Old Loan(s) | R38: =-C14 -> 0
B39: =DATE(YEAR(E$24),MONTH(E$24)+D39+2,DAY(E$24)) -> 46459 | C39: =TEXT(B39,"mmm-yyyy") -> Mar-2027 | D39: 12 | E39: =C$1 -> 949.99786 | F39: =E39-G39 -> 641.75758 | G39: =H38*C$12 -> 308.24028 | H39: =H38-F39 -> 9420.6598 | L39: (-) | M39: Membership Fee: | R39: =-C8 -> -300
B40: =DATE(YEAR(E$24),MONTH(E$24)+D40+2,DAY(E$24)) -> 46490 | C40: =TEXT(B40,"mmm-yyyy") -> Apr-2027 | D40: 13 | E40: =C$1 -> 949.99786 | F40: =E40-G40 -> 661.41643 | G40: =H39*C$12 -> 288.58143 | H40: =H39-F40 -> 8759.2434 | L40: (-) | M40: Paid up Capital: | R40: =-C7 -> -2000
B41: =DATE(YEAR(E$24),MONTH(E$24)+D41+2,DAY(E$24)) -> 46520 | C41: =TEXT(B41,"mmm-yyyy") -> May-2027 | D41: 14 | E41: =C$1 -> 949.99786 | F41: =E41-G41 -> 681.67748 | G41: =H40*C$12 -> 268.32037 | H41: =H40-F41 -> 8077.5659 | L41: (-) | M41: Service Fee | R41: =-C5 -> -1198.47
B42: =DATE(YEAR(E$24),MONTH(E$24)+D42+2,DAY(E$24)) -> 46551 | C42: =TEXT(B42,"mmm-yyyy") -> Jun-2027 | D42: 15 | E42: =C$1 -> 949.99786 | F42: =E42-G42 -> 702.55919 | G42: =H41*C$12 -> 247.43867 | H42: =H41-F42 -> 7375.0067 | L42: (-) | M42: Insurance Premium - Paramount | R42: =-C6 -> -383.5104
B43: =DATE(YEAR(E$24),MONTH(E$24)+D43+2,DAY(E$24)) -> 46581 | C43: =TEXT(B43,"mmm-yyyy") -> Jul-2027 | D43: 16 | E43: =C$1 -> 949.99786 | F43: =E43-G43 -> 724.08057 | G43: =H42*C$12 -> 225.91729 | H43: =H42-F43 -> 6650.9261 | L43: (-) | M43: Advance Interest | R43: =-C9 -> -319.592
B44: =DATE(YEAR(E$24),MONTH(E$24)+D44+2,DAY(E$24)) -> 46612 | C44: =TEXT(B44,"mmm-yyyy") -> Aug-2027 | D44: 17 | E44: =C$1 -> 949.99786 | F44: =E44-G44 -> 746.2612 | G44: =H43*C$12 -> 203.73666 | H44: =H43-F44 -> 5904.6649 | L44: NET PROCEEDS (Php): | R44: =SUM(R36:T43) -> 15979.6
B45: =DATE(YEAR(E$24),MONTH(E$24)+D45+2,DAY(E$24)) -> 46643 | C45: =TEXT(B45,"mmm-yyyy") -> Sep-2027 | D45: 18 | E45: =C$1 -> 949.99786 | F45: =E45-G45 -> 769.12129 | G45: =H44*C$12 -> 180.87657 | H45: =H44-F45 -> 5135.5436
B46: =DATE(YEAR(E$24),MONTH(E$24)+D46+2,DAY(E$24)) -> 46673 | C46: =TEXT(B46,"mmm-yyyy") -> Oct-2027 | D46: 19 | E46: =C$1 -> 949.99786 | F46: =E46-G46 -> 792.68165 | G46: =H45*C$12 -> 157.31621 | H46: =H45-F46 -> 4342.862 | K46: PAYMENT
...

Sheet Loan Form
B6: 20-E 2nd Camarilla St corner 15th Avenue,
B7: Brgy San Roque, Murphy Cubao, Quezon City
B8: Mobile No. (+63)953-033-1580 (GLOBE)
B10: LOAN APPLICATION FORM
Y11: Date: | AA11: 0 | AB11: 1 | AC11: 1 | AD11: 3 | AE11: 2 | AF11: 0 | AG11: 2 | AH11: 6
AA12: m | AB12: m | AC12: d | AD12: d | AE12: y | AF12: y | AG12: y | AH12: y
B13: APPLICATION TYPE | I13: LOAN CLASSIFICATION | Q13: TERM | X13: RELEASE OF LOAN PROCEEDS
C14: New | J14: Salary Loan | R14: 12 Months | Y14: Check
C15: Renewal | J15: Pension Loan | R15: 24 Months | Y15: Bank Electronic Transfer to Borrowers Account
C16: Additional | J16: Emergency | R16: 36 Months | Y16: Others:
C17: Reloan | J17: Health Assistance Loan | R17: 48 Months
C18: Restructure | J18: Educational Loan | R18: 60 Months
J19: Others: | R19: Others:
B20: AMOUNT APPLIED: | F20: ='DATA ENTRY'!D5 -> 15979.6 | R20: MONTHLY AMORTIZATION: | X20: ='DATA ENTRY'!D16 -> 949.99786
B22: LOAN ID: | J22: DEDUCTION CODE: | V22: LOAN PURPOSE:
B23: MEM ID: | K23: Regular Member | W23: Old Member
K24: Associate Member | W24: New Member
B25: BORROWER'S INFORMATION
B26: YADAO | H26: MELENCIO | R26: CASPILLO
B27: (LAST NAME) | H27: (FIRST NAME) | R27: (MIDDLE NAME) | AD27: (SUFFIX)
B28: Rank/Position: | H28: Serial No.: | M28: Branch of Service: | S28: Date of Appointment: | AA28: Date of Retirement:
B29: MSGT | H29: 716611 | M29: PA | T29: , | V29: , | AA29: 1 | AB29: 2 | AC29: 0 | AD29: 1 | AE29: 2 | AF29: 0 | AG29: 0 | AH29: 4
S30: m | T30: m | U30: d | V30: d | W30: y | X30: y | Y30: y | Z30: y | AA30: m | AB30: m | AC30: d | AD30: d | AE30: y | AF30: y | AG30: y | AH30: y
B32: Length of Service: | I32: Date of Birth: | N32: Age: | O32: 65 | Q32: Civil Status: | V32: Single | Y32: Widower | AB32: Home Phone No.
I33: 22254 | V33: Married | Y33: Separated
B34: Unit Assignment: | I34: Unit/Office/Business Address: | AB34: Unit/Office Telephone No/s:
B36: AFP/Company ID No: | K36: Email Address: | X36: Tax Identification No/s:
X37: 9 | Y37: 1 | Z37: 8 | AA37: - | AB37: 6 | AC37: 6 | AD37: 1 | AE37: - | AF37: 6 | AG37: 9 | AH37: 3
B38: Present Address: | F38: B4 L14 DEROSA ST MS2, LNC, BRGY NAVARRO, CITY OF GEN TRIAS CAVITE
B39: NOTIFICATION CLAUSE
C41: I hereby acknowledge and authorized the People's Multi-Purpose Cooperative (PMPC) for the following: 1) the regular submission and disclosure
B42: of my basic credit data (as defined under Republic Act Nr 9510 and its Implementing Rules and Regulations) to the Credit Information Corporation (CIC)
B43: as well as any updates or corrections thereof; and 2) the sharing of my basic data and with other lenders authorized by the CIC, and credit reporting
B44: agencies duly accredited by the CIC.
Y45: ='YADAO, MELENCIO'!D22 -> YADAO, MELENCIO C.
Y46: Printed Name & Signature of Borrower
B47: CERTIFICATION
C49: I hereby certify that the applicant is assigned to this Office; is not on leave without pay; has no pending case; and, that all information he/she
B50: provided is true and correct.
B53: CERTIFYING OFFICER | K53: DESIGNATION | T53: OFFICE | AB53: CONTACT NUMBER
...

Sheet Loan Form Back
V1: FOR VALUE RECEIVED, the undersigned promise to pay the People's Multi-Purpose Cooperative (PMPC) the sum of Php366,000.18, in (60) equal monthly installments amounting to Php each, to be paid on the 28 th day of every month starting on APRIL 2025/ Single Payment of _______________ due on _______________ unpaid installments from maturity will bear charges on unpaid principal at the rate of 2% per month as penalty thereof.
B2: PROMISORY NOTE NO: | P2: ='YADAO, MELENCIO'!H22 -> LRV-060
C3: FOR VALUE RECEIVED, the undersigned promise to pay the People's Multi-Purpose Cooperative (PMPC) the sum of Php
B4: ='YADAO, MELENCIO'!C3 -> 22799.949 | E4: in | F4: 24 | G4: equal monthly installments amounting to Php | T4: ='YADAO, MELENCIO'!C1 -> 949.99786 | V4: each, to be paid on the 28th day of every month starting on
B5: ='YADAO, MELENCIO'!B28 -> 46125 | F5: / Single Payment of due on unpaid installments from maturity will
B6: bear charges on unpaid principal at the rate of 2% per month as penatly thereof.
B7: I hereby waive presentment for payment and notice of dishonor. PMPC may accept partial payment reserving its right of recourse against me. PMPC is hereby authorized and empowered to set off or apply without notice what is due under this Note from whatever funds I have in the Cooperative.
B10: It is further agreed that in case of separation from the service of whatever cause, the unpaid balance with its accumulated surcharges and interest as stipulated above be deducted from my last paymnet, commutation of leave/furlough and/or from my pension.
B13: It is further agreed that when installments are not paid when due and payable, the whole of the principal sum remaining unpaid shall forthwith become due and payable at the election of the Cooperative. I promise and agree to pay for a reasonable attorney's fee if this note is not paid according to its legal tenor and effect when palced in a lawyer's hand for collection. In case litigation, venue shall be vested in the competent court as may be allowed by the Rules of Court at the sole option of PMPC.
B18: Further, I hereby agree and authorized PMPC to encumber, assign or sell to any person or entity any right which it may have under thi Note, and/or any assignment, mortgage lien, pledge or other encumbrances constituted in favor of PMPC pursuant to the provisions of this Note if any. The consent herein granted is recognized and acknowledged by me/us as a waiver, to all intent and purposes of whatever right I may have to notice of actual encumbrance/ assignment.
Q22: Military/Pensioners ID
Q23: Employee's ID/Office ID
Q24: Driver's License
D25: ='YADAO, MELENCIO'!D22 -> YADAO, MELENCIO C. | Q25: Others:
B26: Signature over Printed Name
B28: ID No: | D28: ='YADAO, MELENCIO'!D23 -> 716611
B29: Expiration Date: | Z29: LEFT THUMBMARK | AF29: RIGHT THUMBMARK
B32: ACKNOWLEDGEMENT
B34: REPUBLIC OF THE PHILIPPINES
B35: (20-E, 2nd Camarilla St., Cor. 15th Ave.,BRGY San Roque, Murphy Cubao, Quezon City) S.S
B37: BEFORE ME, a Notary Public for and in Cubao, Quezon City this _______ day of _______________, 20_____, personally appeared __________________
B38: __________, who presented to me the Identification Cards mentioned above, known to me to be the same person who executed the forgoing application for loan and promissory note and acknowledged that the same as his/her true act and deed and took oath that the statement herein are true and correct and that the application is made for the purpose under consideration.
C41: WITNESS MY HAND AND NOTARIAL SEAL, on the date, year and palce first above written.
B43: Doc No.
B44: Page No.
B45: Book No.
B46: Series of.
B48: AUTHORITY TO DEDUCT
C50: In connection with my loan described above, I hereby authorize the Finance/ Agent/ Disburing Officer of the AFP Finance Center, subdivision or
B51: instrumentality of the Government or any other office to which I may subsequently be detailed, assigned or appointed to deduct and /or withhold from my
B52: monthly payment of Php | H52: ='YADAO, MELENCIO'!C1 -> 949.99786 | M52: , for the period of | R52: 24 | T52: months with the total amount of Php | AC52: ='YADAO, MELENCIO'!C3 -> 22799.949 | AH52: has been fully paid.
C53: Likewise, I hereby authorize the above-mentioned official to deduct and/or withhold part of my pension, commutation, salary or any amount due me
B54: and my heirs for the payment of said loan together with the surcharges interest, if any, until the same have been paid in fully.
Q56: =D25 -> YADAO, MELENCIO C.
B57: (Signature of Borrower Over Printed Name)
B59: CERTIFICATION
C61: THIS IS TO CERTIFY that the applicant is under my paying jurisdiction and the amount stated above can be sufficiently deducted from monthly pay.
B62: I guarantee to deduct the amount as stipulated above and to remit the same to the Treasurer, PEOPLE'S MULTI-PURPOSE COOPERATIVE (PMCP) as soon
B63: as possible.
B65: (Signature of Finance/Agent/Disbursing Officer over Printed Name)
