Workbook

Sheet DATA ENTRY
B1: Editable
C3: 1 Yr | D3: 2 Yrs | E3: 3 Yrs | F3: 4 Yrs | G3: 5 Yrs
B4: GROSS AMOUNT | C4: ='Computation Table'!C108 -> 174984.11 | D4: ='Computation Table'!C82 -> 127991.37 | E4: ='Computation Table'!C56 -> 601062.61 | F4: ='Computation Table'!C29 -> 649762.37 | G4: ='Computation Table'!C3 -> 629999.88
B5: NET PROCEEDS | C5: 152000 | D5: 100000 | E5: 443817.41 | F5: 444037 | G5: 388616
B6: Add:
B7: Previous Loan Balance
B8: Service Fee | C8: ='Computation Table'!C110 -> 10640 | D8: ='Computation Table'!C84 -> 7500 | E8: ='Computation Table'!C58 -> 39943.567 | F8: ='Computation Table'!C31 -> 39963.33 | G8: ='Computation Table'!C5 -> 47022.536
B9: Insurance | C9: ='Computation Table'!C111 -> 1824 | D9: ='Computation Table'!C85 -> 2400 | E9: ='Computation Table'!C59 -> 15977.427 | F9: ='Computation Table'!C32 -> 21313.776 | G9: ='Computation Table'!C6 -> 23316.96
B10: CapCon | D10: 5000 | E10: 10000 | F10: 10000 | G10: 5000
B11: membership fee | E11: 300 | F11: 300 | G11: 300
B12: Advance Interest | C12: ='Computation Table'!C114 -> 2280 | D12: ='Computation Table'!C88 -> 1541.6667 | E12: ='Computation Table'!C62 -> 7396.9568 | F12: ='Computation Table'!C35 -> 8140.6783 | G12: ='Computation Table'!C9 -> 7772.32
B13: LOAN AMOUNT | C13: =SUM(C5:C11) -> 164464 | D13: =SUM(D5:D12) -> 116441.67 | E13: =SUM(E5:E12) -> 517435.36 | F13: =SUM(F5:F12) -> 523754.78 | G13: =SUM(G5:G12) -> 472027.82 | J13: 352669.13 | K13: 91376.87
B14: Annual Interest Rate | C14: ='Computation Table'!C116 -> 0.09 | D14: ='Computation Table'!C90 -> 0.0925 | E14: ='Computation Table'!C64 -> 0.1 | F14: ='Computation Table'!C37 -> 0.11 | G14: ='Computation Table'!C11 -> 0.12 | K14: =J13+K13 -> 444046
B15: Effective Interest Rate | C15: ='Computation Table'!C117 -> 0.093806898 | D15: ='Computation Table'!F91 -> 0.096718129 | E15: ='Computation Table'!F65 -> 0.10501772 | F15: ='Computation Table'!C38 -> 0.1161376 | G15: ='Computation Table'!C12 -> 0.12736174
B16: Monthly Amortization | C16: ='Computation Table'!C126 -> 14582.009 | D16: ='Computation Table'!C100 -> 5332.9739 | E16: ='Computation Table'!C74 -> 16696.184 | F16: ='Computation Table'!C47 -> 13536.716 | G16: ='Computation Table'!C21 -> 10499.998

Sheet Amortization  Table
B1: PEOPLE'S MULTI-PURPOSE COOPERATIVE EFFECTIVE ON JANUARY 16, 2025
B4: AFP LOAN TABLE - BUY OUT
B5: Net Proceeds | C5: 1 Yr 12 Months | D5: 2 Yrs 24 Months | E5: 3 Yrs 36 Months | F5: 4 Yrs 48 Months | G5: 5 Yrs 60 Months
B7: 25000 | C7: ='Computation Table'!E126 -> 2398.3568 | D7: ='Computation Table'!C100 -> 5332.9739 | E7: ='Computation Table'!E74 -> 913.69918 | F7: ='Computation Table'!E47 -> 735.30512 | G7: ='Computation Table'!E21 -> 667.88954
B8: 50000 | C8: ='Computation Table'!F126 -> 4796.7135 | D8: ='Computation Table'!F100 -> 2780.9858 | E8: ='Computation Table'!F74 -> 2159.7504 | F8: ='Computation Table'!F47 -> 1736.8191 | G8: ='Computation Table'!F21 -> 1453.6747
B9: 75000 | C9: ='Computation Table'!G126 -> 7195.0703 | D9: ='Computation Table'!G100 -> 3827.9822 | E9: ='Computation Table'!G74 -> 2741.0976 | F9: ='Computation Table'!G47 -> 2205.9154 | G9: ='Computation Table'!G21 -> 2003.6686
B10: 100000 | C10: ='Computation Table'!H126 -> 9593.427 | D10: ='Computation Table'!H100 -> 5332.9739 | E10: ='Computation Table'!H74 -> 3987.1488 | F10: ='Computation Table'!H47 -> 3207.4294 | G10: ='Computation Table'!H21 -> 2789.4537
B11: 150000 | C11: ='Computation Table'!J126 -> 14390.141 | D11: ='Computation Table'!J100 -> 7884.962 | E11: ='Computation Table'!J74 -> 5814.5471 | F11: ='Computation Table'!J47 -> 4678.0396 | G11: ='Computation Table'!J21 -> 4125.2328
B12: 200000 | C12: ='Computation Table'!L126 -> 19186.854 | D12: ='Computation Table'!L100 -> 10436.95 | E12: ='Computation Table'!L74 -> 7641.9455 | F12: ='Computation Table'!L47 -> 6148.6498 | G12: ='Computation Table'!L21 -> 5461.0119
B13: 250000 | C13: ='Computation Table'!N126 -> 23983.568 | D13: ='Computation Table'!N100 -> 12988.938 | E13: ='Computation Table'!N74 -> 9469.3439 | F13: ='Computation Table'!N47 -> 7619.2601 | G13: ='Computation Table'!N21 -> 6796.791
B14: 300000 | C14: ='Computation Table'!P126 -> 28780.281 | D14: ='Computation Table'!P100 -> 15540.926 | E14: ='Computation Table'!P74 -> 11296.742 | F14: ='Computation Table'!P47 -> 9089.8703 | G14: ='Computation Table'!P21 -> 8132.5701
B15: 350000 | C15: ='Computation Table'!R126 -> 33576.995 | D15: ='Computation Table'!R100 -> 18092.914 | E15: ='Computation Table'!R74 -> 13124.141 | F15: ='Computation Table'!R47 -> 10560.481 | G15: ='Computation Table'!R21 -> 9468.3492
B16: 400000 | C16: ='Computation Table'!T126 -> 38373.708 | D16: ='Computation Table'!T100 -> 20644.902 | E16: ='Computation Table'!T74 -> 14951.539 | F16: ='Computation Table'!T47 -> 12031.091 | G16: ='Computation Table'!T21 -> 10804.128
B17: 450000 | C17: ='Computation Table'!V126 -> 43170.422 | D17: ='Computation Table'!V100 -> 23196.891 | E17: ='Computation Table'!V74 -> 16778.937 | F17: ='Computation Table'!V47 -> 13501.701 | G17: ='Computation Table'!V21 -> 12139.907
B18: 500000 | C18: ='Computation Table'!X126 -> 47967.135 | D18: ='Computation Table'!X100 -> 25748.879 | E18: ='Computation Table'!X74 -> 18606.336 | F18: ='Computation Table'!X47 -> 14972.311 | G18: ='Computation Table'!X21 -> 13353.342
B19: 550000 | C19: ='Computation Table'!Z126 -> 52763.849 | D19: ='Computation Table'!Z100 -> 28300.867 | E19: ='Computation Table'!Z74 -> 20433.734 | F19: ='Computation Table'!Z47 -> 16442.921 | G19: ='Computation Table'!Z21 -> 14811.465
B20: 600000 | C20: ='Computation Table'!AB126 -> 57560.562 | D20: ='Computation Table'!AB100 -> 30852.855 | E20: ='Computation Table'!AB74 -> 22261.132 | F20: ='Computation Table'!AB47 -> 17913.532 | G20: ='Computation Table'!AB21 -> 16147.245
B21: 650000 | C21: ='Computation Table'!AD126 -> 62357.276 | D21: ='Computation Table'!AD100 -> 33404.843 | E21: ='Computation Table'!AD74 -> 24088.531 | F21: ='Computation Table'!AD47 -> 19384.142 | G21: ='Computation Table'!AD21 -> 17483.024
B22: 700000 | C22: ='Computation Table'!AF126 -> 67153.989 | D22: ='Computation Table'!AF100 -> 35956.831 | E22: ='Computation Table'!AF74 -> 25915.929 | F22: ='Computation Table'!AF47 -> 20854.752 | G22: ='Computation Table'!AF21 -> 18818.803
B23: 750000 | C23: ='Computation Table'!AH126 -> 71950.703 | D23: ='Computation Table'!AH100 -> 38508.819 | E23: ='Computation Table'!AH74 -> 27743.328 | F23: ='Computation Table'!AH47 -> 22325.362 | G23: ='Computation Table'!AH21 -> 20154.582
B24: 800000 | C24: ='Computation Table'!AJ126 -> 76747.416 | D24: ='Computation Table'!AJ100 -> 41060.807 | E24: ='Computation Table'!AJ74 -> 29570.726 | F24: ='Computation Table'!AJ47 -> 23795.973 | G24: ='Computation Table'!AJ21 -> 21490.361
B25: 850000 | C25: ='Computation Table'!AL126 -> 81544.13 | D25: ='Computation Table'!AL100 -> 43612.795 | E25: ='Computation Table'!AL74 -> 31398.124 | F25: ='Computation Table'!AL47 -> 25266.583 | G25: ='Computation Table'!AL21 -> 22826.14
B26: 900000 | C26: ='Computation Table'!AN126 -> 86340.843 | D26: ='Computation Table'!AN100 -> 46164.784 | E26: ='Computation Table'!AN74 -> 33225.523 | F26: ='Computation Table'!AN47 -> 26737.193 | G26: ='Computation Table'!AN21 -> 24161.919
B27: 950000 | C27: ='Computation Table'!AP126 -> 91137.557 | D27: ='Computation Table'!AP100 -> 48716.772 | E27: ='Computation Table'!AP74 -> 35052.921 | F27: ='Computation Table'!AP47 -> 28207.803 | G27: ='Computation Table'!AP21 -> 25497.698
B28: 1000000 | C28: ='Computation Table'!AR126 -> 95934.27 | D28: ='Computation Table'!AR100 -> 51268.76 | E28: ='Computation Table'!AR74 -> 36880.319 | F28: ='Computation Table'!AR47 -> 29678.414 | G28: ='Computation Table'!AR21 -> 26588.788

Sheet Computation Table
B2: 5 Yrs
B3: GROSS | C3: =C21*C15 -> 629999.88 | E3: =E21*E15 -> 40073.373 | F3: =F21*F15 -> 87220.479 | G3: =G21*G15 -> 120220.12 | H3: =H21*H15 -> 167367.22 | I3: =I21*I15 -> 200366.86 | J3: =J21*J15 -> 247513.97 | K3: =K21*K15 -> 280513.61 | L3: =L21*L15 -> 327660.71 | ... AR3: =AR21*AR15 -> 1595327.3
B4: NET | C4: ='DATA ENTRY'!G5 -> 388616 | E4: 25000 | F4: 50000 | G4: 75000 | H4: 100000 | I4: 125000 | J4: 150000 | K4: 175000 | L4: 200000 | M4: 225000 | N4: 250000 | O4: 275000 | P4: 300000 | Q4: 325000 | R4: 350000 | S4: 375000 | T4: 400000 | U4: 425000 | V4: 450000 | W4: 475000 | X4: 500000 | Y4: 525000 | Z4: 550000 | AA4: 575000 | AB4: 600000 | AC4: 625000 | AD4: 650000 | AE4: 675000 | AF4: 700000 | AG4: 725000 | AH4: 750000 | AI4: 775000 | AJ4: 800000 | AK4: 825000 | AL4: 850000 | AM4: 875000 | AN4: 900000 | AO4: 925000 | AP4: 950000 | AQ4: 975000 | AR4: 1000000
B5: SF | C5: =C4*0.121 -> 47022.536 | E5: =E4*0.121 -> 3025 | F5: =F4*0.121 -> 6050 | G5: =G4*0.121 -> 9075 | H5: =H4*0.121 -> 12100 | I5: =I4*0.121 -> 15125 | J5: =J4*0.121 -> 18150 | K5: =K4*0.121 -> 21175 | L5: =L4*0.121 -> 24200 | ... W5: =W4*0.121 -> 57475 | X5: =X4*0.11 -> 55000 | Y5: =Y4*0.121 -> 63525 | Z5: =Z4*0.121 -> 66550 | AA5: =AA4*0.121 -> 69575 | AB5: =AB4*0.121 -> 72600 | AC5: =AC4*0.121 -> 75625 | AD5: =AD4*0.121 -> 78650 | AE5: =AE4*0.121 -> 81675 | AF5: =AF4*0.121 -> 84700 | ... AQ5: =AQ4*0.121 -> 117975 | AR5: =AR4*0.11 -> 110000
B6: Insurance | C6: =(C4/1000)*C15 -> 23316.96 | E6: =(E4/1000)*E15 -> 1500 | F6: =(F4/1000)*F15 -> 3000 | G6: =(G4/1000)*G15 -> 4500 | H6: =(H4/1000)*H15 -> 6000 | I6: =(I4/1000)*I15 -> 7500 | J6: =(J4/1000)*J15 -> 9000 | K6: =(K4/1000)*K15 -> 10500 | L6: =(L4/1000)*L15 -> 12000 | ... AR6: =(AR4/1000)*AR15 -> 60000
B7: CapCon | C7: ='DATA ENTRY'!G10 -> 5000 | F7: =C7 -> 5000 | G7: =E7 -> 0 | H7: =F7 -> 5000 | I7: =G7 -> 0 | J7: =H7 -> 5000 | K7: =I7 -> 0 | L7: =J7 -> 5000 | M7: =K7 -> 0 | N7: =L7 -> 5000 | ... AR7: =AP7 -> 5000
B8: membership fee | C8: ='DATA ENTRY'!G11 -> 300 | F8: =C8 -> 300 | G8: =E8 -> 0 | H8: =F8 -> 300 | I8: =G8 -> 0 | J8: =H8 -> 300 | K8: =I8 -> 0 | L8: =J8 -> 300 | M8: =K8 -> 0 | N8: =L8 -> 300 | ... AR8: =AP8 -> 300
B9: Advance Interest | C9: =C14*C4*2 -> 7772.32 | E9: =E14*E4*2 -> 500 | F9: =F14*F4*2 -> 1000 | G9: =G14*G4*2 -> 1500 | H9: =H14*H4*2 -> 2000 | I9: =I14*I4*2 -> 2500 | J9: =J14*J4*2 -> 3000 | K9: =K14*K4*2 -> 3500 | L9: =L14*L4*2 -> 4000 | ... AR9: =AR14*AR4*2 -> 20000
B10: LOAN AMOUNT | C10: =SUM(C4:C9) -> 472027.82 | E10: =SUM(E4:E9) -> 30025 | F10: =SUM(F4:F9) -> 65350 | G10: =SUM(G4:G9) -> 90075 | H10: =SUM(H4:H9) -> 125400 | I10: =SUM(I4:I9) -> 150125 | J10: =SUM(J4:J9) -> 185450 | K10: =SUM(K4:K9) -> 210175 | L10: =SUM(L4:L9) -> 245500 | ... AR10: =SUM(AR4:AR9) -> 1195300
B11: Annual Interest | C11: 0.12 | E11: =C11 -> 0.12 | F11: =C11 -> 0.12 | G11: =F11 -> 0.12 | H11: =G11 -> 0.12 | I11: =H11 -> 0.12 | J11: =I11 -> 0.12 | K11: =J11 -> 0.12 | L11: =K11 -> 0.12 | M11: =L11 -> 0.12 | N11: =M11 -> 0.12 | ... X11: =W11 -> 0.12 | Y11: =W11 -> 0.12 | Z11: =Y11 -> 0.12 | AA11: =Z11 -> 0.12 | AB11: =AA11 -> 0.12 | AC11: =AB11 -> 0.12 | AD11: =AC11 -> 0.12 | AE11: =AD11 -> 0.12 | AF11: =AE11 -> 0.12 | AG11: =AF11 -> 0.12 | ... AR11: =AQ11 -> 0.12
B12: Effective Interest rate | C12: =(1+C11/C15)^C15-1 -> 0.12736174 | E12: =(1+E11/E15)^E15-1 -> 0.12736174 | F12: =(1+F11/F15)^F15-1 -> 0.12736174 | G12: =(1+G11/G15)^G15-1 -> 0.12736174 | H12: =(1+H11/H15)^H15-1 -> 0.12736174 | I12: =(1+I11/I15)^I15-1 -> 0.12736174 | J12: =(1+J11/J15)^J15-1 -> 0.12736174 | K12: =(1+K11/K15)^K15-1 -> 0.12736174 | L12: =(1+L11/L15)^L15-1 -> 0.12736174 | ... AR12: =(1+AR11/AR15)^AR15-1 -> 0.12736174
B13: Loan Term | C13: 5 | E13: 5 | F13: 5 | G13: 5 | H13: 5 | I13: 5 | J13: 5 | K13: 5 | L13: 5 | M13: 5 | N13: 5 | O13: 5 | P13: 5 | Q13: 5 | R13: 5 | S13: 5 | T13: =P13 -> 5 | U13: =Q13 -> 5 | V13: =R13 -> 5 | W13: =S13 -> 5 | X13: =T13 -> 5 | Y13: =U13 -> 5 | Z13: =V13 -> 5 | AA13: =W13 -> 5 | ... AR13: =AN13 -> 5
B14: Monthly Interest Rate | C14: =C11/12 -> 0.01 | E14: =E11/12 -> 0.01 | F14: =F11/12 -> 0.01 | G14: =G11/12 -> 0.01 | H14: =H11/12 -> 0.01 | I14: =I11/12 -> 0.01 | J14: =J11/12 -> 0.01 | K14: =K11/12 -> 0.01 | L14: =L11/12 -> 0.01 | ... AR14: =AR11/12 -> 0.01
B15: Nr of Payments | C15: =C13*12 -> 60 | E15: =E13*12 -> 60 | F15: =F13*12 -> 60 | G15: =G13*12 -> 60 | H15: =H13*12 -> 60 | I15: =I13*12 -> 60 | J15: =J13*12 -> 60 | K15: =K13*12 -> 60 | L15: =L13*12 -> 60 | ... AR15: =AR13*12 -> 60
B17: Monthly Amortization | C17: =(1+C14)^C15 -> 1.8166967 | E17: =(1+E14)^E15 -> 1.8166967 | F17: =(1+F14)^F15 -> 1.8166967 | G17: =(1+G14)^G15 -> 1.8166967 | H17: =(1+H14)^H15 -> 1.8166967 | I17: =(1+I14)^I15 -> 1.8166967 | J17: =(1+J14)^J15 -> 1.8166967 | K17: =(1+K14)^K15 -> 1.8166967 | L17: =(1+L14)^L15 -> 1.8166967 | ... AR17: =(1+AR14)^AR15 -> 1.8166967
C18: =C17*C14 -> 0.018166967 | E18: =E17*E14 -> 0.018166967 | F18: =F17*F14 -> 0.018166967 | G18: =G17*G14 -> 0.018166967 | H18: =H17*H14 -> 0.018166967 | I18: =I17*I14 -> 0.018166967 | J18: =J17*J14 -> 0.018166967 | K18: =K17*K14 -> 0.018166967 | L18: =L17*L14 -> 0.018166967 | ... AR18: =AR17*AR14 -> 0.018166967
C19: =C17-1 -> 0.8166967 | E19: =E17-1 -> 0.8166967 | F19: =F17-1 -> 0.8166967 | G19: =G17-1 -> 0.8166967 | H19: =H17-1 -> 0.8166967 | I19: =I17-1 -> 0.8166967 | J19: =J17-1 -> 0.8166967 | K19: =K17-1 -> 0.8166967 | L19: =L17-1 -> 0.8166967 | ... AR19: =AR17-1 -> 0.8166967
C20: =C18/C19 -> 0.022244448 | E20: =E18/E19 -> 0.022244448 | F20: =F18/F19 -> 0.022244448 | G20: =G18/G19 -> 0.022244448 | H20: =H18/H19 -> 0.022244448 | I20: =I18/I19 -> 0.022244448 | J20: =J18/J19 -> 0.022244448 | K20: =K18/K19 -> 0.022244448 | L20: =L18/L19 -> 0.022244448 | ... AR20: =AR18/AR19 -> 0.022244448
B21: Monthly Amortization | C21: =C20*C10 -> 10499.998 | E21: =E20*E10 -> 667.88954 | F21: =F20*F10 -> 1453.6747 | G21: =G20*G10 -> 2003.6686 | H21: =H20*H10 -> 2789.4537 | I21: =I20*I10 -> 3339.4477 | J21: =J20*J10 -> 4125.2328 | K21: =K20*K10 -> 4675.2268 | L21: =L20*L10 -> 5461.0119 | ... AR21: =AR20*AR10 -> 26588.788
B23: Income | C23: =C3-C4 -> 241383.88 | E23: =E3-E4 -> 15073.373 | F23: =F3-F4 -> 37220.479 | G23: =G3-G4 -> 45220.118 | H23: =H3-H4 -> 67367.224 | I23: =I3-I4 -> 75366.863 | J23: =J3-J4 -> 97513.969 | K23: =K3-K4 -> 105513.61 | L23: =L3-L4 -> 127660.71 | ... AR23: =AR3-AR4 -> 595327.3
B24: % Income | C24: =C23/C3 -> 0.38314909 | E24: =E23/E3 -> 0.37614435 | F24: =F23/F3 -> 0.42674014 | G24: =G23/G3 -> 0.37614435 | H24: =H23/H3 -> 0.40251145 | I24: =I23/I3 -> 0.37614435 | J24: =J23/J3 -> 0.3939736 | K24: =K23/K3 -> 0.37614435 | L24: =L23/L3 -> 0.38961251 | ... AR24: =AR23/AR3 -> 0.37316938
B28: 4 yrs
B29: GROSS | C29: =C47*C41 -> 649762.37 | E29: =E47*E41 -> 35294.646 | F29: =F47*F41 -> 83367.318 | G29: =G47*G41 -> 105883.94 | H29: =H47*H41 -> 153956.61 | I29: =I47*I41 -> 176473.23 | J29: =J47*J41 -> 224545.9 | K29: =K47*K41 -> 247062.52 | L29: =L47*L41 -> 295135.19 | ... AR29: =AR47*AR41 -> 1424563.9
B30: NET | C30: ='DATA ENTRY'!F5 -> 444037 | E30: 25000 | F30: 50000 | G30: 75000 | H30: 100000 | I30: 125000 | J30: 150000 | K30: 175000 | L30: 200000 | M30: 225000 | N30: 250000 | O30: 275000 | P30: 300000 | Q30: 325000 | R30: 350000 | S30: 375000 | T30: 400000 | U30: 425000 | V30: 450000 | W30: 475000 | X30: 500000 | Y30: 525000 | Z30: 550000 | AA30: 575000 | AB30: 600000 | AC30: 625000 | AD30: 650000 | AE30: 675000 | AF30: 700000 | AG30: 725000 | AH30: 750000 | AI30: 775000 | AJ30: 800000 | AK30: 825000 | AL30: 850000 | AM30: 875000 | AN30: 900000 | AO30: 925000 | AP30: 950000 | AQ30: 975000 | AR30: 1000000
B31: SF | C31: =C30*0.09 -> 39963.33 | D31: =D30*0.09 -> 0 | E31: =E30*0.09 -> 2250 | F31: =F30*0.09 -> 4500 | G31: =G30*0.09 -> 6750 | H31: =H30*0.09 -> 9000 | I31: =I30*0.09 -> 11250 | J31: =J30*0.09 -> 13500 | ... AR31: =AR30*0.09 -> 90000
B32: Insurance | C32: =(C30/1000)*C41 -> 21313.776 | E32: =(E30/1000)*E41 -> 1200 | F32: =(F30/1000)*F41 -> 2400 | G32: =(G30/1000)*G41 -> 3600 | H32: =(H30/1000)*H41 -> 4800 | I32: =(I30/1000)*I41 -> 6000 | J32: =(J30/1000)*J41 -> 7200 | K32: =(K30/1000)*K41 -> 8400 | L32: =(L30/1000)*L41 -> 9600 | ... AR32: =(AR30/1000)*AR41 -> 48000
B33: CapCon | C33: ='DATA ENTRY'!F10 -> 10000 | F33: =C33 -> 10000 | G33: =E33 -> 0 | H33: =F33 -> 10000 | I33: =G33 -> 0 | J33: =H33 -> 10000 | K33: =I33 -> 0 | L33: =J33 -> 10000 | M33: =K33 -> 0 | N33: =L33 -> 10000 | ... AR33: =AP33 -> 10000
B34: membership fee | C34: ='DATA ENTRY'!F11 -> 300 | F34: =C34 -> 300 | G34: =E34 -> 0 | H34: =F34 -> 300 | I34: =G34 -> 0 | J34: =H34 -> 300 | K34: =I34 -> 0 | L34: =J34 -> 300 | M34: =K34 -> 0 | N34: =L34 -> 300 | ... AR34: =AP34 -> 300
B35: Advance Interest | C35: =C40*C30*2 -> 8140.6783 | E35: =E40*E30*2 -> 458.33333 | F35: =F40*F30*2 -> 916.66667 | G35: =G40*G30*2 -> 1375 | H35: =H40*H30*2 -> 1833.3333 | I35: =I40*I30*2 -> 2291.6667 | J35: =J40*J30*2 -> 2750 | K35: =K40*K30*2 -> 3208.3333 | L35: =L40*L30*2 -> 3666.6667 | ... AR35: =AR40*AR30*2 -> 18333.333
B36: LOAN AMOUNT | C36: =SUM(C30:C35) -> 523754.78 | E36: =SUM(E30:E34) -> 28450 | F36: =SUM(F30:F34) -> 67200 | G36: =SUM(G30:G34) -> 85350 | H36: =SUM(H30:H34) -> 124100 | I36: =SUM(I30:I34) -> 142250 | J36: =SUM(J30:J34) -> 181000 | K36: =SUM(K30:K34) -> 199150 | L36: =SUM(L30:L34) -> 237900 | ... AR36: =SUM(AR30:AR34) -> 1148300
B37: Annual Interest | C37: 0.11 | E37: =C37 -> 0.11 | F37: =C37 -> 0.11 | G37: =F37 -> 0.11 | H37: =F37 -> 0.11 | I37: =G37 -> 0.11 | J37: =H37 -> 0.11 | K37: =I37 -> 0.11 | L37: =J37 -> 0.11 | M37: =K37 -> 0.11 | N37: =L37 -> 0.11 | O37: =M37 -> 0.11 | ... AR37: =AP37 -> 0.11
B38: Effective Interest rate | C38: =(1+C37/C41)^C41-1 -> 0.1161376 | E38: =(1+E37/E41)^E41-1 -> 0.1161376 | F38: =(1+F37/F41)^F41-1 -> 0.1161376 | G38: =(1+G37/G41)^G41-1 -> 0.1161376 | H38: =(1+H37/H41)^H41-1 -> 0.1161376 | I38: =(1+I37/I41)^I41-1 -> 0.1161376 | J38: =(1+J37/J41)^J41-1 -> 0.1161376 | K38: =(1+K37/K41)^K41-1 -> 0.1161376 | L38: =(1+L37/L41)^L41-1 -> 0.1161376 | ... AR38: =(1+AR37/AR41)^AR41-1 -> 0.1161376
B39: Loan Term | C39: 4 | E39: 4 | F39: 4 | G39: 4 | H39: 4 | I39: 4 | J39: 4 | K39: 4 | L39: =H39 -> 4 | M39: =I39 -> 4 | N39: =K39 -> 4 | O39: =K39 -> 4 | P39: =L39 -> 4 | Q39: =M39 -> 4 | R39: =N39 -> 4 | S39: =O39 -> 4 | T39: =P39 -> 4 | U39: =Q39 -> 4 | V39: =R39 -> 4 | ... AR39: =AN39 -> 4
B40: Monthly Interest Rate | C40: =C37/12 -> 0.0091666667 | E40: =E37/12 -> 0.0091666667 | F40: =F37/12 -> 0.0091666667 | G40: =G37/12 -> 0.0091666667 | H40: =H37/12 -> 0.0091666667 | I40: =I37/12 -> 0.0091666667 | J40: =J37/12 -> 0.0091666667 | K40: =K37/12 -> 0.0091666667 | L40: =L37/12 -> 0.0091666667 | ... AR40: =AR37/12 -> 0.0091666667
B41: Nr of Payments | C41: =C39*12 -> 48 | E41: =E39*12 -> 48 | F41: =F39*12 -> 48 | G41: =G39*12 -> 48 | H41: =H39*12 -> 48 | I41: =I39*12 -> 48 | J41: =J39*12 -> 48 | K41: =K39*12 -> 48 | L41: =L39*12 -> 48 | ... AR41: =AR39*12 -> 48
B43: Monthly Amortization | C43: =(1+C40)^C41 -> 1.549598 | E43: =(1+E40)^E41 -> 1.549598 | F43: =(1+F40)^F41 -> 1.549598 | G43: =(1+G40)^G41 -> 1.549598 | H43: =(1+H40)^H41 -> 1.549598 | I43: =(1+I40)^I41 -> 1.549598 | J43: =(1+J40)^J41 -> 1.549598 | K43: =(1+K40)^K41 -> 1.549598 | L43: =(1+L40)^L41 -> 1.549598 | ... AR43: =(1+AR40)^AR41 -> 1.549598
C44: =C43*C40 -> 0.014204649 | E44: =E43*E40 -> 0.014204649 | F44: =F43*F40 -> 0.014204649 | G44: =G43*G40 -> 0.014204649 | H44: =H43*H40 -> 0.014204649 | I44: =I43*I40 -> 0.014204649 | J44: =J43*J40 -> 0.014204649 | K44: =K43*K40 -> 0.014204649 | L44: =L43*L40 -> 0.014204649 | ... AR44: =AR43*AR40 -> 0.014204649
C45: =C43-1 -> 0.54959805 | E45: =E43-1 -> 0.54959805 | F45: =F43-1 -> 0.54959805 | G45: =G43-1 -> 0.54959805 | H45: =H43-1 -> 0.54959805 | I45: =I43-1 -> 0.54959805 | J45: =J43-1 -> 0.54959805 | K45: =K43-1 -> 0.54959805 | L45: =L43-1 -> 0.54959805 | ... AR45: =AR43-1 -> 0.54959805
C46: =C44/C45 -> 0.025845523 | E46: =E44/E45 -> 0.025845523 | F46: =F44/F45 -> 0.025845523 | G46: =G44/G45 -> 0.025845523 | H46: =H44/H45 -> 0.025845523 | I46: =I44/I45 -> 0.025845523 | J46: =J44/J45 -> 0.025845523 | K46: =K44/K45 -> 0.025845523 | L46: =L44/L45 -> 0.025845523 | ... AR46: =AR44/AR45 -> 0.025845523
B47: Monthly Amortization | C47: =C46*C36 -> 13536.716 | E47: =E46*E36 -> 735.30512 | F47: =F46*F36 -> 1736.8191 | G47: =G46*G36 -> 2205.9154 | H47: =H46*H36 -> 3207.4294 | I47: =I46*I36 -> 3676.5256 | J47: =J46*J36 -> 4678.0396 | K47: =K46*K36 -> 5147.1358 | L47: =L46*L36 -> 6148.6498 | ... AR47: =AR46*AR36 -> 29678.414
...

Sheet 2 years
A1: \ | B1: Amortization | C1: ='DATA ENTRY'!D16 -> 5332.9739
B2: Timeline | C2: 0 | D2: 1 | E2: 2 | F2: 3 | G2: 4 | H2: 5 | I2: 6 | J2: 7 | K2: 8 | L2: 9 | M2: 10 | N2: 11 | O2: 12 | P2: 13 | Q2: 14 | R2: 15 | S2: 16 | T2: 17 | U2: 18 | V2: 19 | W2: 20 | X2: 21 | Y2: 22 | Z2: 23 | AA2: 24
B3: GROSS AMOUNT | C3: ='DATA ENTRY'!D4 -> 127991.37
B4: LOAN AMOUNT | C4: ='DATA ENTRY'!D13 -> 116441.67 | D4: =-$C1 -> -5332.9739 | E4: =-$C1 -> -5332.9739 | F4: =-$C1 -> -5332.9739 | G4: =-$C1 -> -5332.9739 | H4: =-$C1 -> -5332.9739 | I4: =-$C1 -> -5332.9739 | J4: =-$C1 -> -5332.9739 | K4: =-$C1 -> -5332.9739 | ... AA4: =-$C1 -> -5332.9739
B5: Service Fee | C5: ='DATA ENTRY'!D8 -> 7500
B6: Insurance | C6: ='DATA ENTRY'!D9 -> 2400
B7: CapCon | C7: ='DATA ENTRY'!D10 -> 5000
B8: membership fee | C8: ='DATA ENTRY'!D11 -> 0
B9: Advance Interest | C9: ='DATA ENTRY'!D12 -> 1541.6667
B10: NET PROCEEDS/CASH FLOW | C10: =C4-C5-C6-C7-C8-C9 -> 100000
B12: Interest Rate of Return | C12: =IRR(C4:AA4) -> 0.0077083333 | D12: =C12/5 -> 0.0015416667
B14: Loan Balance
B15: Monthly Interest Rate | C15: ='DATA ENTRY'!D14/12 -> 0.0077083333
B16: Effective Interest Rate | C16: ='DATA ENTRY'!D15 -> 0.096718129 | K16: APPROVED
C20: LOAN LEDGER CARD
C22: Name: | D22: MARIA CRISELDA G. MACAPILI | G22: Loan Voucher No. | H22: LV-052
C23: Serial Nr: | D23: 734219 | E23: Address: | F23: PUROK 3 ,DAET, CAMARINEZ NORTE | G23: Amount: | H23: =C10-C14 -> 100000
C24: Posting date | D24: Date of Loan: | E24: 45915 | F24: Maturity Date | G24: =B51 -> 46675 | K24: PEOPLE'S MULTI-PURPOSE COOPERATIVE
D25: Term: | E25: 24 | F25: MOS | K25: 20-E 2nd Camarilla St. corner 15th Ave., Brgy. San Roque, Murphy Cubao, Quezon City | X25: 20-E 2nd Camarilla St corner 15th Avenue,
D26: Loan | E26: Installment | F26: Principal | G26: EIR | H26: Balance | X26: Brgy San Roque, Murphy Cubao, Quezon City
D27: Month 0 | H27: =C4 -> 116441.67 | K27: LOAN RELEASE VOUCHER | X27: Mobile No. (+63)953-033-1580 (GLOBE)
B28: =DATE(YEAR(E$24),MONTH(E$24)+D28+1,DAY(E$24)) -> 45976 | C28: =TEXT(B28,"mmm-yyyy") -> Nov-2025 | D28: 1 | E28: =C$1 -> 5332.9739 | F28: =E28-G28 -> 4435.4027 | G28: =H27*C$12 -> 897.57118 | H28: =H27-F28 -> 112006.26
B29: =DATE(YEAR(E$24),MONTH(E$24)+D29+1,DAY(E$24)) -> 46006 | C29: =TEXT(B29,"mmm-yyyy") -> Dec-2025 | D29: 2 | E29: =C$1 -> 5332.9739 | F29: =E29-G29 -> 4469.5923 | G29: =H28*C$12 -> 863.38162 | H29: =H28-F29 -> 107536.67 | R29: Date: | S29: =E24 -> 45915 | X29: LOAN APPLICATION FORM
B30: =DATE(YEAR(E$24),MONTH(E$24)+D30+1,DAY(E$24)) -> 46037 | C30: =TEXT(B30,"mmm-yyyy") -> Jan-2026 | D30: 3 | E30: =C$1 -> 5332.9739 | F30: =E30-G30 -> 4504.0454 | G30: =H29*C$12 -> 828.92851 | H30: =H29-F30 -> 103032.63 | R30: LV No: | S30: =H22 -> LV-052 | AU30: Date: | AW30: 0 | AX30: 9 | AY30: 1 | AZ30: 5 | BA30: 2 | BB30: 0 | BC30: 2 | BD30: 5
B31: =DATE(YEAR(E$24),MONTH(E$24)+D31+1,DAY(E$24)) -> 46068 | C31: =TEXT(B31,"mmm-yyyy") -> Feb-2026 | D31: 4 | E31: =C$1 -> 5332.9739 | F31: =E31-G31 -> 4538.764 | G31: =H30*C$12 -> 794.20983 | H31: =H30-F31 -> 98493.862 | AW31: m | AX31: m | AY31: d | AZ31: d | BA31: y | BB31: y | BC31: y | BD31: y
B32: =DATE(YEAR(E$24),MONTH(E$24)+D32+1,DAY(E$24)) -> 46096 | C32: =TEXT(B32,"mmm-yyyy") -> Mar-2026 | D32: 5 | E32: =C$1 -> 5332.9739 | F32: =E32-G32 -> 4573.7503 | G32: =H31*C$12 -> 759.22352 | H32: =H31-F32 -> 93920.112 | K32: Name of Borrower: | N32: =D22 -> MARIA CRISELDA G. MACAPILI | X32: APPLICATION TYPE | AE32: LOAN CLASSIFICATION | AM32: TERM | AT32: RELEASE OF LOAN PROCEEDS
B33: =DATE(YEAR(E$24),MONTH(E$24)+D33+1,DAY(E$24)) -> 46127 | C33: =TEXT(B33,"mmm-yyyy") -> Apr-2026 | D33: 6 | E33: =C$1 -> 5332.9739 | F33: =E33-G33 -> 4609.0063 | G33: =H32*C$12 -> 723.96753 | H33: =H32-F33 -> 89311.106 | K33: Serial No.: | N33: =D23 -> 734219 | Y33: New | AF33: Salary Loan | AN33: 12 Months | AU33: Check
B34: =DATE(YEAR(E$24),MONTH(E$24)+D34+1,DAY(E$24)) -> 46157 | C34: =TEXT(B34,"mmm-yyyy") -> May-2026 | D34: 7 | E34: =C$1 -> 5332.9739 | F34: =E34-G34 -> 4644.5341 | G34: =H33*C$12 -> 688.43977 | H34: =H33-F34 -> 84666.572 | K34: Address: | N34: =F23 -> PUROK 3 ,DAET, CAMARINEZ NORTE | Y34: Renewal | AF34: Pension Loan | AN34: 24 Months | AU34: Bank Electronic Transfer to Borrowers Account
B35: =DATE(YEAR(E$24),MONTH(E$24)+D35+1,DAY(E$24)) -> 46188 | C35: =TEXT(B35,"mmm-yyyy") -> Jun-2026 | D35: 8 | E35: =C$1 -> 5332.9739 | F35: =E35-G35 -> 4680.3357 | G35: =H34*C$12 -> 652.63816 | H35: =H34-F35 -> 79986.236 | Y35: Additional | AF35: Emergency | AN35: 36 Months | AU35: Others:
B36: =DATE(YEAR(E$24),MONTH(E$24)+D36+1,DAY(E$24)) -> 46218 | C36: =TEXT(B36,"mmm-yyyy") -> Jul-2026 | D36: 9 | E36: =C$1 -> 5332.9739 | F36: =E36-G36 -> 4716.4133 | G36: =H35*C$12 -> 616.56057 | H36: =H35-F36 -> 75269.823 | L36: Principal Amount | R36: =C4 -> 116441.67 | Y36: Reloan | AF36: Health Assistance Loan | AN36: 48 Months
B37: =DATE(YEAR(E$24),MONTH(E$24)+D37+1,DAY(E$24)) -> 46249 | C37: =TEXT(B37,"mmm-yyyy") -> Aug-2026 | D37: 10 | E37: =C$1 -> 5332.9739 | F37: =E37-G37 -> 4752.769 | G37: =H36*C$12 -> 580.20488 | H37: =H36-F37 -> 70517.054 | Y37: Restructure | AF37: Educational Loan | AN37: 60 Months
B38: =DATE(YEAR(E$24),MONTH(E$24)+D38+1,DAY(E$24)) -> 46280 | C38: =TEXT(B38,"mmm-yyyy") -> Sep-2026 | D38: 11 | E38: =C$1 -> 5332.9739 | F38: =E38-G38 -> 4789.4049 | G38: =H37*C$12 -> 543.56895 | H38: =H37-F38 -> 65727.649 | L38: (-) | M38: Balance Old Loan(s) | R38: =-C14 -> 0 | AF38: Others: | AN38: Others:
B39: =DATE(YEAR(E$24),MONTH(E$24)+D39+1,DAY(E$24)) -> 46310 | C39: =TEXT(B39,"mmm-yyyy") -> Oct-2026 | D39: 12 | E39: =C$1 -> 5332.9739 | F39: =E39-G39 -> 4826.3232 | G39: =H38*C$12 -> 506.65062 | H39: =H38-F39 -> 60901.325 | L39: (-) | M39: Membership Fee: | R39: =-C8 -> 0 | X39: AMOUNT APPLIED: | AB39: =R44 -> 100000 | AN39: MONTHLY AMORTIZATION: | AT39: =R49 -> 5332.9739
B40: =DATE(YEAR(E$24),MONTH(E$24)+D40+1,DAY(E$24)) -> 46341 | C40: =TEXT(B40,"mmm-yyyy") -> Nov-2026 | D40: 13 | E40: =C$1 -> 5332.9739 | F40: =E40-G40 -> 4863.5262 | G40: =H39*C$12 -> 469.44772 | H40: =H39-F40 -> 56037.799 | L40: (-) | M40: Paid up Capital: | R40: =-C7 -> -5000
B41: =DATE(YEAR(E$24),MONTH(E$24)+D41+1,DAY(E$24)) -> 46371 | C41: =TEXT(B41,"mmm-yyyy") -> Dec-2026 | D41: 14 | E41: =C$1 -> 5332.9739 | F41: =E41-G41 -> 4901.0158 | G41: =H40*C$12 -> 431.95804 | H41: =H40-F41 -> 51136.783 | L41: (-) | M41: Service Fee | R41: =-C5 -> -7500 | X41: LOAN ID: | AF41: DEDUCTION CODE: | AR41: LOAN PURPOSE:
B42: =DATE(YEAR(E$24),MONTH(E$24)+D42+1,DAY(E$24)) -> 46402 | C42: =TEXT(B42,"mmm-yyyy") -> Jan-2027 | D42: 15 | E42: =C$1 -> 5332.9739 | F42: =E42-G42 -> 4938.7945 | G42: =H41*C$12 -> 394.17937 | H42: =H41-F42 -> 46197.989 | L42: (-) | M42: Insurance Premium - Paramount | R42: =-C6 -> -2400 | X42: MEM ID: | AG42: Regular Member | AS42: Old Member
B43: =DATE(YEAR(E$24),MONTH(E$24)+D43+1,DAY(E$24)) -> 46433 | C43: =TEXT(B43,"mmm-yyyy") -> Feb-2027 | D43: 16 | E43: =C$1 -> 5332.9739 | F43: =E43-G43 -> 4976.8644 | G43: =H42*C$12 -> 356.1095 | H43: =H42-F43 -> 41221.125 | L43: (-) | M43: Advance Interest | R43: =-C9 -> -1541.6667 | AG43: Associate Member | AS43: New Member
B44: =DATE(YEAR(E$24),MONTH(E$24)+D44+1,DAY(E$24)) -> 46461 | C44: =TEXT(B44,"mmm-yyyy") -> Mar-2027 | D44: 17 | E44: =C$1 -> 5332.9739 | F44: =E44-G44 -> 5015.2277 | G44: =H43*C$12 -> 317.74617 | H44: =H43-F44 -> 36205.897 | L44: NET PROCEEDS (Php): | R44: =SUM(R36:T43) -> 100000 | X44: BORROWER'S INFORMATION
B45: =DATE(YEAR(E$24),MONTH(E$24)+D45+1,DAY(E$24)) -> 46492 | C45: =TEXT(B45,"mmm-yyyy") -> Apr-2027 | D45: 18 | E45: =C$1 -> 5332.9739 | F45: =E45-G45 -> 5053.8867 | G45: =H44*C$12 -> 279.08712 | H45: =H44-F45 -> 31152.01 | X45: MACAPILI | AD45: MARIA CRISELDA | AN45: GINAGA
B46: =DATE(YEAR(E$24),MONTH(E$24)+D46+1,DAY(E$24)) -> 46522 | C46: =TEXT(B46,"mmm-yyyy") -> May-2027 | D46: 19 | E46: =C$1 -> 5332.9739 | F46: =E46-G46 -> 5092.8438 | G46: =H45*C$12 -> 240.13008 | H46: =H45-F46 -> 26059.166 | K46: PAYMENT | X46: (LAST NAME) | AD46: (FIRST NAME) | AN46: (MIDDLE NAME) | AZ46: (SUFFIX)
...

Sheet 3 years
A1: \ | B1: Amortization | C1: ='DATA ENTRY'!E16 -> 16696.184
B2: Timeline | C2: 0 | D2: 1 | E2: 2 | F2: 3 | G2: 4 | H2: 5 | I2: 6 | J2: 7 | K2: 8 | L2: 9 | M2: 10 | N2: 11 | O2: 12 | P2: 13 | Q2: 14 | R2: 15 | S2: 16 | T2: 17 | U2: 18 | V2: 19 | W2: 20 | X2: 21 | Y2: 22 | Z2: 23 | AA2: 24 | AB2: 25 | AC2: 26 | AD2: 27 | AE2: 28 | AF2: 29 | AG2: 30 | AH2: 31 | AI2: 32 | AJ2: 33 | AK2: 34 | AL2: 35 | AM2: 36
B3: GROSS AMOUNT | C3: ='DATA ENTRY'!E4 -> 601062.61
B4: LOAN AMOUNT | C4: ='DATA ENTRY'!E13 -> 517435.36 | D4: -13536.72 | E4: -13536.72 | F4: -13536.72 | G4: -13536.72 | H4: -13536.72 | I4: -13536.72 | J4: -13536.72 | K4: -13536.72 | L4: -13536.72 | M4: -13536.72 | N4: -13536.72 | O4: -13536.72 | P4: -13536.72 | Q4: -13536.72 | R4: -13536.72 | S4: -13536.72 | T4: -13536.72 | U4: -13536.72 | V4: -13536.72 | W4: -13536.72 | X4: -13536.72 | Y4: -13536.72 | Z4: -13536.72 | AA4: -13536.72 | AB4: -13536.72 | AC4: -13536.72 | AD4: -13536.72 | AE4: -13536.72 | AF4: -13536.72 | AG4: -13536.72 | AH4: -13536.72 | AI4: -13536.72 | AJ4: -13536.72 | AK4: -13536.72 | AL4: -13536.72 | AM4: -13536.72
B5: Service Fee | C5: ='DATA ENTRY'!E8 -> 39943.567
B6: Insurance | C6: ='DATA ENTRY'!E9 -> 15977.427
B7: CapCon | C7: ='DATA ENTRY'!E10 -> 10000
B8: membership fee | C8: ='DATA ENTRY'!E11 -> 300
B9: Advance Interest | C9: ='DATA ENTRY'!E12 -> 7396.9568
B10: NET PROCEEDS/CASH FLOW | C10: =C4-C5-C6-C7-C8-C9 -> 443817.41 | D10: =-$C1 -> -16696.184 | E10: =-$C1 -> -16696.184 | F10: =-$C1 -> -16696.184 | G10: =-$C1 -> -16696.184 | H10: =-$C1 -> -16696.184 | I10: =-$C1 -> -16696.184 | J10: =-$C1 -> -16696.184 | K10: =-$C1 -> -16696.184 | ... AM10: =-$C1 -> -16696.184
B12: Interest Rate of Return | C12: =IRR(C4:AM4) -> -0.0032058465 | D12: =C12/5 -> -0.00064116929 | G12: sinense LB
E13: =C10+C14 -> 534965.69 | G13: 72462.47
B14: Loan Balance | C14: =G15 -> 91148.28 | G14: 18685.81
B15: Monthly Interest Rate | C15: ='DATA ENTRY'!E14/12 -> 0.0083333333 | G15: =G13+G14 -> 91148.28
B16: Effective Interest Rate | C16: ='DATA ENTRY'!E15 -> 0.10501772 | K16: APPROVED
C20: LOAN LEDGER CARD
C22: Name: | D22: SEVERO B. SINENSE | G22: Loan Voucher No. | H22: LV- 004-BO
C23: Serial Nr: | D23: O-121408 | E23: Address: | F23: P7 CABUGAO, ECHAGUE ISABELA | G23: Amount: | H23: =C10-C14 -> 352669.13
C24: Posting date | D24: Date of Loan: | E24: 45868 | F24: Maturity Date | G24: =B63 -> 47026 | K24: PEOPLE'S MULTI-PURPOSE COOPERATIVE
D25: Term: | E25: 36 | F25: MOS | K25: 20-E 2nd Camarilla St. corner 15th Ave., Brgy. San Roque, Murphy Cubao, Quezon City | X25: 20-E 2nd Camarilla St corner 15th Avenue,
D26: Loan | E26: Installment | F26: Principal | G26: EIR | H26: Balance | X26: Brgy San Roque, Murphy Cubao, Quezon City
D27: Month 0 | H27: =C4 -> 517435.36 | K27: LOAN RELEASE VOUCHER | X27: Mobile No. (+63)953-033-1580 (GLOBE)
B28: =DATE(YEAR(E$24),MONTH(E$24)+D28+2,DAY(E$24)) -> 45960 | C28: =TEXT(B28,"mmm-yyyy") -> Oct-2025 | D28: 1 | E28: =C$1 -> 16696.184 | F28: =E28-G28 -> 18355.002 | G28: =H27*C$12 -> -1658.8183 | H28: =H27-F28 -> 499080.36
B29: =DATE(YEAR(E$24),MONTH(E$24)+D29+2,DAY(E$24)) -> 45991 | C29: =TEXT(B29,"mmm-yyyy") -> Nov-2025 | D29: 2 | E29: =C$1 -> 16696.184 | F29: =E29-G29 -> 18296.159 | G29: =H28*C$12 -> -1599.975 | H29: =H28-F29 -> 480784.2 | R29: Date: | S29: =E24 -> 45868 | X29: LOAN APPLICATION FORM
B30: =DATE(YEAR(E$24),MONTH(E$24)+D30+2,DAY(E$24)) -> 46021 | C30: =TEXT(B30,"mmm-yyyy") -> Dec-2025 | D30: 3 | E30: =C$1 -> 16696.184 | F30: =E30-G30 -> 18237.504 | G30: =H29*C$12 -> -1541.3203 | H30: =H29-F30 -> 462546.7 | R30: LV No: | S30: =H22 -> LV- 004-BO | AU30: Date: | AX30: , | AZ30: ,
B31: =DATE(YEAR(E$24),MONTH(E$24)+D31+2,DAY(E$24)) -> 46052 | C31: =TEXT(B31,"mmm-yyyy") -> Jan-2026 | D31: 4 | E31: =C$1 -> 16696.184 | F31: =E31-G31 -> 18179.037 | G31: =H30*C$12 -> -1482.8537 | H31: =H30-F31 -> 444367.66 | AW31: m | AX31: m | AY31: d | AZ31: d | BA31: y | BB31: y | BC31: y | BD31: y
B32: =DATE(YEAR(E$24),MONTH(E$24)+D32+2,DAY(E$24)) -> 46083 | C32: =TEXT(B32,"mmm-yyyy") -> Mar-2026 | D32: 5 | E32: =C$1 -> 16696.184 | F32: =E32-G32 -> 18120.758 | G32: =H31*C$12 -> -1424.5745 | H32: =H31-F32 -> 426246.9 | K32: Name of Borrower: | N32: =D22 -> SEVERO B. SINENSE | X32: APPLICATION TYPE | AE32: LOAN CLASSIFICATION | AM32: TERM | AT32: RELEASE OF LOAN PROCEEDS
B33: =DATE(YEAR(E$24),MONTH(E$24)+D33+2,DAY(E$24)) -> 46111 | C33: =TEXT(B33,"mmm-yyyy") -> Mar-2026 | D33: 6 | E33: =C$1 -> 16696.184 | F33: =E33-G33 -> 18062.666 | G33: =H32*C$12 -> -1366.4821 | H33: =H32-F33 -> 408184.23 | K33: Serial No.: | N33: =D23 -> O-121408 | Y33: New | AF33: Salary Loan | AN33: 12 Months | AU33: Check
B34: =DATE(YEAR(E$24),MONTH(E$24)+D34+2,DAY(E$24)) -> 46142 | C34: =TEXT(B34,"mmm-yyyy") -> Apr-2026 | D34: 7 | E34: =C$1 -> 16696.184 | F34: =E34-G34 -> 18004.76 | G34: =H33*C$12 -> -1308.576 | H34: =H33-F34 -> 390179.48 | K34: Address: | N34: =F23 -> P7 CABUGAO, ECHAGUE ISABELA | Y34: Renewal | AF34: Pension Loan | AN34: 24 Months | AU34: Bank Electronic Transfer to Borrowers Account
B35: =DATE(YEAR(E$24),MONTH(E$24)+D35+2,DAY(E$24)) -> 46172 | C35: =TEXT(B35,"mmm-yyyy") -> May-2026 | D35: 8 | E35: =C$1 -> 16696.184 | F35: =E35-G35 -> 17947.039 | G35: =H34*C$12 -> -1250.8555 | H35: =H34-F35 -> 372232.44 | Y35: Additional | AF35: Emergency | AN35: 36 Months | AU35: Others:
B36: =DATE(YEAR(E$24),MONTH(E$24)+D36+2,DAY(E$24)) -> 46203 | C36: =TEXT(B36,"mmm-yyyy") -> Jun-2026 | D36: 9 | E36: =C$1 -> 16696.184 | F36: =E36-G36 -> 17889.504 | G36: =H35*C$12 -> -1193.32 | H36: =H35-F36 -> 354342.93 | L36: Principal Amount | R36: =C4 -> 517435.36 | Y36: Reloan | AF36: Health Assistance Loan | AN36: 48 Months
B37: =DATE(YEAR(E$24),MONTH(E$24)+D37+2,DAY(E$24)) -> 46233 | C37: =TEXT(B37,"mmm-yyyy") -> Jul-2026 | D37: 10 | E37: =C$1 -> 16696.184 | F37: =E37-G37 -> 17832.153 | G37: =H36*C$12 -> -1135.969 | H37: =H36-F37 -> 336510.78 | Y37: Restructure | AF37: Educational Loan | AN37: 60 Months
B38: =DATE(YEAR(E$24),MONTH(E$24)+D38+2,DAY(E$24)) -> 46264 | C38: =TEXT(B38,"mmm-yyyy") -> Aug-2026 | D38: 11 | E38: =C$1 -> 16696.184 | F38: =E38-G38 -> 17774.986 | G38: =H37*C$12 -> -1078.8019 | H38: =H37-F38 -> 318735.79 | L38: (-) | M38: Balance Old Loan(s) | R38: =-C14 -> -91148.28 | AF38: Others: | AN38: Others:
B39: =DATE(YEAR(E$24),MONTH(E$24)+D39+2,DAY(E$24)) -> 46295 | C39: =TEXT(B39,"mmm-yyyy") -> Sep-2026 | D39: 12 | E39: =C$1 -> 16696.184 | F39: =E39-G39 -> 17718.002 | G39: =H38*C$12 -> -1021.818 | H39: =H38-F39 -> 301017.79 | L39: (-) | M39: Membership Fee: | R39: =-C8 -> -300 | X39: AMOUNT APPLIED: | AB39: =R44 -> 352669.13 | AN39: MONTHLY AMORTIZATION: | AT39: =R49 -> 16696.184
B40: =DATE(YEAR(E$24),MONTH(E$24)+D40+2,DAY(E$24)) -> 46325 | C40: =TEXT(B40,"mmm-yyyy") -> Oct-2026 | D40: 13 | E40: =C$1 -> 16696.184 | F40: =E40-G40 -> 17661.2 | G40: =H39*C$12 -> -965.01683 | H40: =H39-F40 -> 283356.59 | L40: (-) | M40: Paid up Capital: | R40: =-C7 -> -10000
B41: =DATE(YEAR(E$24),MONTH(E$24)+D41+2,DAY(E$24)) -> 46356 | C41: =TEXT(B41,"mmm-yyyy") -> Nov-2026 | D41: 14 | E41: =C$1 -> 16696.184 | F41: =E41-G41 -> 17604.581 | G41: =H40*C$12 -> -908.39773 | H41: =H40-F41 -> 265752.01 | L41: (-) | M41: Service Fee | R41: =-C5 -> -39943.567 | X41: LOAN ID: | AF41: DEDUCTION CODE: | AR41: LOAN PURPOSE:
B42: =DATE(YEAR(E$24),MONTH(E$24)+D42+2,DAY(E$24)) -> 46386 | C42: =TEXT(B42,"mmm-yyyy") -> Dec-2026 | D42: 15 | E42: =C$1 -> 16696.184 | F42: =E42-G42 -> 17548.144 | G42: =H41*C$12 -> -851.96014 | H42: =H41-F42 -> 248203.87 | L42: (-) | M42: Insurance Premium - Paramount | R42: =-C6 -> -15977.427 | X42: MEM ID: | AG42: Regular Member | AS42: Old Member
B43: =DATE(YEAR(E$24),MONTH(E$24)+D43+2,DAY(E$24)) -> 46417 | C43: =TEXT(B43,"mmm-yyyy") -> Jan-2027 | D43: 16 | E43: =C$1 -> 16696.184 | F43: =E43-G43 -> 17491.887 | G43: =H42*C$12 -> -795.70349 | H43: =H42-F43 -> 230711.98 | L43: (-) | M43: Advance Interest | R43: =-C9 -> -7396.9568 | AG43: Associate Member | AS43: New Member
B44: =DATE(YEAR(E$24),MONTH(E$24)+D44+2,DAY(E$24)) -> 46448 | C44: =TEXT(B44,"mmm-yyyy") -> Mar-2027 | D44: 17 | E44: =C$1 -> 16696.184 | F44: =E44-G44 -> 17435.811 | G44: =H43*C$12 -> -739.62719 | H44: =H43-F44 -> 213276.17 | L44: NET PROCEEDS (Php): | R44: =SUM(R36:T43) -> 352669.13 | X44: BORROWER'S INFORMATION
B45: =DATE(YEAR(E$24),MONTH(E$24)+D45+2,DAY(E$24)) -> 46476 | C45: =TEXT(B45,"mmm-yyyy") -> Mar-2027 | D45: 18 | E45: =C$1 -> 16696.184 | F45: =E45-G45 -> 17379.914 | G45: =H44*C$12 -> -683.73065 | H45: =H44-F45 -> 195896.25 | X45: SINENSE | AD45: SEVERO | AN45: BATOBATO
...

Sheet 4 years
A1: \ | B1: Amortization | C1: ='DATA ENTRY'!F16 -> 13536.716
B2: Timeline | C2: 0 | D2: 1 | E2: 2 | F2: 3 | G2: 4 | H2: 5 | I2: 6 | J2: 7 | K2: 8 | L2: 9 | M2: 10 | N2: 11 | O2: 12 | P2: 13 | Q2: 14 | R2: 15 | S2: 16 | T2: 17 | U2: 18 | V2: 19 | W2: 20 | X2: 21 | Y2: 22 | Z2: 23 | AA2: 24 | AB2: 25 | AC2: 26 | AD2: 27 | AE2: 28 | AF2: 29 | AG2: 30 | AH2: 31 | AI2: 32 | AJ2: 33 | AK2: 34 | AL2: 35 | AM2: 36 | AN2: 37 | AO2: 38 | AP2: 39 | AQ2: 40 | AR2: 41 | AS2: 42 | AT2: 43 | AU2: 44 | AV2: 45 | AW2: 46 | AX2: 47 | AY2: 48 | AZ2: 49 | BA2: 50 | BB2: 51 | BC2: 52 | BD2: 53 | BE2: 54 | BF2: 55 | BG2: 56 | BH2: 57 | BI2: 58 | BJ2: 59 | BK2: 60
B3: GROSS AMOUNT | C3: ='DATA ENTRY'!F4 -> 649762.37
B4: LOAN AMOUNT | C4: ='DATA ENTRY'!F13 -> 523754.78 | D4: =D10 -> -13536.716 | E4: =E10 -> -13536.716 | F4: =F10 -> -13536.716 | G4: =G10 -> -13536.716 | H4: =H10 -> -13536.716 | I4: =I10 -> -13536.716 | J4: =J10 -> -13536.716 | K4: =K10 -> -13536.716 | ... BK4: =BK10 -> -13536.716
B5: Service Fee | C5: ='DATA ENTRY'!F8 -> 39963.33
B6: Insurance | C6: ='DATA ENTRY'!F9 -> 21313.776
B7: CapCon | C7: ='DATA ENTRY'!F10 -> 10000
B8: membership fee | C8: ='DATA ENTRY'!G11 -> 300
B9: Advance Interest | C9: ='DATA ENTRY'!F12 -> 8140.6783
B10: NET PROCEEDS/CASH FLOW | C10: =C4-C5-C6-C7-C8-C9 -> 444037 | D10: =-$C1 -> -13536.716 | E10: =-$C1 -> -13536.716 | F10: =-$C1 -> -13536.716 | G10: =-$C1 -> -13536.716 | H10: =-$C1 -> -13536.716 | I10: =-$C1 -> -13536.716 | J10: =-$C1 -> -13536.716 | K10: =-$C1 -> -13536.716 | ... BK10: =-$C1 -> -13536.716
B12: Interest Rate of Return | C12: =IRR(C4:AY4) -> 0.0091666667 | D12: =C12/5 -> 0.0018333333
B14: Loan Balance | C14: 91367.87
B15: Monthly Interest Rate | C15: ='DATA ENTRY'!G14/12 -> 0.01
B16: Effective Interest Rate | C16: ='DATA ENTRY'!G15 -> 0.12736174 | K16: APPROVED
C20: LOAN LEDGER CARD
C22: Name: | D22: SEVERO B. SINENSE | G22: Loan Voucher No. | H22: LV- 004-BO
C23: Serial Nr: | D23: O-121408 | E23: Address: | F23: P7 CABUGAO, ECHAGUE, ISABELA | G23: Amount: | H23: =C10 -> 444037
C24: Posting date | D24: Date of Loan: | E24: 45874 | F24: Maturity Date | G24: =B75 -> 47366 | K24: PEOPLE'S MULTI-PURPOSE COOPERATIVE
D25: Term: | E25: 48 | F25: MOS | K25: 20-E 2nd Camarilla St. corner 15th Ave., Brgy. San Roque, Murphy Cubao, Quezon City | X25: 20-E 2nd Camarilla St corner 15th Avenue,
D26: Loan | E26: Installment | F26: Principal | G26: EIR | H26: Balance | X26: Brgy San Roque, Murphy Cubao, Quezon City
D27: Month 0 | H27: =C4 -> 523754.78 | K27: LOAN RELEASE VOUCHER | X27: Mobile No. (+63)953-033-1580 (GLOBE)
B28: =DATE(YEAR(E$24),MONTH(E$24)+D28+1,DAY(E$24)) -> 45935 | C28: =TEXT(B28,"mmm-yyyy") -> Oct-2025 | D28: 1 | E28: =C$1 -> 13536.716 | F28: =E28-G28 -> 8735.6306 | G28: =H27*C$12 -> 4801.0855 | H28: =H27-F28 -> 515019.15
B29: =DATE(YEAR(E$24),MONTH(E$24)+D29+1,DAY(E$24)) -> 45966 | C29: =TEXT(B29,"mmm-yyyy") -> Nov-2025 | D29: 2 | E29: =C$1 -> 13536.716 | F29: =E29-G29 -> 8815.7072 | G29: =H28*C$12 -> 4721.0089 | H29: =H28-F29 -> 506203.45 | R29: Date: | S29: =E24 -> 45874 | X29: LOAN APPLICATION FORM
B30: =DATE(YEAR(E$24),MONTH(E$24)+D30+1,DAY(E$24)) -> 45996 | C30: =TEXT(B30,"mmm-yyyy") -> Dec-2025 | D30: 3 | E30: =C$1 -> 13536.716 | F30: =E30-G30 -> 8896.5179 | G30: =H29*C$12 -> 4640.1983 | H30: =H29-F30 -> 497306.93 | R30: LV No: | S30: =H22 -> LV- 004-BO | AU30: Date: | AX30: , | AZ30: ,
B31: =DATE(YEAR(E$24),MONTH(E$24)+D31+1,DAY(E$24)) -> 46027 | C31: =TEXT(B31,"mmm-yyyy") -> Jan-2026 | D31: 4 | E31: =C$1 -> 13536.716 | F31: =E31-G31 -> 8978.0693 | G31: =H30*C$12 -> 4558.6468 | H31: =H30-F31 -> 488328.86 | AW31: m | AX31: m | AY31: d | AZ31: d | BA31: y | BB31: y | BC31: y | BD31: y
B32: =DATE(YEAR(E$24),MONTH(E$24)+D32+1,DAY(E$24)) -> 46058 | C32: =TEXT(B32,"mmm-yyyy") -> Feb-2026 | D32: 5 | E32: =C$1 -> 13536.716 | F32: =E32-G32 -> 9060.3682 | G32: =H31*C$12 -> 4476.3479 | H32: =H31-F32 -> 479268.49 | K32: Name of Borrower: | N32: =D22 -> SEVERO B. SINENSE | X32: APPLICATION TYPE | AE32: LOAN CLASSIFICATION | AM32: TERM | AT32: RELEASE OF LOAN PROCEEDS
B33: =DATE(YEAR(E$24),MONTH(E$24)+D33+1,DAY(E$24)) -> 46086 | C33: =TEXT(B33,"mmm-yyyy") -> Mar-2026 | D33: 6 | E33: =C$1 -> 13536.716 | F33: =E33-G33 -> 9143.4216 | G33: =H32*C$12 -> 4393.2945 | H33: =H32-F33 -> 470125.07 | K33: Serial No.: | N33: =D23 -> O-121408 | Y33: New | AF33: Salary Loan | AN33: 12 Months | AU33: Check
B34: =DATE(YEAR(E$24),MONTH(E$24)+D34+1,DAY(E$24)) -> 46117 | C34: =TEXT(B34,"mmm-yyyy") -> Apr-2026 | D34: 7 | E34: =C$1 -> 13536.716 | F34: =E34-G34 -> 9227.2363 | G34: =H33*C$12 -> 4309.4798 | H34: =H33-F34 -> 460897.83 | K34: Address: | N34: =F23 -> P7 CABUGAO, ECHAGUE, ISABELA | Y34: Renewal | AF34: Pension Loan | AN34: 24 Months | AU34: Bank Electronic Transfer to Borrowers Account
B35: =DATE(YEAR(E$24),MONTH(E$24)+D35+1,DAY(E$24)) -> 46147 | C35: =TEXT(B35,"mmm-yyyy") -> May-2026 | D35: 8 | E35: =C$1 -> 13536.716 | F35: =E35-G35 -> 9311.8193 | G35: =H34*C$12 -> 4224.8968 | H35: =H34-F35 -> 451586.01 | Y35: Additional | AF35: Emergency | AN35: 36 Months | AU35: Others:
B36: =DATE(YEAR(E$24),MONTH(E$24)+D36+1,DAY(E$24)) -> 46178 | C36: =TEXT(B36,"mmm-yyyy") -> Jun-2026 | D36: 9 | E36: =C$1 -> 13536.716 | F36: =E36-G36 -> 9397.1777 | G36: =H35*C$12 -> 4139.5385 | H36: =H35-F36 -> 442188.84 | L36: Principal Amount | R36: =C4 -> 523754.78 | Y36: Reloan | AF36: Health Assistance Loan | AN36: 48 Months
B37: =DATE(YEAR(E$24),MONTH(E$24)+D37+1,DAY(E$24)) -> 46208 | C37: =TEXT(B37,"mmm-yyyy") -> Jul-2026 | D37: 10 | E37: =C$1 -> 13536.716 | F37: =E37-G37 -> 9483.3185 | G37: =H36*C$12 -> 4053.3977 | H37: =H36-F37 -> 432705.52 | Y37: Restructure | AF37: Educational Loan | AN37: 60 Months
B38: =DATE(YEAR(E$24),MONTH(E$24)+D38+1,DAY(E$24)) -> 46239 | C38: =TEXT(B38,"mmm-yyyy") -> Aug-2026 | D38: 11 | E38: =C$1 -> 13536.716 | F38: =E38-G38 -> 9570.2489 | G38: =H37*C$12 -> 3966.4672 | H38: =H37-F38 -> 423135.27 | L38: (-) | M38: Balance Old Loan(s) | R38: =-C14 -> -91367.87 | AF38: Others: | AN38: Others:
B39: =DATE(YEAR(E$24),MONTH(E$24)+D39+1,DAY(E$24)) -> 46270 | C39: =TEXT(B39,"mmm-yyyy") -> Sep-2026 | D39: 12 | E39: =C$1 -> 13536.716 | F39: =E39-G39 -> 9657.9762 | G39: =H38*C$12 -> 3878.74 | H39: =H38-F39 -> 413477.29 | L39: (-) | M39: Membership Fee: | R39: =-C8 -> -300 | X39: AMOUNT APPLIED: | AB39: =R44 -> 352669.13 | AN39: MONTHLY AMORTIZATION: | AT39: =R49 -> 13536.716
B40: =DATE(YEAR(E$24),MONTH(E$24)+D40+1,DAY(E$24)) -> 46300 | C40: =TEXT(B40,"mmm-yyyy") -> Oct-2026 | D40: 13 | E40: =C$1 -> 13536.716 | F40: =E40-G40 -> 9746.5076 | G40: =H39*C$12 -> 3790.2085 | H40: =H39-F40 -> 403730.79 | L40: (-) | M40: Paid up Capital: | R40: =-C7 -> -10000
B41: =DATE(YEAR(E$24),MONTH(E$24)+D41+1,DAY(E$24)) -> 46331 | C41: =TEXT(B41,"mmm-yyyy") -> Nov-2026 | D41: 14 | E41: =C$1 -> 13536.716 | F41: =E41-G41 -> 9835.8506 | G41: =H40*C$12 -> 3700.8655 | H41: =H40-F41 -> 393894.93 | L41: (-) | M41: Service Fee | R41: =-C5 -> -39963.33 | X41: LOAN ID: | AF41: DEDUCTION CODE: | AR41: LOAN PURPOSE:
B42: =DATE(YEAR(E$24),MONTH(E$24)+D42+1,DAY(E$24)) -> 46361 | C42: =TEXT(B42,"mmm-yyyy") -> Dec-2026 | D42: 15 | E42: =C$1 -> 13536.716 | F42: =E42-G42 -> 9926.0126 | G42: =H41*C$12 -> 3610.7036 | H42: =H41-F42 -> 383968.92 | L42: (-) | M42: Insurance Premium - Paramount | R42: =-C6 -> -21313.776 | X42: MEM ID: | AG42: Regular Member | AS42: Old Member
B43: =DATE(YEAR(E$24),MONTH(E$24)+D43+1,DAY(E$24)) -> 46392 | C43: =TEXT(B43,"mmm-yyyy") -> Jan-2027 | D43: 16 | E43: =C$1 -> 13536.716 | F43: =E43-G43 -> 10017.001 | G43: =H42*C$12 -> 3519.7151 | H43: =H42-F43 -> 373951.92 | L43: (-) | M43: Advance Interest | R43: =-C9 -> -8140.6783 | AG43: Associate Member | AS43: New Member
B44: =DATE(YEAR(E$24),MONTH(E$24)+D44+1,DAY(E$24)) -> 46423 | C44: =TEXT(B44,"mmm-yyyy") -> Feb-2027 | D44: 17 | E44: =C$1 -> 13536.716 | F44: =E44-G44 -> 10108.824 | G44: =H43*C$12 -> 3427.8926 | H44: =H43-F44 -> 363843.1 | L44: NET PROCEEDS (Php): | R44: =SUM(R36:T43) -> 352669.13 | X44: BORROWER'S INFORMATION
B45: =DATE(YEAR(E$24),MONTH(E$24)+D45+1,DAY(E$24)) -> 46451 | C45: =TEXT(B45,"mmm-yyyy") -> Mar-2027 | D45: 18 | E45: =C$1 -> 13536.716 | F45: =E45-G45 -> 10201.488 | G45: =H44*C$12 -> 3335.2284 | H45: =H44-F45 -> 353641.61 | X45: SINENSE | AD45: SEVERO | AN45: BATOBATO
B46: =DATE(YEAR(E$24),MONTH(E$24)+D46+1,DAY(E$24)) -> 46482 | C46: =TEXT(B46,"mmm-yyyy") -> Apr-2027 | D46: 19 | E46: =C$1 -> 13536.716 | F46: =E46-G46 -> 10295.001 | G46: =H45*C$12 -> 3241.7148 | H46: =H45-F46 -> 343346.61 | K46: PAYMENT | X46: (LAST NAME) | AD46: (FIRST NAME) | AN46: (MIDDLE NAME) | AZ46: (SUFFIX)
...

Sheet 5 years
A1: \ | B1: Amortization | C1: ='DATA ENTRY'!G16 -> 10499.998
B2: Timeline | C2: 0 | D2: 1 | E2: 2 | F2: 3 | G2: 4 | H2: 5 | I2: 6 | J2: 7 | K2: 8 | L2: 9 | M2: 10 | N2: 11 | O2: 12 | P2: 13 | Q2: 14 | R2: 15 | S2: 16 | T2: 17 | U2: 18 | V2: 19 | W2: 20 | X2: 21 | Y2: 22 | Z2: 23 | AA2: 24 | AB2: 25 | AC2: 26 | AD2: 27 | AE2: 28 | AF2: 29 | AG2: 30 | AH2: 31 | AI2: 32 | AJ2: 33 | AK2: 34 | AL2: 35 | AM2: 36 | AN2: 37 | AO2: 38 | AP2: 39 | AQ2: 40 | AR2: 41 | AS2: 42 | AT2: 43 | AU2: 44 | AV2: 45 | AW2: 46 | AX2: 47 | AY2: 48 | AZ2: 49 | BA2: 50 | BB2: 51 | BC2: 52 | BD2: 53 | BE2: 54 | BF2: 55 | BG2: 56 | BH2: 57 | BI2: 58 | BJ2: 59 | BK2: 60
B3: GROSS AMOUNT | C3: ='DATA ENTRY'!G4 -> 629999.88
B4: LOAN AMOUNT | C4: ='DATA ENTRY'!G13 -> 472027.82 | D4: =-$C1 -> -10499.998 | E4: =-$C1 -> -10499.998 | F4: =-$C1 -> -10499.998 | G4: =-$C1 -> -10499.998 | H4: =-$C1 -> -10499.998 | I4: =-$C1 -> -10499.998 | J4: =-$C1 -> -10499.998 | K4: =-$C1 -> -10499.998 | ... BK4: =-$C1 -> -10499.998
B5: Service Fee | C5: ='DATA ENTRY'!G8 -> 47022.536
B6: Insurance | C6: ='DATA ENTRY'!G9 -> 23316.96
B7: CapCon | C7: ='DATA ENTRY'!G10 -> 5000
B8: membership fee | C8: ='DATA ENTRY'!G11 -> 300
B9: Advance Interest | C9: ='DATA ENTRY'!G12 -> 7772.32
B10: NET PROCEEDS/CASH FLOW | C10: =C4-C5-C6-C7-C8-C9 -> 388616
B12: Interest Rate of Return | C12: =IRR(C4:BK4) -> 0.01
B14: Loan Balance | C14: 261703.78
B15: Monthly Interest Rate | C15: ='DATA ENTRY'!G14/12 -> 0.01
B16: Effective Interest Rate | C16: ='DATA ENTRY'!G15 -> 0.12736174 | K16: APPROVED
C20: LOAN LEDGER CARD
C22: Name: | D22: ALBERTO B MAGISTRADO | G22: Loan Voucher No. | H22: LV- 005-BO
C23: Serial Nr: | D23: 665147 | E23: Address: | F23: BLK 7 LOT 11 PHASE 2 REGINA VILLE 2000 BRGY INCENCIO TRECE MARTIRES CITY CAVITE | G23: Amount: | H23: =C10-C14 -> 126912.22
C24: Posting date | D24: Date of Loan: | E24: 45903 | F24: Maturity Date | G24: =B63 -> 47029 | K24: PEOPLE'S MULTI-PURPOSE COOPERATIVE
D25: Term: | E25: 60 | F25: MOS | K25: 20-E 2nd Camarilla St. corner 15th Ave., Brgy. San Roque, Murphy Cubao, Quezon City | X25: 20-E 2nd Camarilla St corner 15th Avenue,
D26: Loan | E26: Installment | F26: Principal | G26: EIR | H26: Balance | X26: Brgy San Roque, Murphy Cubao, Quezon City
D27: Month 0 | H27: =C4 -> 472027.82 | K27: LOAN RELEASE VOUCHER | X27: Mobile No. (+63)953-033-1580 (GLOBE)
B28: =DATE(YEAR(E$24),MONTH(E$24)+D28+1,DAY(E$24)) -> 45964 | C28: =TEXT(B28,"mmm-yyyy") -> Nov-2025 | D28: 1 | E28: =C$1 -> 10499.998 | F28: =E28-G28 -> 5779.7199 | G28: =H27*C$12 -> 4720.2782 | H28: =H27-F28 -> 466248.1
B29: =DATE(YEAR(E$24),MONTH(E$24)+D29+1,DAY(E$24)) -> 45994 | C29: =TEXT(B29,"mmm-yyyy") -> Dec-2025 | D29: 2 | E29: =C$1 -> 10499.998 | F29: =E29-G29 -> 5837.5171 | G29: =H28*C$12 -> 4662.481 | H29: =H28-F29 -> 460410.58 | R29: Date: | S29: =E24 -> 45903 | X29: LOAN APPLICATION FORM
B30: =DATE(YEAR(E$24),MONTH(E$24)+D30+1,DAY(E$24)) -> 46025 | C30: =TEXT(B30,"mmm-yyyy") -> Jan-2026 | D30: 3 | E30: =C$1 -> 10499.998 | F30: =E30-G30 -> 5895.8923 | G30: =H29*C$12 -> 4604.1058 | H30: =H29-F30 -> 454514.69 | R30: LV No: | S30: =H22 -> LV- 005-BO | AU30: Date: | AW30: 0 | AX30: 9 | AY30: 0 | AZ30: 3 | BA30: 2 | BB30: 0 | BC30: 2 | BD30: 5
B31: =DATE(YEAR(E$24),MONTH(E$24)+D31+1,DAY(E$24)) -> 46056 | C31: =TEXT(B31,"mmm-yyyy") -> Feb-2026 | D31: 4 | E31: =C$1 -> 10499.998 | F31: =E31-G31 -> 5954.8512 | G31: =H30*C$12 -> 4545.1469 | H31: =H30-F31 -> 448559.84 | AW31: m | AX31: m | AY31: d | AZ31: d | BA31: y | BB31: y | BC31: y | BD31: y
B32: =DATE(YEAR(E$24),MONTH(E$24)+D32+1,DAY(E$24)) -> 46084 | C32: =TEXT(B32,"mmm-yyyy") -> Mar-2026 | D32: 5 | E32: =C$1 -> 10499.998 | F32: =E32-G32 -> 6014.3997 | G32: =H31*C$12 -> 4485.5984 | H32: =H31-F32 -> 442545.44 | K32: Name of Borrower: | N32: =D22 -> ALBERTO B MAGISTRADO | X32: APPLICATION TYPE | AE32: LOAN CLASSIFICATION | AM32: TERM | AT32: RELEASE OF LOAN PROCEEDS
B33: =DATE(YEAR(E$24),MONTH(E$24)+D33+1,DAY(E$24)) -> 46115 | C33: =TEXT(B33,"mmm-yyyy") -> Apr-2026 | D33: 6 | E33: =C$1 -> 10499.998 | F33: =E33-G33 -> 6074.5437 | G33: =H32*C$12 -> 4425.4544 | H33: =H32-F33 -> 436470.89 | K33: Serial No.: | N33: =D23 -> 665147 | Y33: New | AF33: Salary Loan | AN33: 12 Months | AU33: Check
B34: =DATE(YEAR(E$24),MONTH(E$24)+D34+1,DAY(E$24)) -> 46145 | C34: =TEXT(B34,"mmm-yyyy") -> May-2026 | D34: 7 | E34: =C$1 -> 10499.998 | F34: =E34-G34 -> 6135.2891 | G34: =H33*C$12 -> 4364.7089 | H34: =H33-F34 -> 430335.6 | K34: Address: | N34: =F23 -> BLK 7 LOT 11 PHASE 2 REGINA VILLE 2000 BRGY INCENCIO TRECE MARTIRES CITY CAVITE | Y34: Renewal | AF34: Pension Loan | AN34: 24 Months | AU34: Bank Electronic Transfer to Borrowers Account
B35: =DATE(YEAR(E$24),MONTH(E$24)+D35+1,DAY(E$24)) -> 46176 | C35: =TEXT(B35,"mmm-yyyy") -> Jun-2026 | D35: 8 | E35: =C$1 -> 10499.998 | F35: =E35-G35 -> 6196.642 | G35: =H34*C$12 -> 4303.356 | H35: =H34-F35 -> 424138.96 | Y35: Additional | AF35: Emergency | AN35: 36 Months | AU35: Others:
B36: =DATE(YEAR(E$24),MONTH(E$24)+D36+1,DAY(E$24)) -> 46206 | C36: =TEXT(B36,"mmm-yyyy") -> Jul-2026 | D36: 9 | E36: =C$1 -> 10499.998 | F36: =E36-G36 -> 6258.6084 | G36: =H35*C$12 -> 4241.3896 | H36: =H35-F36 -> 417880.35 | L36: Principal Amount | R36: =C4 -> 472027.82 | Y36: Reloan | AF36: Health Assistance Loan | AN36: 48 Months
B37: =DATE(YEAR(E$24),MONTH(E$24)+D37+1,DAY(E$24)) -> 46237 | C37: =TEXT(B37,"mmm-yyyy") -> Aug-2026 | D37: 10 | E37: =C$1 -> 10499.998 | F37: =E37-G37 -> 6321.1945 | G37: =H36*C$12 -> 4178.8035 | H37: =H36-F37 -> 411559.16 | Y37: Restructure | AF37: Educational Loan | AN37: 60 Months
B38: =DATE(YEAR(E$24),MONTH(E$24)+D38+1,DAY(E$24)) -> 46268 | C38: =TEXT(B38,"mmm-yyyy") -> Sep-2026 | D38: 11 | E38: =C$1 -> 10499.998 | F38: =E38-G38 -> 6384.4065 | G38: =H37*C$12 -> 4115.5916 | H38: =H37-F38 -> 405174.75 | L38: (-) | M38: Balance Old Loan(s) | R38: =-C14 -> -261703.78 | AF38: Others: | AN38: Others:
B39: =DATE(YEAR(E$24),MONTH(E$24)+D39+1,DAY(E$24)) -> 46298 | C39: =TEXT(B39,"mmm-yyyy") -> Oct-2026 | D39: 12 | E39: =C$1 -> 10499.998 | F39: =E39-G39 -> 6448.2505 | G39: =H38*C$12 -> 4051.7475 | H39: =H38-F39 -> 398726.5 | L39: (-) | M39: Membership Fee: | R39: =-C8 -> -300 | X39: AMOUNT APPLIED: | AB39: =R44 -> 126912.22 | AN39: MONTHLY AMORTIZATION: | AT39: =R49 -> 10499.998
B40: =DATE(YEAR(E$24),MONTH(E$24)+D40+1,DAY(E$24)) -> 46329 | C40: =TEXT(B40,"mmm-yyyy") -> Nov-2026 | D40: 13 | E40: =C$1 -> 10499.998 | F40: =E40-G40 -> 6512.733 | G40: =H39*C$12 -> 3987.265 | H40: =H39-F40 -> 392213.77 | L40: (-) | M40: Paid up Capital: | R40: =-C7 -> -5000
B41: =DATE(YEAR(E$24),MONTH(E$24)+D41+1,DAY(E$24)) -> 46359 | C41: =TEXT(B41,"mmm-yyyy") -> Dec-2026 | D41: 14 | E41: =C$1 -> 10499.998 | F41: =E41-G41 -> 6577.8604 | G41: =H40*C$12 -> 3922.1377 | H41: =H40-F41 -> 385635.91 | L41: (-) | M41: Service Fee | R41: =-C5 -> -47022.536 | X41: LOAN ID: | AF41: DEDUCTION CODE: | AR41: LOAN PURPOSE:
B42: =DATE(YEAR(E$24),MONTH(E$24)+D42+1,DAY(E$24)) -> 46390 | C42: =TEXT(B42,"mmm-yyyy") -> Jan-2027 | D42: 15 | E42: =C$1 -> 10499.998 | F42: =E42-G42 -> 6643.639 | G42: =H41*C$12 -> 3856.3591 | H42: =H41-F42 -> 378992.27 | L42: (-) | M42: Insurance Premium - Paramount | R42: =-C6 -> -23316.96 | X42: MEM ID: | AG42: Regular Member | AS42: Old Member
B43: =DATE(YEAR(E$24),MONTH(E$24)+D43+1,DAY(E$24)) -> 46421 | C43: =TEXT(B43,"mmm-yyyy") -> Feb-2027 | D43: 16 | E43: =C$1 -> 10499.998 | F43: =E43-G43 -> 6710.0754 | G43: =H42*C$12 -> 3789.9227 | H43: =H42-F43 -> 372282.19 | L43: (-) | M43: Advance Interest | R43: =-C9 -> -7772.32 | AG43: Associate Member | AS43: New Member
B44: =DATE(YEAR(E$24),MONTH(E$24)+D44+1,DAY(E$24)) -> 46449 | C44: =TEXT(B44,"mmm-yyyy") -> Mar-2027 | D44: 17 | E44: =C$1 -> 10499.998 | F44: =E44-G44 -> 6777.1761 | G44: =H43*C$12 -> 3722.8219 | H44: =H43-F44 -> 365505.02 | L44: NET PROCEEDS (Php): | R44: =SUM(R36:T43) -> 126912.22 | X44: BORROWER'S INFORMATION
B45: =DATE(YEAR(E$24),MONTH(E$24)+D45+1,DAY(E$24)) -> 46480 | C45: =TEXT(B45,"mmm-yyyy") -> Apr-2027 | D45: 18 | E45: =C$1 -> 10499.998 | F45: =E45-G45 -> 6844.9479 | G45: =H44*C$12 -> 3655.0502 | H45: =H44-F45 -> 358660.07 | X45: MAGISTRADO | AD45: ALBERTO | AN45: BENJAMIN
B46: =DATE(YEAR(E$24),MONTH(E$24)+D46+1,DAY(E$24)) -> 46510 | C46: =TEXT(B46,"mmm-yyyy") -> May-2027 | D46: 19 | E46: =C$1 -> 10499.998 | F46: =E46-G46 -> 6913.3974 | G46: =H45*C$12 -> 3586.6007 | H46: =H45-F46 -> 351746.67 | K46: PAYMENT | X46: (LAST NAME) | AD46: (FIRST NAME) | AN46: (MIDDLE NAME) | AZ46: (SUFFIX)
...
